Workbook

Sheet 歷年
A1: 兒童及少年保護-受虐/問題類型 Child and Youth Protection Cases - Type/Matter of Abused
A2: 單位：人 Unit : Person
A3: 年別 Year | B3: 兒童少年受虐/間題類型 (人數)By Types/Matters (Person)
B4: 總計 Total | E4: 遺棄 Abandon | I4: 身心不當對待Physical Emotional Abuse | Q4: 目睹家暴 Witnessing Domestic Violence | S4: 兒少物質濫用 | U4: 不當管教 Improper Discipline | W4: 其他 Others
E5: 棄嬰 Abandoned Infants | G5: 棄兒 Abandoned Children | I5: 身體不當對待 Physical Abuse | K5: 精神不當對待 Emotional Abuse | M5: 性不當對待 Sexual Abuse | O5: 疏忽 Neglect
B6: 合計 SubTotal | C6: 男 Male | D6: 女 Female | E6: 男 Male | F6: 女 Female | G6: 男 Male | H6: 女 Female | I6: 男 Male | J6: 女 Female | K6: 男 Male | L6: 女 Female | M6: 男 Male | N6: 女 Female | O6: 男 Male | P6: 女 Female | Q6: 男 Male | R6: 女 Female | S6: 男 Male | T6: 女 Female | U6: 男 Male | V6: 女 Female | W6: 男 Male | X6: 女 Female
A7: 108年, 2019 | B7: ='2019'!D8 -> 11113 | C7: ='2019'!E8 -> 4832 | D7: ='2019'!F8 -> 6281 | E7: ='2019'!G8 -> 8 | F7: ='2019'!H8 -> 8 | G7: ='2019'!I8 -> 8 | H7: ='2019'!J8 -> 4 | I7: ='2019'!K8 -> 429 | ... P7: ='2019'!R8 -> 480 | Q7: ='2019'!U8 -> 61 | R7: ='2019'!V8 -> 57 | S7: ='2019'!W8 -> 89 | T7: ='2019'!X8 -> 126 | U7: ='2019'!S8 -> 1879 | V7: ='2019'!T8 -> 1154 | W7: ='2019'!Y8 -> 1156 | X7: ='2019'!Z8 -> 1400
A8: 109年, 2020 | B8: ='2020'!D8 -> 12610 | C8: ='2020'!E8 -> 5475 | D8: ='2020'!F8 -> 7135 | E8: ='2020'!G8 -> 5 | F8: ='2020'!H8 -> 8 | G8: ='2020'!I8 -> 8 | H8: ='2020'!J8 -> 11 | I8: ='2020'!K8 -> 1841 | ... P8: ='2020'!R8 -> 588 | Q8: ='2020'!U8 -> 62 | R8: ='2020'!V8 -> 67 | S8: ='2020'!W8 -> 343 | T8: ='2020'!X8 -> 156 | U8: ='2020'!S8 -> 801 | V8: ='2020'!T8 -> 536 | W8: ='2020'!Y8 -> 1251 | X8: ='2020'!Z8 -> 2575
A9: 110年, 2021 | B9: ='2021'!D8 -> 11523 | C9: ='2021'!E8 -> 5108 | D9: ='2021'!F8 -> 6415 | E9: ='2021'!G8 -> 11 | F9: ='2021'!H8 -> 7 | G9: ='2021'!I8 -> 13 | H9: ='2021'!J8 -> 9 | I9: ='2021'!K8 -> 3032 | ... T9: ='2021'!V8 -> 111 | U9: — | V9: — | W9: — | X9: —
A10: 111年, 2022 | B10: ='2022'!D8 -> 11950 | C10: ='2022'!E8 -> 5281 | D10: ='2022'!F8 -> 6669 | E10: ='2022'!G8 -> 15 | F10: ='2022'!H8 -> 1 | G10: ='2022'!I8 -> 6 | H10: ='2022'!J8 -> 9 | I10: ='2022'!K8 -> 3199 | ... T10: ='2022'!V8 -> 73 | U10: — | V10: — | W10: — | X10: —
A11: 112年, 2023 | B11: ='2023'!D8 -> 12646 | C11: ='2023'!E8 -> 5649 | D11: ='2023'!F8 -> 6997 | E11: ='2023'!G8 -> 9 | F11: ='2023'!H8 -> 5 | G11: ='2023'!I8 -> 12 | H11: ='2023'!J8 -> 3 | I11: ='2023'!K8 -> 3756 | ... T11: ='2023'!V8 -> 33 | U11: — | V11: — | W11: ='2023'!Y8 -> 0 | X11: ='2023'!Z8 -> 0
A12: 113年, 2024 | B12: ='2024'!D8 -> 10810 | C12: ='2024'!E8 -> 4836 | D12: ='2024'!F8 -> 5974 | E12: ='2024'!G8 -> 5 | F12: ='2024'!H8 -> 6 | G12: ='2024'!I8 -> 10 | H12: ='2024'!J8 -> 4 | I12: ='2024'!K8 -> 3340 | ... X12: ='2024'!Z8 -> 0
A13: 上半年, Jan.-June | B13: 5771 | C13: 2521 | D13: 3250 | E13: 3 | F13: 5 | G13: 5 | H13: 3 | I13: 1804 | J13: 1242 | K13: 144 | L13: 144 | M13: 278 | N13: 1591 | O13: 273 | P13: 243 | Q13: 9 | R13: 11 | S13: 5 | T13: 11 | U13: — | V13: — | W13: — | X13: —
A14: 下半年, July-Dec. | B14: 5039 | C14: 2315 | D14: 2724 | E14: 2 | F14: 1 | G14: 5 | H14: 1 | I14: 1536 | J14: 1084 | K14: 110 | L14: 94 | M14: 307 | N14: 1291 | O14: 327 | P14: 233 | Q14: 28 | R14: 20 | S14: 0 | T14: 0 | U14: — | V14: — | W14: — | X14: —
A15: 114年, 2025 | B15: ='2025'!D8 -> 9898 | C15: ='2025'!E8 -> 4451 | D15: ='2025'!F8 -> 5447 | E15: ='2025'!G8 -> 6 | F15: ='2025'!H8 -> 4 | G15: ='2025'!I8 -> 9 | H15: ='2025'!J8 -> 1 | I15: ='2025'!K8 -> 3125 | ... X15: ='2025'!Z8 -> 0
A16: 上半年, Jan.-June | B16: ='Jan.-June, 2025'!D8 -> 5352 | C16: ='Jan.-June, 2025'!E8 -> 2421 | D16: ='Jan.-June, 2025'!F8 -> 2931 | E16: ='Jan.-June, 2025'!G8 -> 2 | F16: ='Jan.-June, 2025'!H8 -> 4 | G16: ='Jan.-June, 2025'!I8 -> 2 | H16: ='Jan.-June, 2025'!J8 -> 0 | I16: ='Jan.-June, 2025'!K8 -> 1714 | ... U16: ='Jan.-June, 2025'!W8 -> 0 | V16: — | W16: — | X16: —
A17: 下半年, July-Dec. | B17: ='July-Dec., 2025'!D8 -> 4546 | C17: ='July-Dec., 2025'!E8 -> 2030 | D17: ='July-Dec., 2025'!F8 -> 2516 | E17: ='July-Dec., 2025'!G8 -> 4 | F17: ='July-Dec., 2025'!H8 -> 0 | G17: ='July-Dec., 2025'!I8 -> 7 | H17: ='July-Dec., 2025'!J8 -> 1 | I17: ='July-Dec., 2025'!K8 -> 1411 | ... X17: ='July-Dec., 2025'!Z8 -> 0
A18: 資料來源：各直轄市、縣市政府。
A19: 說 明：1.106年及107年，係統計『家內』兒少保護案件，自108年起統計範圍包含家內及家外之兒少保護案件，其中「家內案件」係指因兒童及少年之父母、監護人、其他實際照顧兒童及少年之人或其他家庭成員， 未盡力禁止或故意，致兒少受到不當對待之案件；「家外案件」則指因兒少本人或照顧人以外之人故意，致兒少受到不當對待之案件。
A20: 附 註：1.自109年7月起刪除「不當管教」統計項目，轉至妥適項目統計。
A21: 2.自112年7月起「兒少物質濫用」移由少年輔導委員會及教育主管機關提供服務。
A22: Source: County and Government.
A23: 更新日期：2026/03/31
B24: =IF(B15=SUM(B16:B17),"","*") | C24: =IF(C15=SUM(C16:C17),"","*") | D24: =IF(D15=SUM(D16:D17),"","*") | E24: =IF(E15=SUM(E16:E17),"","*") | F24: =IF(F15=SUM(F16:F17),"","*") | G24: =IF(G15=SUM(G16:G17),"","*") | H24: =IF(H15=SUM(H16:H17),"","*") | I24: =IF(I15=SUM(I16:I17),"","*") | ... X24: =IF(X15=SUM(X16:X17),"","*")

Sheet 2025
A1: 兒童及少年保護-受虐/問題類型Child and Youth Protection Cases - Type/Matter of Abused
A2: 單位：人 Unit : Person
A3: 民國114年, 2025 | D3: =IF(D8=SUM(D11,D14,D17,D20,D23,D26,D29,D32,D35,D38,D41,D44,D47,D50,D53,D56,D59,D62,D65,D68,D71,D74,),"",SUM(D11,D14,D17,D20,D23,D26,D29,D32,D35,D38,D41,D44,D47,D50,D53,D56,D59,D62,D65,D68,D71,D74,)) | E3: =IF(E8=SUM(E11,E14,E17,E20,E23,E26,E29,E32,E35,E38,E41,E44,E47,E50,E53,E56,E59,E62,E65,E68,E71,E74,),"",SUM(E11,E14,E17,E20,E23,E26,E29,E32,E35,E38,E41,E44,E47,E50,E53,E56,E59,E62,E65,E68,E71,E74,)) | F3: =IF(F8=SUM(F11,F14,F17,F20,F23,F26,F29,F32,F35,F38,F41,F44,F47,F50,F53,F56,F59,F62,F65,F68,F71,F74,),"",SUM(F11,F14,F17,F20,F23,F26,F29,F32,F35,F38,F41,F44,F47,F50,F53,F56,F59,F62,F65,F68,F71,F74,)) | G3: =IF(G8=SUM(G11,G14,G17,G20,G23,G26,G29,G32,G35,G38,G41,G44,G47,G50,G53,G56,G59,G62,G65,G68,G71,G74,),"",SUM(G11,G14,G17,G20,G23,G26,G29,G32,G35,G38,G41,G44,G47,G50,G53,G56,G59,G62,G65,G68,G71,G74,)) | H3: =IF(H8=SUM(H11,H14,H17,H20,H23,H26,H29,H32,H35,H38,H41,H44,H47,H50,H53,H56,H59,H62,H65,H68,H71,H74,),"",SUM(H11,H14,H17,H20,H23,H26,H29,H32,H35,H38,H41,H44,H47,H50,H53,H56,H59,H62,H65,H68,H71,H74,)) | I3: =IF(I8=SUM(I11,I14,I17,I20,I23,I26,I29,I32,I35,I38,I41,I44,I47,I50,I53,I56,I59,I62,I65,I68,I71,I74,),"",SUM(I11,I14,I17,I20,I23,I26,I29,I32,I35,I38,I41,I44,I47,I50,I53,I56,I59,I62,I65,I68,I71,I74,)) | J3: =IF(J8=SUM(J11,J14,J17,J20,J23,J26,J29,J32,J35,J38,J41,J44,J47,J50,J53,J56,J59,J62,J65,J68,J71,J74,),"",SUM(J11,J14,J17,J20,J23,J26,J29,J32,J35,J38,J41,J44,J47,J50,J53,J56,J59,J62,J65,J68,J71,J74,)) | K3: =IF(K8=SUM(K11,K14,K17,K20,K23,K26,K29,K32,K35,K38,K41,K44,K47,K50,K53,K56,K59,K62,K65,K68,K71,K74,),"",SUM(K11,K14,K17,K20,K23,K26,K29,K32,K35,K38,K41,K44,K47,K50,K53,K56,K59,K62,K65,K68,K71,K74,)) | ... T3: =IF(T8=SUM(T11,T14,T17,T20,T23,T26,T29,T32,T35,T38,T41,T44,T47,T50,T53,T56,T59,T62,T65,T68,T71,T74,),"",SUM(T11,T14,T17,T20,T23,T26,T29,T32,T35,T38,T41,T44,T47,T50,T53,T56,T59,T62,T65,T68,T71,T74,))
A4: 區域及特殊族群別 Locality & Ethnos | D4: 兒童少年受虐/間題類型 (人數)By Types/Matters (Person)
D5: 總計 Total | G5: 遺棄 Abandon | K5: 身心不當對待Physical Emotional Abuse | S5: 目睹家暴 Witnessing Domestic Violence
G6: 棄嬰 Abandoned Infants | I6: 棄兒 Abandoned Children | K6: 身體不當對待 Physical Abuse | M6: 精神不當對待 Emotional Abuse | O6: 性不當對待 Sexual Abuse | Q6: 疏忽 Neglect
D7: 合計 SubTotal | E7: 男 Male | F7: 女 Female | G7: 男 Male | H7: 女 Female | I7: 男 Male | J7: 女 Female | K7: 男 Male | L7: 女 Female | M7: 男 Male | N7: 女 Female | O7: 男 Male | P7: 女 Female | Q7: 男 Male | R7: 女 Female | S7: 男 Male | T7: 女 Female
A8: 總計 | B8: 計 | C8: Total | D8: 9898 | E8: 4451 | F8: 5447 | G8: 6 | H8: 4 | I8: 9 | J8: 1 | K8: 3125 | L8: 2045 | M8: 209 | N8: 227 | O8: 452 | P8: 2657 | Q8: 620 | R8: 486 | S8: 30 | T8: 27
A9: Total | B9: 一般 | C9: General | D9: 8952 | E9: 4080 | F9: 4872 | G9: 6 | H9: 4 | I9: 8 | J9: 1 | K9: 2873 | L9: 1850 | M9: 192 | N9: 212 | O9: 410 | P9: 2355 | Q9: 561 | R9: 427 | S9: 30 | T9: 23
B10: 原住民 | C10: Indigenous | D10: 946 | E10: 371 | F10: 575 | G10: 0 | H10: 0 | I10: 1 | J10: 0 | K10: 252 | L10: 195 | M10: 17 | N10: 15 | O10: 42 | P10: 302 | Q10: 59 | R10: 59 | S10: 0 | T10: 4
A11: 新北市 | B11: 計 | C11: Total | D11: 2147 | E11: 951 | F11: 1196 | G11: 0 | H11: 0 | I11: 1 | J11: 0 | K11: 704 | L11: 480 | M11: 70 | N11: 66 | O11: 85 | P11: 593 | Q11: 81 | R11: 49 | S11: 10 | T11: 8
A12: New Taipei City | B12: 一般 | C12: General | D12: 2009 | E12: 902 | F12: 1107 | G12: 0 | H12: 0 | I12: 1 | J12: 0 | K12: 665 | L12: 431 | M12: 68 | N12: 57 | O12: 80 | P12: 567 | Q12: 78 | R12: 45 | S12: 10 | T12: 7
B13: 原住民 | C13: Indigenous | D13: 138 | E13: 49 | F13: 89 | G13: 0 | H13: 0 | I13: 0 | J13: 0 | K13: 39 | L13: 49 | M13: 2 | N13: 9 | O13: 5 | P13: 26 | Q13: 3 | R13: 4 | S13: 0 | T13: 1
A14: 臺北市 | B14: 計 | C14: Total | D14: 894 | E14: 424 | F14: 470 | G14: 1 | H14: 1 | I14: 0 | J14: 0 | K14: 279 | L14: 167 | M14: 11 | N14: 15 | O14: 54 | P14: 230 | Q14: 76 | R14: 53 | S14: 3 | T14: 4
A15: Taipei City | B15: 一般 | C15: General | D15: 874 | E15: 413 | F15: 461 | G15: 1 | H15: 1 | I15: 0 | J15: 0 | K15: 271 | L15: 165 | M15: 11 | N15: 15 | O15: 54 | P15: 225 | Q15: 73 | R15: 51 | S15: 3 | T15: 4
B16: 原住民 | C16: Indigenous | D16: 20 | E16: 11 | F16: 9 | G16: 0 | H16: 0 | I16: 0 | J16: 0 | K16: 8 | L16: 2 | M16: 0 | N16: 0 | O16: 0 | P16: 5 | Q16: 3 | R16: 2 | S16: 0 | T16: 0
A17: 桃園市 | B17: 計 | C17: Total | D17: 777 | E17: 353 | F17: 424 | G17: 1 | H17: 1 | I17: 0 | J17: 0 | K17: 305 | L17: 183 | M17: 1 | N17: 2 | O17: 24 | P17: 225 | Q17: 22 | R17: 13 | S17: 0 | T17: 0
A18: Taoyuan City | B18: 一般 | C18: General | D18: 645 | E18: 296 | F18: 349 | G18: 1 | H18: 1 | I18: 0 | J18: 0 | K18: 254 | L18: 152 | M18: 1 | N18: 2 | O18: 22 | P18: 185 | Q18: 18 | R18: 9 | S18: 0 | T18: 0
B19: 原住民 | C19: Indigenous | D19: 132 | E19: 57 | F19: 75 | G19: 0 | H19: 0 | I19: 0 | J19: 0 | K19: 51 | L19: 31 | M19: 0 | N19: 0 | O19: 2 | P19: 40 | Q19: 4 | R19: 4 | S19: 0 | T19: 0
A20: 臺中市 | B20: 計 | C20: Total | D20: 1327 | E20: 663 | F20: 664 | G20: 0 | H20: 0 | I20: 2 | J20: 0 | K20: 519 | L20: 304 | M20: 38 | N20: 30 | O20: 57 | P20: 292 | Q20: 45 | R20: 38 | S20: 2 | T20: 0
A21: Taichung City | B21: 一般 | C21: General | D21: 1250 | E21: 621 | F21: 629 | G21: 0 | H21: 0 | I21: 1 | J21: 0 | K21: 491 | L21: 289 | M21: 36 | N21: 29 | O21: 51 | P21: 277 | Q21: 40 | R21: 34 | S21: 2 | T21: 0
B22: 原住民 | C22: Indigenous | D22: 77 | E22: 42 | F22: 35 | G22: 0 | H22: 0 | I22: 1 | J22: 0 | K22: 28 | L22: 15 | M22: 2 | N22: 1 | O22: 6 | P22: 15 | Q22: 5 | R22: 4 | S22: 0 | T22: 0
A23: 臺南市 | B23: 計 | C23: Total | D23: 532 | E23: 263 | F23: 269 | G23: 0 | H23: 1 | I23: 1 | J23: 0 | K23: 156 | L23: 83 | M23: 8 | N23: 18 | O23: 26 | P23: 124 | Q23: 69 | R23: 42 | S23: 3 | T23: 1
A24: Tainan City | B24: 一般 | C24: General | D24: 510 | E24: 249 | F24: 261 | G24: 0 | H24: 1 | I24: 1 | J24: 0 | K24: 148 | L24: 80 | M24: 8 | N24: 18 | O24: 26 | P24: 119 | Q24: 63 | R24: 42 | S24: 3 | T24: 1
B25: 原住民 | C25: Indigenous | D25: 22 | E25: 14 | F25: 8 | G25: 0 | H25: 0 | I25: 0 | J25: 0 | K25: 8 | L25: 3 | M25: 0 | N25: 0 | O25: 0 | P25: 5 | Q25: 6 | R25: 0 | S25: 0 | T25: 0
A26: 高雄市 | B26: 計 | C26: Total | D26: 1283 | E26: 606 | F26: 677 | G26: 0 | H26: 0 | I26: 0 | J26: 0 | K26: 440 | L26: 289 | M26: 23 | N26: 27 | O26: 29 | P26: 281 | Q26: 110 | R26: 72 | S26: 4 | T26: 8
A27: Kaohsiung City | B27: 一般 | C27: General | D27: 1191 | E27: 569 | F27: 622 | G27: 0 | H27: 0 | I27: 0 | J27: 0 | K27: 411 | L27: 265 | M27: 22 | N27: 27 | O27: 28 | P27: 257 | Q27: 104 | R27: 65 | S27: 4 | T27: 8
B28: 原住民 | C28: Indigenous | D28: 92 | E28: 37 | F28: 55 | G28: 0 | H28: 0 | I28: 0 | J28: 0 | K28: 29 | L28: 24 | M28: 1 | N28: 0 | O28: 1 | P28: 24 | Q28: 6 | R28: 7 | S28: 0 | T28: 0
A29: 宜蘭縣 | B29: 計 | C29: Total | D29: 65 | E29: 10 | F29: 55 | G29: 0 | H29: 0 | I29: 0 | J29: 0 | K29: 6 | L29: 20 | M29: 0 | N29: 0 | O29: 2 | P29: 30 | Q29: 2 | R29: 5 | S29: 0 | T29: 0
A30: Yilan County | B30: 一般 | C30: General | D30: 61 | E30: 10 | F30: 51 | G30: 0 | H30: 0 | I30: 0 | J30: 0 | K30: 6 | L30: 20 | M30: 0 | N30: 0 | O30: 2 | P30: 26 | Q30: 2 | R30: 5 | S30: 0 | T30: 0
B31: 原住民 | C31: Indigenous | D31: 4 | E31: 0 | F31: 4 | G31: 0 | H31: 0 | I31: 0 | J31: 0 | K31: 0 | L31: 0 | M31: 0 | N31: 0 | O31: 0 | P31: 4 | Q31: 0 | R31: 0 | S31: 0 | T31: 0
A32: 新竹縣 | B32: 計 | C32: Total | D32: 362 | E32: 163 | F32: 199 | G32: 0 | H32: 0 | I32: 0 | J32: 0 | K32: 98 | L32: 76 | M32: 17 | N32: 21 | O32: 12 | P32: 66 | Q32: 35 | R32: 36 | S32: 1 | T32: 0
A33: Hsinchu County | B33: 一般 | C33: General | D33: 303 | E33: 142 | F33: 161 | G33: 0 | H33: 0 | I33: 0 | J33: 0 | K33: 88 | L33: 63 | M33: 15 | N33: 19 | O33: 11 | P33: 53 | Q33: 27 | R33: 26 | S33: 1 | T33: 0
B34: 原住民 | C34: Indigenous | D34: 59 | E34: 21 | F34: 38 | G34: 0 | H34: 0 | I34: 0 | J34: 0 | K34: 10 | L34: 13 | M34: 2 | N34: 2 | O34: 1 | P34: 13 | Q34: 8 | R34: 10 | S34: 0 | T34: 0
A35: 苗栗縣 | B35: 計 | C35: Total | D35: 182 | E35: 49 | F35: 133 | G35: 0 | H35: 0 | I35: 1 | J35: 0 | K35: 28 | L35: 35 | M35: 5 | N35: 7 | O35: 5 | P35: 78 | Q35: 10 | R35: 13 | S35: 0 | T35: 0
A36: Miaoli County | B36: 一般 | C36: General | D36: 163 | E36: 45 | F36: 118 | G36: 0 | H36: 0 | I36: 1 | J36: 0 | K36: 27 | L36: 32 | M36: 4 | N36: 6 | O36: 4 | P36: 68 | Q36: 9 | R36: 12 | S36: 0 | T36: 0
B37: 原住民 | C37: Indigenous | D37: 19 | E37: 4 | F37: 15 | G37: 0 | H37: 0 | I37: 0 | J37: 0 | K37: 1 | L37: 3 | M37: 1 | N37: 1 | O37: 1 | P37: 10 | Q37: 1 | R37: 1 | S37: 0 | T37: 0
A38: 彰化縣 | B38: 計 | C38: Total | D38: 373 | E38: 161 | F38: 212 | G38: 1 | H38: 1 | I38: 0 | J38: 0 | K38: 105 | L38: 65 | M38: 10 | N38: 13 | O38: 26 | P38: 112 | Q38: 17 | R38: 20 | S38: 2 | T38: 1
A39: Changhua County | B39: 一般 | C39: General | D39: 357 | E39: 156 | F39: 201 | G39: 1 | H39: 1 | I39: 0 | J39: 0 | K39: 102 | L39: 64 | M39: 9 | N39: 12 | O39: 25 | P39: 105 | Q39: 17 | R39: 18 | S39: 2 | T39: 1
B40: 原住民 | C40: Indigenous | D40: 16 | E40: 5 | F40: 11 | G40: 0 | H40: 0 | I40: 0 | J40: 0 | K40: 3 | L40: 1 | M40: 1 | N40: 1 | O40: 1 | P40: 7 | Q40: 0 | R40: 2 | S40: 0 | T40: 0
...

Sheet July-Dec., 2025
A1: 兒童及少年保護-受虐/問題類型Child and Youth Protection Cases - Type/Matter of Abused
A2: 單位：人 Unit : Person
A3: 民國114年7-12月 July-Dec., 2025 | D3: =IF(D8=SUM(D11,D14,D17,D20,D23,D26,D29,D32,D35,D38,D41,D44,D47,D50,D53,D56,D59,D62,D65,D68,D71,D74,),"",SUM(D11,D14,D17,D20,D23,D26,D29,D32,D35,D38,D41,D44,D47,D50,D53,D56,D59,D62,D65,D68,D71,D74,)) | E3: =IF(E8=SUM(E11,E14,E17,E20,E23,E26,E29,E32,E35,E38,E41,E44,E47,E50,E53,E56,E59,E62,E65,E68,E71,E74,),"",SUM(E11,E14,E17,E20,E23,E26,E29,E32,E35,E38,E41,E44,E47,E50,E53,E56,E59,E62,E65,E68,E71,E74,)) | F3: =IF(F8=SUM(F11,F14,F17,F20,F23,F26,F29,F32,F35,F38,F41,F44,F47,F50,F53,F56,F59,F62,F65,F68,F71,F74,),"",SUM(F11,F14,F17,F20,F23,F26,F29,F32,F35,F38,F41,F44,F47,F50,F53,F56,F59,F62,F65,F68,F71,F74,)) | G3: =IF(G8=SUM(G11,G14,G17,G20,G23,G26,G29,G32,G35,G38,G41,G44,G47,G50,G53,G56,G59,G62,G65,G68,G71,G74,),"",SUM(G11,G14,G17,G20,G23,G26,G29,G32,G35,G38,G41,G44,G47,G50,G53,G56,G59,G62,G65,G68,G71,G74,)) | H3: =IF(H8=SUM(H11,H14,H17,H20,H23,H26,H29,H32,H35,H38,H41,H44,H47,H50,H53,H56,H59,H62,H65,H68,H71,H74,),"",SUM(H11,H14,H17,H20,H23,H26,H29,H32,H35,H38,H41,H44,H47,H50,H53,H56,H59,H62,H65,H68,H71,H74,)) | I3: =IF(I8=SUM(I11,I14,I17,I20,I23,I26,I29,I32,I35,I38,I41,I44,I47,I50,I53,I56,I59,I62,I65,I68,I71,I74,),"",SUM(I11,I14,I17,I20,I23,I26,I29,I32,I35,I38,I41,I44,I47,I50,I53,I56,I59,I62,I65,I68,I71,I74,)) | J3: =IF(J8=SUM(J11,J14,J17,J20,J23,J26,J29,J32,J35,J38,J41,J44,J47,J50,J53,J56,J59,J62,J65,J68,J71,J74,),"",SUM(J11,J14,J17,J20,J23,J26,J29,J32,J35,J38,J41,J44,J47,J50,J53,J56,J59,J62,J65,J68,J71,J74,)) | K3: =IF(K8=SUM(K11,K14,K17,K20,K23,K26,K29,K32,K35,K38,K41,K44,K47,K50,K53,K56,K59,K62,K65,K68,K71,K74,),"",SUM(K11,K14,K17,K20,K23,K26,K29,K32,K35,K38,K41,K44,K47,K50,K53,K56,K59,K62,K65,K68,K71,K74,)) | ... T3: =IF(T8=SUM(T11,T14,T17,T20,T23,T26,T29,T32,T35,T38,T41,T44,T47,T50,T53,T56,T59,T62,T65,T68,T71,T74,),"",SUM(T11,T14,T17,T20,T23,T26,T29,T32,T35,T38,T41,T44,T47,T50,T53,T56,T59,T62,T65,T68,T71,T74,))
A4: 區域及特殊族群別 Locality & Ethnos | D4: 兒童少年受虐/間題類型 (人數)By Types/Matters (Person)
D5: 總計 Total | G5: 遺棄 Abandon | K5: 身心不當對待Physical Emotional Abuse | S5: 目睹家暴 Witnessing Domestic Violence
G6: 棄嬰 Abandoned Infants | I6: 棄兒 Abandoned Children | K6: 身體不當對待 Physical Abuse | M6: 精神不當對待 Emotional Abuse | O6: 性不當對待 Sexual Abuse | Q6: 疏忽 Neglect
D7: 合計 SubTotal | E7: 男 Male | F7: 女 Female | G7: 男 Male | H7: 女 Female | I7: 男 Male | J7: 女 Female | K7: 男 Male | L7: 女 Female | M7: 男 Male | N7: 女 Female | O7: 男 Male | P7: 女 Female | Q7: 男 Male | R7: 女 Female | S7: 男 Male | T7: 女 Female
A8: 總計 | B8: 計 | C8: Total | D8: 4546 | E8: 2030 | F8: 2516 | G8: 4 | H8: 0 | I8: 7 | J8: 1 | K8: 1411 | L8: 933 | M8: 113 | N8: 120 | O8: 178 | P8: 1203 | Q8: 303 | R8: 249 | S8: 14 | T8: 10
A9: Total | B9: 一般 | C9: General | D9: 4085 | E9: 1858 | F9: 2227 | G9: 4 | H9: 0 | I9: 6 | J9: 1 | K9: 1294 | L9: 826 | M9: 103 | N9: 111 | O9: 159 | P9: 1064 | Q9: 278 | R9: 216 | S9: 14 | T9: 9
B10: 原住民 | C10: Indigenous | D10: 461 | E10: 172 | F10: 289 | G10: 0 | H10: 0 | I10: 1 | J10: 0 | K10: 117 | L10: 107 | M10: 10 | N10: 9 | O10: 19 | P10: 139 | Q10: 25 | R10: 33 | S10: 0 | T10: 1
A11: 新北市 | B11: 計 | C11: Total | D11: 996 | E11: 451 | F11: 545 | G11: 0 | H11: 0 | I11: 0 | J11: 0 | K11: 336 | L11: 210 | M11: 36 | N11: 34 | O11: 34 | P11: 273 | Q11: 41 | R11: 24 | S11: 4 | T11: 4
A12: New Taipei City | B12: 一般 | C12: General | D12: 914 | E12: 422 | F12: 492 | G12: 0 | H12: 0 | I12: 0 | J12: 0 | K12: 312 | L12: 182 | M12: 35 | N12: 28 | O12: 32 | P12: 258 | Q12: 39 | R12: 21 | S12: 4 | T12: 3
B13: 原住民 | C13: Indigenous | D13: 82 | E13: 29 | F13: 53 | G13: 0 | H13: 0 | I13: 0 | J13: 0 | K13: 24 | L13: 28 | M13: 1 | N13: 6 | O13: 2 | P13: 15 | Q13: 2 | R13: 3 | S13: 0 | T13: 1
A14: 臺北市 | B14: 計 | C14: Total | D14: 375 | E14: 161 | F14: 214 | G14: 1 | H14: 0 | I14: 0 | J14: 0 | K14: 102 | L14: 62 | M14: 7 | N14: 7 | O14: 17 | P14: 111 | Q14: 33 | R14: 33 | S14: 1 | T14: 1
A15: Taipei City | B15: 一般 | C15: General | D15: 364 | E15: 155 | F15: 209 | G15: 1 | H15: 0 | I15: 0 | J15: 0 | K15: 98 | L15: 61 | M15: 7 | N15: 7 | O15: 17 | P15: 108 | Q15: 31 | R15: 32 | S15: 1 | T15: 1
B16: 原住民 | C16: Indigenous | D16: 11 | E16: 6 | F16: 5 | G16: 0 | H16: 0 | I16: 0 | J16: 0 | K16: 4 | L16: 1 | M16: 0 | N16: 0 | O16: 0 | P16: 3 | Q16: 2 | R16: 1 | S16: 0 | T16: 0
A17: 桃園市 | B17: 計 | C17: Total | D17: 353 | E17: 153 | F17: 200 | G17: 1 | H17: 0 | I17: 0 | J17: 0 | K17: 141 | L17: 82 | M17: 0 | N17: 2 | O17: 6 | P17: 111 | Q17: 5 | R17: 5 | S17: 0 | T17: 0
A18: Taoyuan City | B18: 一般 | C18: General | D18: 282 | E18: 124 | F18: 158 | G18: 1 | H18: 0 | I18: 0 | J18: 0 | K18: 112 | L18: 63 | M18: 0 | N18: 2 | O18: 6 | P18: 91 | Q18: 5 | R18: 2 | S18: 0 | T18: 0
B19: 原住民 | C19: Indigenous | D19: 71 | E19: 29 | F19: 42 | G19: 0 | H19: 0 | I19: 0 | J19: 0 | K19: 29 | L19: 19 | M19: 0 | N19: 0 | O19: 0 | P19: 20 | Q19: 0 | R19: 3 | S19: 0 | T19: 0
A20: 臺中市 | B20: 計 | C20: Total | D20: 618 | E20: 305 | F20: 313 | G20: 0 | H20: 0 | I20: 2 | J20: 0 | K20: 230 | L20: 141 | M20: 23 | N20: 23 | O20: 23 | P20: 127 | Q20: 26 | R20: 22 | S20: 1 | T20: 0
A21: Taichung City | B21: 一般 | C21: General | D21: 592 | E21: 291 | F21: 301 | G21: 0 | H21: 0 | I21: 1 | J21: 0 | K21: 219 | L21: 135 | M21: 22 | N21: 23 | O21: 22 | P21: 122 | Q21: 26 | R21: 21 | S21: 1 | T21: 0
B22: 原住民 | C22: Indigenous | D22: 26 | E22: 14 | F22: 12 | G22: 0 | H22: 0 | I22: 1 | J22: 0 | K22: 11 | L22: 6 | M22: 1 | N22: 0 | O22: 1 | P22: 5 | Q22: 0 | R22: 1 | S22: 0 | T22: 0
A23: 臺南市 | B23: 計 | C23: Total | D23: 213 | E23: 99 | F23: 114 | G23: 0 | H23: 0 | I23: 0 | J23: 0 | K23: 59 | L23: 36 | M23: 2 | N23: 3 | O23: 10 | P23: 58 | Q23: 26 | R23: 16 | S23: 2 | T23: 1
A24: Tainan City | B24: 一般 | C24: General | D24: 206 | E24: 96 | F24: 110 | G24: 0 | H24: 0 | I24: 0 | J24: 0 | K24: 56 | L24: 35 | M24: 2 | N24: 3 | O24: 10 | P24: 55 | Q24: 26 | R24: 16 | S24: 2 | T24: 1
B25: 原住民 | C25: Indigenous | D25: 7 | E25: 3 | F25: 4 | G25: 0 | H25: 0 | I25: 0 | J25: 0 | K25: 3 | L25: 1 | M25: 0 | N25: 0 | O25: 0 | P25: 3 | Q25: 0 | R25: 0 | S25: 0 | T25: 0
A26: 高雄市 | B26: 計 | C26: Total | D26: 601 | E26: 290 | F26: 311 | G26: 0 | H26: 0 | I26: 0 | J26: 0 | K26: 210 | L26: 145 | M26: 10 | N26: 16 | O26: 14 | P26: 107 | Q26: 54 | R26: 40 | S26: 2 | T26: 3
A27: Kaohsiung City | B27: 一般 | C27: General | D27: 555 | E27: 272 | F27: 283 | G27: 0 | H27: 0 | I27: 0 | J27: 0 | K27: 197 | L27: 130 | M27: 10 | N27: 16 | O27: 13 | P27: 98 | Q27: 50 | R27: 36 | S27: 2 | T27: 3
B28: 原住民 | C28: Indigenous | D28: 46 | E28: 18 | F28: 28 | G28: 0 | H28: 0 | I28: 0 | J28: 0 | K28: 13 | L28: 15 | M28: 0 | N28: 0 | O28: 1 | P28: 9 | Q28: 4 | R28: 4 | S28: 0 | T28: 0
A29: 宜蘭縣 | B29: 計 | C29: Total | D29: 30 | E29: 3 | F29: 27 | G29: 0 | H29: 0 | I29: 0 | J29: 0 | K29: 0 | L29: 10 | M29: 0 | N29: 0 | O29: 1 | P29: 13 | Q29: 2 | R29: 4 | S29: 0 | T29: 0
A30: Yilan County | B30: 一般 | C30: General | D30: 28 | E30: 3 | F30: 25 | G30: 0 | H30: 0 | I30: 0 | J30: 0 | K30: 0 | L30: 10 | M30: 0 | N30: 0 | O30: 1 | P30: 11 | Q30: 2 | R30: 4 | S30: 0 | T30: 0
B31: 原住民 | C31: Indigenous | D31: 2 | E31: 0 | F31: 2 | G31: 0 | H31: 0 | I31: 0 | J31: 0 | K31: 0 | L31: 0 | M31: 0 | N31: 0 | O31: 0 | P31: 2 | Q31: 0 | R31: 0 | S31: 0 | T31: 0
A32: 新竹縣 | B32: 計 | C32: Total | D32: 178 | E32: 83 | F32: 95 | G32: 0 | H32: 0 | I32: 0 | J32: 0 | K32: 47 | L32: 35 | M32: 9 | N32: 10 | O32: 8 | P32: 33 | Q32: 19 | R32: 17 | S32: 0 | T32: 0
A33: Hsinchu County | B33: 一般 | C33: General | D33: 155 | E33: 71 | F33: 84 | G33: 0 | H33: 0 | I33: 0 | J33: 0 | K33: 42 | L33: 32 | M33: 8 | N33: 9 | O33: 7 | P33: 29 | Q33: 14 | R33: 14 | S33: 0 | T33: 0
B34: 原住民 | C34: Indigenous | D34: 23 | E34: 12 | F34: 11 | G34: 0 | H34: 0 | I34: 0 | J34: 0 | K34: 5 | L34: 3 | M34: 1 | N34: 1 | O34: 1 | P34: 4 | Q34: 5 | R34: 3 | S34: 0 | T34: 0
A35: 苗栗縣 | B35: 計 | C35: Total | D35: 91 | E35: 26 | F35: 65 | G35: 0 | H35: 0 | I35: 1 | J35: 0 | K35: 15 | L35: 22 | M35: 3 | N35: 4 | O35: 2 | P35: 34 | Q35: 5 | R35: 5 | S35: 0 | T35: 0
A36: Miaoli County | B36: 一般 | C36: General | D36: 83 | E36: 24 | F36: 59 | G36: 0 | H36: 0 | I36: 1 | J36: 0 | K36: 15 | L36: 21 | M36: 2 | N36: 3 | O36: 2 | P36: 31 | Q36: 4 | R36: 4 | S36: 0 | T36: 0
B37: 原住民 | C37: Indigenous | D37: 8 | E37: 2 | F37: 6 | G37: 0 | H37: 0 | I37: 0 | J37: 0 | K37: 0 | L37: 1 | M37: 1 | N37: 1 | O37: 0 | P37: 3 | Q37: 1 | R37: 1 | S37: 0 | T37: 0
A38: 彰化縣 | B38: 計 | C38: Total | D38: 150 | E38: 61 | F38: 89 | G38: 0 | H38: 0 | I38: 0 | J38: 0 | K38: 38 | L38: 30 | M38: 3 | N38: 3 | O38: 9 | P38: 45 | Q38: 11 | R38: 11 | S38: 0 | T38: 0
A39: Changhua County | B39: 一般 | C39: General | D39: 140 | E39: 57 | F39: 83 | G39: 0 | H39: 0 | I39: 0 | J39: 0 | K39: 36 | L39: 30 | M39: 2 | N39: 3 | O39: 8 | P39: 40 | Q39: 11 | R39: 10 | S39: 0 | T39: 0
B40: 原住民 | C40: Indigenous | D40: 10 | E40: 4 | F40: 6 | G40: 0 | H40: 0 | I40: 0 | J40: 0 | K40: 2 | L40: 0 | M40: 1 | N40: 0 | O40: 1 | P40: 5 | Q40: 0 | R40: 1 | S40: 0 | T40: 0
...

Sheet Jan.-June,  2025
A1: 兒童及少年保護-受虐/問題類型Child and Youth Protection Cases - Type/Matter of Abused
A2: 單位：人 Unit : Person
A3: 民國114年1-6月 Jan.-June, 2025 | D3: =IF(D8=SUM(D11,D14,D17,D20,D23,D26,D29,D32,D35,D38,D41,D44,D47,D50,D53,D56,D59,D62,D65,D68,D71,D74,),"",SUM(D11,D14,D17,D20,D23,D26,D29,D32,D35,D38,D41,D44,D47,D50,D53,D56,D59,D62,D65,D68,D71,D74,)) | E3: =IF(E8=SUM(E11,E14,E17,E20,E23,E26,E29,E32,E35,E38,E41,E44,E47,E50,E53,E56,E59,E62,E65,E68,E71,E74,),"",SUM(E11,E14,E17,E20,E23,E26,E29,E32,E35,E38,E41,E44,E47,E50,E53,E56,E59,E62,E65,E68,E71,E74,)) | F3: =IF(F8=SUM(F11,F14,F17,F20,F23,F26,F29,F32,F35,F38,F41,F44,F47,F50,F53,F56,F59,F62,F65,F68,F71,F74,),"",SUM(F11,F14,F17,F20,F23,F26,F29,F32,F35,F38,F41,F44,F47,F50,F53,F56,F59,F62,F65,F68,F71,F74,)) | G3: =IF(G8=SUM(G11,G14,G17,G20,G23,G26,G29,G32,G35,G38,G41,G44,G47,G50,G53,G56,G59,G62,G65,G68,G71,G74,),"",SUM(G11,G14,G17,G20,G23,G26,G29,G32,G35,G38,G41,G44,G47,G50,G53,G56,G59,G62,G65,G68,G71,G74,)) | H3: =IF(H8=SUM(H11,H14,H17,H20,H23,H26,H29,H32,H35,H38,H41,H44,H47,H50,H53,H56,H59,H62,H65,H68,H71,H74,),"",SUM(H11,H14,H17,H20,H23,H26,H29,H32,H35,H38,H41,H44,H47,H50,H53,H56,H59,H62,H65,H68,H71,H74,)) | I3: =IF(I8=SUM(I11,I14,I17,I20,I23,I26,I29,I32,I35,I38,I41,I44,I47,I50,I53,I56,I59,I62,I65,I68,I71,I74,),"",SUM(I11,I14,I17,I20,I23,I26,I29,I32,I35,I38,I41,I44,I47,I50,I53,I56,I59,I62,I65,I68,I71,I74,)) | J3: =IF(J8=SUM(J11,J14,J17,J20,J23,J26,J29,J32,J35,J38,J41,J44,J47,J50,J53,J56,J59,J62,J65,J68,J71,J74,),"",SUM(J11,J14,J17,J20,J23,J26,J29,J32,J35,J38,J41,J44,J47,J50,J53,J56,J59,J62,J65,J68,J71,J74,)) | K3: =IF(K8=SUM(K11,K14,K17,K20,K23,K26,K29,K32,K35,K38,K41,K44,K47,K50,K53,K56,K59,K62,K65,K68,K71,K74,),"",SUM(K11,K14,K17,K20,K23,K26,K29,K32,K35,K38,K41,K44,K47,K50,K53,K56,K59,K62,K65,K68,K71,K74,)) | ... T3: =IF(T8=SUM(T11,T14,T17,T20,T23,T26,T29,T32,T35,T38,T41,T44,T47,T50,T53,T56,T59,T62,T65,T68,T71,T74,),"",SUM(T11,T14,T17,T20,T23,T26,T29,T32,T35,T38,T41,T44,T47,T50,T53,T56,T59,T62,T65,T68,T71,T74,))
A4: 區域及特殊族群別 Locality & Ethnos | D4: 兒童少年受虐/間題類型 (人數)By Types/Matters (Person)
D5: 總計 Total | G5: 遺棄 Abandon | K5: 身心不當對待Physical Emotional Abuse | S5: 目睹家暴 Witnessing Domestic Violence
G6: 棄嬰 Abandoned Infants | I6: 棄兒 Abandoned Children | K6: 身體不當對待 Physical Abuse | M6: 精神不當對待 Emotional Abuse | O6: 性不當對待 Sexual Abuse | Q6: 疏忽 Neglect
D7: 合計 SubTotal | E7: 男 Male | F7: 女 Female | G7: 男 Male | H7: 女 Female | I7: 男 Male | J7: 女 Female | K7: 男 Male | L7: 女 Female | M7: 男 Male | N7: 女 Female | O7: 男 Male | P7: 女 Female | Q7: 男 Male | R7: 女 Female | S7: 男 Male | T7: 女 Female
A8: 總計 | B8: 計 | C8: Total | D8: 5352 | E8: 2421 | F8: 2931 | G8: 2 | H8: 4 | I8: 2 | J8: 0 | K8: 1714 | L8: 1112 | M8: 96 | N8: 107 | O8: 274 | P8: 1454 | Q8: 317 | R8: 237 | S8: 16 | T8: 17
A9: Total | B9: 一般 | C9: General | D9: 4867 | E9: 2222 | F9: 2645 | G9: 2 | H9: 4 | I9: 2 | J9: 0 | K9: 1579 | L9: 1024 | M9: 89 | N9: 101 | O9: 251 | P9: 1291 | Q9: 283 | R9: 211 | S9: 16 | T9: 14
B10: 原住民 | C10: Indigenous | D10: 485 | E10: 199 | F10: 286 | G10: 0 | H10: 0 | I10: 0 | J10: 0 | K10: 135 | L10: 88 | M10: 7 | N10: 6 | O10: 23 | P10: 163 | Q10: 34 | R10: 26 | S10: 0 | T10: 3
A11: 新北市 | B11: 計 | C11: Total | D11: 1151 | E11: 500 | F11: 651 | G11: 0 | H11: 0 | I11: 1 | J11: 0 | K11: 368 | L11: 270 | M11: 34 | N11: 32 | O11: 51 | P11: 320 | Q11: 40 | R11: 25 | S11: 6 | T11: 4
A12: New Taipei City | B12: 一般 | C12: General | D12: 1095 | E12: 480 | F12: 615 | G12: 0 | H12: 0 | I12: 1 | J12: 0 | K12: 353 | L12: 249 | M12: 33 | N12: 29 | O12: 48 | P12: 309 | Q12: 39 | R12: 24 | S12: 6 | T12: 4
B13: 原住民 | C13: Indigenous | D13: 56 | E13: 20 | F13: 36 | G13: 0 | H13: 0 | I13: 0 | J13: 0 | K13: 15 | L13: 21 | M13: 1 | N13: 3 | O13: 3 | P13: 11 | Q13: 1 | R13: 1 | S13: 0 | T13: 0
A14: 臺北市 | B14: 計 | C14: Total | D14: 519 | E14: 263 | F14: 256 | G14: 0 | H14: 1 | I14: 0 | J14: 0 | K14: 177 | L14: 105 | M14: 4 | N14: 8 | O14: 37 | P14: 119 | Q14: 43 | R14: 20 | S14: 2 | T14: 3
A15: Taipei City | B15: 一般 | C15: General | D15: 510 | E15: 258 | F15: 252 | G15: 0 | H15: 1 | I15: 0 | J15: 0 | K15: 173 | L15: 104 | M15: 4 | N15: 8 | O15: 37 | P15: 117 | Q15: 42 | R15: 19 | S15: 2 | T15: 3
B16: 原住民 | C16: Indigenous | D16: 9 | E16: 5 | F16: 4 | G16: 0 | H16: 0 | I16: 0 | J16: 0 | K16: 4 | L16: 1 | M16: 0 | N16: 0 | O16: 0 | P16: 2 | Q16: 1 | R16: 1 | S16: 0 | T16: 0
A17: 桃園市 | B17: 計 | C17: Total | D17: 424 | E17: 200 | F17: 224 | G17: 0 | H17: 1 | I17: 0 | J17: 0 | K17: 164 | L17: 101 | M17: 1 | N17: 0 | O17: 18 | P17: 114 | Q17: 17 | R17: 8 | S17: 0 | T17: 0
A18: Taoyuan City | B18: 一般 | C18: General | D18: 363 | E18: 172 | F18: 191 | G18: 0 | H18: 1 | I18: 0 | J18: 0 | K18: 142 | L18: 89 | M18: 1 | N18: 0 | O18: 16 | P18: 94 | Q18: 13 | R18: 7 | S18: 0 | T18: 0
B19: 原住民 | C19: Indigenous | D19: 61 | E19: 28 | F19: 33 | G19: 0 | H19: 0 | I19: 0 | J19: 0 | K19: 22 | L19: 12 | M19: 0 | N19: 0 | O19: 2 | P19: 20 | Q19: 4 | R19: 1 | S19: 0 | T19: 0
A20: 臺中市 | B20: 計 | C20: Total | D20: 709 | E20: 358 | F20: 351 | G20: 0 | H20: 0 | I20: 0 | J20: 0 | K20: 289 | L20: 163 | M20: 15 | N20: 7 | O20: 34 | P20: 165 | Q20: 19 | R20: 16 | S20: 1 | T20: 0
A21: Taichung City | B21: 一般 | C21: General | D21: 658 | E21: 330 | F21: 328 | G21: 0 | H21: 0 | I21: 0 | J21: 0 | K21: 272 | L21: 154 | M21: 14 | N21: 6 | O21: 29 | P21: 155 | Q21: 14 | R21: 13 | S21: 1 | T21: 0
B22: 原住民 | C22: Indigenous | D22: 51 | E22: 28 | F22: 23 | G22: 0 | H22: 0 | I22: 0 | J22: 0 | K22: 17 | L22: 9 | M22: 1 | N22: 1 | O22: 5 | P22: 10 | Q22: 5 | R22: 3 | S22: 0 | T22: 0
A23: 臺南市 | B23: 計 | C23: Total | D23: 319 | E23: 164 | F23: 155 | G23: 0 | H23: 1 | I23: 1 | J23: 0 | K23: 97 | L23: 47 | M23: 6 | N23: 15 | O23: 16 | P23: 66 | Q23: 43 | R23: 26 | S23: 1 | T23: 0
A24: Tainan City | B24: 一般 | C24: General | D24: 304 | E24: 153 | F24: 151 | G24: 0 | H24: 1 | I24: 1 | J24: 0 | K24: 92 | L24: 45 | M24: 6 | N24: 15 | O24: 16 | P24: 64 | Q24: 37 | R24: 26 | S24: 1 | T24: 0
B25: 原住民 | C25: Indigenous | D25: 15 | E25: 11 | F25: 4 | G25: 0 | H25: 0 | I25: 0 | J25: 0 | K25: 5 | L25: 2 | M25: 0 | N25: 0 | O25: 0 | P25: 2 | Q25: 6 | R25: 0 | S25: 0 | T25: 0
A26: 高雄市 | B26: 計 | C26: Total | D26: 682 | E26: 316 | F26: 366 | G26: 0 | H26: 0 | I26: 0 | J26: 0 | K26: 230 | L26: 144 | M26: 13 | N26: 11 | O26: 15 | P26: 174 | Q26: 56 | R26: 32 | S26: 2 | T26: 5
A27: Kaohsiung City | B27: 一般 | C27: General | D27: 636 | E27: 297 | F27: 339 | G27: 0 | H27: 0 | I27: 0 | J27: 0 | K27: 214 | L27: 135 | M27: 12 | N27: 11 | O27: 15 | P27: 159 | Q27: 54 | R27: 29 | S27: 2 | T27: 5
B28: 原住民 | C28: Indigenous | D28: 46 | E28: 19 | F28: 27 | G28: 0 | H28: 0 | I28: 0 | J28: 0 | K28: 16 | L28: 9 | M28: 1 | N28: 0 | O28: 0 | P28: 15 | Q28: 2 | R28: 3 | S28: 0 | T28: 0
A29: 宜蘭縣 | B29: 計 | C29: Total | D29: 35 | E29: 7 | F29: 28 | G29: 0 | H29: 0 | I29: 0 | J29: 0 | K29: 6 | L29: 10 | M29: 0 | N29: 0 | O29: 1 | P29: 17 | Q29: 0 | R29: 1 | S29: 0 | T29: 0
A30: Yilan County | B30: 一般 | C30: General | D30: 33 | E30: 7 | F30: 26 | G30: 0 | H30: 0 | I30: 0 | J30: 0 | K30: 6 | L30: 10 | M30: 0 | N30: 0 | O30: 1 | P30: 15 | Q30: 0 | R30: 1 | S30: 0 | T30: 0
B31: 原住民 | C31: Indigenous | D31: 2 | E31: 0 | F31: 2 | G31: 0 | H31: 0 | I31: 0 | J31: 0 | K31: 0 | L31: 0 | M31: 0 | N31: 0 | O31: 0 | P31: 2 | Q31: 0 | R31: 0 | S31: 0 | T31: 0
A32: 新竹縣 | B32: 計 | C32: Total | D32: 184 | E32: 80 | F32: 104 | G32: 0 | H32: 0 | I32: 0 | J32: 0 | K32: 51 | L32: 41 | M32: 8 | N32: 11 | O32: 4 | P32: 33 | Q32: 16 | R32: 19 | S32: 1 | T32: 0
A33: Hsinchu County | B33: 一般 | C33: General | D33: 148 | E33: 71 | F33: 77 | G33: 0 | H33: 0 | I33: 0 | J33: 0 | K33: 46 | L33: 31 | M33: 7 | N33: 10 | O33: 4 | P33: 24 | Q33: 13 | R33: 12 | S33: 1 | T33: 0
B34: 原住民 | C34: Indigenous | D34: 36 | E34: 9 | F34: 27 | G34: 0 | H34: 0 | I34: 0 | J34: 0 | K34: 5 | L34: 10 | M34: 1 | N34: 1 | O34: 0 | P34: 9 | Q34: 3 | R34: 7 | S34: 0 | T34: 0
A35: 苗栗縣 | B35: 計 | C35: Total | D35: 91 | E35: 23 | F35: 68 | G35: 0 | H35: 0 | I35: 0 | J35: 0 | K35: 13 | L35: 13 | M35: 2 | N35: 3 | O35: 3 | P35: 44 | Q35: 5 | R35: 8 | S35: 0 | T35: 0
A36: Miaoli County | B36: 一般 | C36: General | D36: 80 | E36: 21 | F36: 59 | G36: 0 | H36: 0 | I36: 0 | J36: 0 | K36: 12 | L36: 11 | M36: 2 | N36: 3 | O36: 2 | P36: 37 | Q36: 5 | R36: 8 | S36: 0 | T36: 0
B37: 原住民 | C37: Indigenous | D37: 11 | E37: 2 | F37: 9 | G37: 0 | H37: 0 | I37: 0 | J37: 0 | K37: 1 | L37: 2 | M37: 0 | N37: 0 | O37: 1 | P37: 7 | Q37: 0 | R37: 0 | S37: 0 | T37: 0
A38: 彰化縣 | B38: 計 | C38: Total | D38: 223 | E38: 100 | F38: 123 | G38: 1 | H38: 1 | I38: 0 | J38: 0 | K38: 67 | L38: 35 | M38: 7 | N38: 10 | O38: 17 | P38: 67 | Q38: 6 | R38: 9 | S38: 2 | T38: 1
A39: Changhua County | B39: 一般 | C39: General | D39: 217 | E39: 99 | F39: 118 | G39: 1 | H39: 1 | I39: 0 | J39: 0 | K39: 66 | L39: 34 | M39: 7 | N39: 9 | O39: 17 | P39: 65 | Q39: 6 | R39: 8 | S39: 2 | T39: 1
B40: 原住民 | C40: Indigenous | D40: 6 | E40: 1 | F40: 5 | G40: 0 | H40: 0 | I40: 0 | J40: 0 | K40: 1 | L40: 1 | M40: 0 | N40: 1 | O40: 0 | P40: 2 | Q40: 0 | R40: 1 | S40: 0 | T40: 0
...

Sheet 2024
A1: 兒童及少年保護-受虐/問題類型Child and Youth Protection Cases - Type/Matter of Abused
A2: 單位：人 Unit : Person
A3: 民國113年, 2024 | D3: =IF(D8=SUM(D11,D14,D17,D20,D23,D26,D29,D32,D35,D38,D41,D44,D47,D50,D53,D56,D59,D62,D65,D68,D71,D74,),"",SUM(D11,D14,D17,D20,D23,D26,D29,D32,D35,D38,D41,D44,D47,D50,D53,D56,D59,D62,D65,D68,D71,D74,)) | E3: =IF(E8=SUM(E11,E14,E17,E20,E23,E26,E29,E32,E35,E38,E41,E44,E47,E50,E53,E56,E59,E62,E65,E68,E71,E74,),"",SUM(E11,E14,E17,E20,E23,E26,E29,E32,E35,E38,E41,E44,E47,E50,E53,E56,E59,E62,E65,E68,E71,E74,)) | F3: =IF(F8=SUM(F11,F14,F17,F20,F23,F26,F29,F32,F35,F38,F41,F44,F47,F50,F53,F56,F59,F62,F65,F68,F71,F74,),"",SUM(F11,F14,F17,F20,F23,F26,F29,F32,F35,F38,F41,F44,F47,F50,F53,F56,F59,F62,F65,F68,F71,F74,)) | G3: =IF(G8=SUM(G11,G14,G17,G20,G23,G26,G29,G32,G35,G38,G41,G44,G47,G50,G53,G56,G59,G62,G65,G68,G71,G74,),"",SUM(G11,G14,G17,G20,G23,G26,G29,G32,G35,G38,G41,G44,G47,G50,G53,G56,G59,G62,G65,G68,G71,G74,)) | H3: =IF(H8=SUM(H11,H14,H17,H20,H23,H26,H29,H32,H35,H38,H41,H44,H47,H50,H53,H56,H59,H62,H65,H68,H71,H74,),"",SUM(H11,H14,H17,H20,H23,H26,H29,H32,H35,H38,H41,H44,H47,H50,H53,H56,H59,H62,H65,H68,H71,H74,)) | I3: =IF(I8=SUM(I11,I14,I17,I20,I23,I26,I29,I32,I35,I38,I41,I44,I47,I50,I53,I56,I59,I62,I65,I68,I71,I74,),"",SUM(I11,I14,I17,I20,I23,I26,I29,I32,I35,I38,I41,I44,I47,I50,I53,I56,I59,I62,I65,I68,I71,I74,)) | J3: =IF(J8=SUM(J11,J14,J17,J20,J23,J26,J29,J32,J35,J38,J41,J44,J47,J50,J53,J56,J59,J62,J65,J68,J71,J74,),"",SUM(J11,J14,J17,J20,J23,J26,J29,J32,J35,J38,J41,J44,J47,J50,J53,J56,J59,J62,J65,J68,J71,J74,)) | K3: =IF(K8=SUM(K11,K14,K17,K20,K23,K26,K29,K32,K35,K38,K41,K44,K47,K50,K53,K56,K59,K62,K65,K68,K71,K74,),"",SUM(K11,K14,K17,K20,K23,K26,K29,K32,K35,K38,K41,K44,K47,K50,K53,K56,K59,K62,K65,K68,K71,K74,)) | ... V3: =IF(V8=SUM(V11,V14,V17,V20,V23,V26,V29,V32,V35,V38,V41,V44,V47,V50,V53,V56,V59,V62,V65,V68,V71,V74,),"",SUM(V11,V14,V17,V20,V23,V26,V29,V32,V35,V38,V41,V44,V47,V50,V53,V56,V59,V62,V65,V68,V71,V74,))
A4: 區域及特殊族群別 Locality & Ethnos | D4: 兒童少年受虐/間題類型 (人數)By Types/Matters (Person)
D5: 總計 Total | G5: 遺棄 Abandon | K5: 身心不當對待Physical Emotional Abuse | S5: 目睹家暴 Witnessing Domestic Violence | U5: 兒少物質濫用
G6: 棄嬰 Abandoned Infants | I6: 棄兒 Abandoned Children | K6: 身體不當對待 Physical Abuse | M6: 精神不當對待 Emotional Abuse | O6: 性不當對待 Sexual Abuse | Q6: 疏忽 Neglect
D7: 合計 SubTotal | E7: 男 Male | F7: 女 Female | G7: 男 Male | H7: 女 Female | I7: 男 Male | J7: 女 Female | K7: 男 Male | L7: 女 Female | M7: 男 Male | N7: 女 Female | O7: 男 Male | P7: 女 Female | Q7: 男 Male | R7: 女 Female | S7: 男 Male | T7: 女 Female | U7: 男 Male | V7: 女 Female
A8: 總計 | B8: 計 | C8: Total | D8: 10810 | E8: 4836 | F8: 5974 | G8: 5 | H8: 6 | I8: 10 | J8: 4 | K8: 3340 | L8: 2326 | M8: 254 | N8: 238 | O8: 585 | P8: 2882 | Q8: 600 | R8: 476 | S8: 37 | T8: 31 | U8: 5 | V8: 11
A9: Total | B9: 一般 | C9: General | D9: 9795 | E9: 4375 | F9: 5420 | G9: 5 | H9: 6 | I9: 9 | J9: 4 | K9: 3055 | L9: 2155 | M9: 232 | N9: 212 | O9: 506 | P9: 2581 | Q9: 531 | R9: 429 | S9: 34 | T9: 29 | U9: 3 | V9: 4
B10: 原住民 | C10: Indigenous | D10: 1015 | E10: 461 | F10: 554 | G10: 0 | H10: 0 | I10: 1 | J10: 0 | K10: 285 | L10: 171 | M10: 22 | N10: 26 | O10: 79 | P10: 301 | Q10: 69 | R10: 47 | S10: 3 | T10: 2 | U10: 2 | V10: 7
A11: 新北市 | B11: 計 | C11: Total | D11: 2222 | E11: 974 | F11: 1248 | G11: 0 | H11: 0 | I11: 0 | J11: 0 | K11: 736 | L11: 485 | M11: 63 | N11: 53 | O11: 103 | P11: 650 | Q11: 62 | R11: 49 | S11: 10 | T11: 11 | U11: 0 | V11: 0
A12: New Taipei City | B12: 一般 | C12: General | D12: 2092 | E12: 917 | F12: 1175 | G12: 0 | H12: 0 | I12: 0 | J12: 0 | K12: 688 | L12: 456 | M12: 60 | N12: 47 | O12: 99 | P12: 614 | Q12: 60 | R12: 47 | S12: 10 | T12: 11 | U12: 0 | V12: 0
B13: 原住民 | C13: Indigenous | D13: 130 | E13: 57 | F13: 73 | G13: 0 | H13: 0 | I13: 0 | J13: 0 | K13: 48 | L13: 29 | M13: 3 | N13: 6 | O13: 4 | P13: 36 | Q13: 2 | R13: 2 | S13: 0 | T13: 0 | U13: 0 | V13: 0
A14: 臺北市 | B14: 計 | C14: Total | D14: 1077 | E14: 498 | F14: 579 | G14: 0 | H14: 0 | I14: 0 | J14: 0 | K14: 328 | L14: 230 | M14: 12 | N14: 13 | O14: 80 | P14: 262 | Q14: 77 | R14: 72 | S14: 1 | T14: 2 | U14: 0 | V14: 0
A15: Taipei City | B15: 一般 | C15: General | D15: 1051 | E15: 483 | F15: 568 | G15: 0 | H15: 0 | I15: 0 | J15: 0 | K15: 317 | L15: 225 | M15: 12 | N15: 13 | O15: 80 | P15: 257 | Q15: 73 | R15: 71 | S15: 1 | T15: 2 | U15: 0 | V15: 0
B16: 原住民 | C16: Indigenous | D16: 26 | E16: 15 | F16: 11 | G16: 0 | H16: 0 | I16: 0 | J16: 0 | K16: 11 | L16: 5 | M16: 0 | N16: 0 | O16: 0 | P16: 5 | Q16: 4 | R16: 1 | S16: 0 | T16: 0 | U16: 0 | V16: 0
A17: 桃園市 | B17: 計 | C17: Total | D17: 1050 | E17: 491 | F17: 559 | G17: 0 | H17: 0 | I17: 0 | J17: 0 | K17: 394 | L17: 249 | M17: 12 | N17: 9 | O17: 50 | P17: 288 | Q17: 35 | R17: 12 | S17: 0 | T17: 1 | U17: 0 | V17: 0
A18: Taoyuan City | B18: 一般 | C18: General | D18: 892 | E18: 409 | F18: 483 | G18: 0 | H18: 0 | I18: 0 | J18: 0 | K18: 327 | L18: 223 | M18: 11 | N18: 9 | O18: 41 | P18: 240 | Q18: 30 | R18: 10 | S18: 0 | T18: 1 | U18: 0 | V18: 0
B19: 原住民 | C19: Indigenous | D19: 158 | E19: 82 | F19: 76 | G19: 0 | H19: 0 | I19: 0 | J19: 0 | K19: 67 | L19: 26 | M19: 1 | N19: 0 | O19: 9 | P19: 48 | Q19: 5 | R19: 2 | S19: 0 | T19: 0 | U19: 0 | V19: 0
A20: 臺中市 | B20: 計 | C20: Total | D20: 1339 | E20: 654 | F20: 685 | G20: 0 | H20: 0 | I20: 1 | J20: 0 | K20: 489 | L20: 321 | M20: 32 | N20: 35 | O20: 70 | P20: 288 | Q20: 53 | R20: 36 | S20: 9 | T20: 5 | U20: 0 | V20: 0
A21: Taichung City | B21: 一般 | C21: General | D21: 1264 | E21: 619 | F21: 645 | G21: 0 | H21: 0 | I21: 1 | J21: 0 | K21: 464 | L21: 305 | M21: 29 | N21: 34 | O21: 66 | P21: 268 | Q21: 50 | R21: 34 | S21: 9 | T21: 4 | U21: 0 | V21: 0
B22: 原住民 | C22: Indigenous | D22: 75 | E22: 35 | F22: 40 | G22: 0 | H22: 0 | I22: 0 | J22: 0 | K22: 25 | L22: 16 | M22: 3 | N22: 1 | O22: 4 | P22: 20 | Q22: 3 | R22: 2 | S22: 0 | T22: 1 | U22: 0 | V22: 0
A23: 臺南市 | B23: 計 | C23: Total | D23: 572 | E23: 271 | F23: 301 | G23: 0 | H23: 0 | I23: 4 | J23: 2 | K23: 178 | L23: 139 | M23: 6 | N23: 7 | O23: 23 | P23: 115 | Q23: 59 | R23: 37 | S23: 1 | T23: 1 | U23: 0 | V23: 0
A24: Tainan City | B24: 一般 | C24: General | D24: 548 | E24: 260 | F24: 288 | G24: 0 | H24: 0 | I24: 4 | J24: 2 | K24: 170 | L24: 135 | M24: 6 | N24: 7 | O24: 22 | P24: 108 | Q24: 57 | R24: 35 | S24: 1 | T24: 1 | U24: 0 | V24: 0
B25: 原住民 | C25: Indigenous | D25: 24 | E25: 11 | F25: 13 | G25: 0 | H25: 0 | I25: 0 | J25: 0 | K25: 8 | L25: 4 | M25: 0 | N25: 0 | O25: 1 | P25: 7 | Q25: 2 | R25: 2 | S25: 0 | T25: 0 | U25: 0 | V25: 0
A26: 高雄市 | B26: 計 | C26: Total | D26: 1157 | E26: 542 | F26: 615 | G26: 3 | H26: 5 | I26: 0 | J26: 1 | K26: 401 | L26: 261 | M26: 26 | N26: 30 | O26: 51 | P26: 263 | Q26: 57 | R26: 54 | S26: 4 | T26: 1 | U26: 0 | V26: 0
A27: Kaohsiung City | B27: 一般 | C27: General | D27: 1084 | E27: 509 | F27: 575 | G27: 3 | H27: 5 | I27: 0 | J27: 1 | K27: 387 | L27: 246 | M27: 23 | N27: 26 | O27: 43 | P27: 245 | Q27: 51 | R27: 51 | S27: 2 | T27: 1 | U27: 0 | V27: 0
B28: 原住民 | C28: Indigenous | D28: 73 | E28: 33 | F28: 40 | G28: 0 | H28: 0 | I28: 0 | J28: 0 | K28: 14 | L28: 15 | M28: 3 | N28: 4 | O28: 8 | P28: 18 | Q28: 6 | R28: 3 | S28: 2 | T28: 0 | U28: 0 | V28: 0
A29: 宜蘭縣 | B29: 計 | C29: Total | D29: 141 | E29: 52 | F29: 89 | G29: 0 | H29: 0 | I29: 0 | J29: 0 | K29: 36 | L29: 25 | M29: 2 | N29: 6 | O29: 4 | P29: 54 | Q29: 10 | R29: 4 | S29: 0 | T29: 0 | U29: 0 | V29: 0
A30: Yilan County | B30: 一般 | C30: General | D30: 128 | E30: 45 | F30: 83 | G30: 0 | H30: 0 | I30: 0 | J30: 0 | K30: 34 | L30: 25 | M30: 1 | N30: 6 | O30: 0 | P30: 48 | Q30: 10 | R30: 4 | S30: 0 | T30: 0 | U30: 0 | V30: 0
B31: 原住民 | C31: Indigenous | D31: 13 | E31: 7 | F31: 6 | G31: 0 | H31: 0 | I31: 0 | J31: 0 | K31: 2 | L31: 0 | M31: 1 | N31: 0 | O31: 4 | P31: 6 | Q31: 0 | R31: 0 | S31: 0 | T31: 0 | U31: 0 | V31: 0
A32: 新竹縣 | B32: 計 | C32: Total | D32: 416 | E32: 181 | F32: 235 | G32: 0 | H32: 1 | I32: 2 | J32: 0 | K32: 103 | L32: 84 | M32: 12 | N32: 6 | O32: 25 | P32: 118 | Q32: 35 | R32: 26 | S32: 4 | T32: 0 | U32: 0 | V32: 0
A33: Hsinchu County | B33: 一般 | C33: General | D33: 345 | E33: 144 | F33: 201 | G33: 0 | H33: 1 | I33: 1 | J33: 0 | K33: 87 | L33: 76 | M33: 12 | N33: 5 | O33: 17 | P33: 102 | Q33: 23 | R33: 17 | S33: 4 | T33: 0 | U33: 0 | V33: 0
B34: 原住民 | C34: Indigenous | D34: 71 | E34: 37 | F34: 34 | G34: 0 | H34: 0 | I34: 1 | J34: 0 | K34: 16 | L34: 8 | M34: 0 | N34: 1 | O34: 8 | P34: 16 | Q34: 12 | R34: 9 | S34: 0 | T34: 0 | U34: 0 | V34: 0
A35: 苗栗縣 | B35: 計 | C35: Total | D35: 148 | E35: 46 | F35: 102 | G35: 0 | H35: 0 | I35: 0 | J35: 0 | K35: 24 | L35: 24 | M35: 3 | N35: 4 | O35: 9 | P35: 64 | Q35: 10 | R35: 10 | S35: 0 | T35: 0 | U35: 0 | V35: 0
A36: Miaoli County | B36: 一般 | C36: General | D36: 131 | E36: 41 | F36: 90 | G36: 0 | H36: 0 | I36: 0 | J36: 0 | K36: 22 | L36: 20 | M36: 3 | N36: 2 | O36: 8 | P36: 58 | Q36: 8 | R36: 10 | S36: 0 | T36: 0 | U36: 0 | V36: 0
B37: 原住民 | C37: Indigenous | D37: 17 | E37: 5 | F37: 12 | G37: 0 | H37: 0 | I37: 0 | J37: 0 | K37: 2 | L37: 4 | M37: 0 | N37: 2 | O37: 1 | P37: 6 | Q37: 2 | R37: 0 | S37: 0 | T37: 0 | U37: 0 | V37: 0
A38: 彰化縣 | B38: 計 | C38: Total | D38: 544 | E38: 226 | F38: 318 | G38: 0 | H38: 0 | I38: 0 | J38: 0 | K38: 124 | L38: 89 | M38: 38 | N38: 24 | O38: 33 | P38: 172 | Q38: 31 | R38: 32 | S38: 0 | T38: 1 | U38: 0 | V38: 0
A39: Changhua County | B39: 一般 | C39: General | D39: 517 | E39: 216 | F39: 301 | G39: 0 | H39: 0 | I39: 0 | J39: 0 | K39: 120 | L39: 84 | M39: 37 | N39: 24 | O39: 29 | P39: 161 | Q39: 30 | R39: 31 | S39: 0 | T39: 1 | U39: 0 | V39: 0
B40: 原住民 | C40: Indigenous | D40: 27 | E40: 10 | F40: 17 | G40: 0 | H40: 0 | I40: 0 | J40: 0 | K40: 4 | L40: 5 | M40: 1 | N40: 0 | O40: 4 | P40: 11 | Q40: 1 | R40: 1 | S40: 0 | T40: 0 | U40: 0 | V40: 0
...

Sheet July-Dec., 2024
A1: 兒童及少年保護-受虐/問題類型Child and Youth Protection Cases - Type/Matter of Abused
A2: 單位：人 Unit : Person
A3: 民國113年7-12月 July-Dec., 2024 | D3: =IF(D8=SUM(D11,D14,D17,D20,D23,D26,D29,D32,D35,D38,D41,D44,D47,D50,D53,D56,D59,D62,D65,D68,D71,D74,),"",SUM(D11,D14,D17,D20,D23,D26,D29,D32,D35,D38,D41,D44,D47,D50,D53,D56,D59,D62,D65,D68,D71,D74,)) | E3: =IF(E8=SUM(E11,E14,E17,E20,E23,E26,E29,E32,E35,E38,E41,E44,E47,E50,E53,E56,E59,E62,E65,E68,E71,E74,),"",SUM(E11,E14,E17,E20,E23,E26,E29,E32,E35,E38,E41,E44,E47,E50,E53,E56,E59,E62,E65,E68,E71,E74,)) | F3: =IF(F8=SUM(F11,F14,F17,F20,F23,F26,F29,F32,F35,F38,F41,F44,F47,F50,F53,F56,F59,F62,F65,F68,F71,F74,),"",SUM(F11,F14,F17,F20,F23,F26,F29,F32,F35,F38,F41,F44,F47,F50,F53,F56,F59,F62,F65,F68,F71,F74,)) | G3: =IF(G8=SUM(G11,G14,G17,G20,G23,G26,G29,G32,G35,G38,G41,G44,G47,G50,G53,G56,G59,G62,G65,G68,G71,G74,),"",SUM(G11,G14,G17,G20,G23,G26,G29,G32,G35,G38,G41,G44,G47,G50,G53,G56,G59,G62,G65,G68,G71,G74,)) | H3: =IF(H8=SUM(H11,H14,H17,H20,H23,H26,H29,H32,H35,H38,H41,H44,H47,H50,H53,H56,H59,H62,H65,H68,H71,H74,),"",SUM(H11,H14,H17,H20,H23,H26,H29,H32,H35,H38,H41,H44,H47,H50,H53,H56,H59,H62,H65,H68,H71,H74,)) | I3: =IF(I8=SUM(I11,I14,I17,I20,I23,I26,I29,I32,I35,I38,I41,I44,I47,I50,I53,I56,I59,I62,I65,I68,I71,I74,),"",SUM(I11,I14,I17,I20,I23,I26,I29,I32,I35,I38,I41,I44,I47,I50,I53,I56,I59,I62,I65,I68,I71,I74,)) | J3: =IF(J8=SUM(J11,J14,J17,J20,J23,J26,J29,J32,J35,J38,J41,J44,J47,J50,J53,J56,J59,J62,J65,J68,J71,J74,),"",SUM(J11,J14,J17,J20,J23,J26,J29,J32,J35,J38,J41,J44,J47,J50,J53,J56,J59,J62,J65,J68,J71,J74,)) | K3: =IF(K8=SUM(K11,K14,K17,K20,K23,K26,K29,K32,K35,K38,K41,K44,K47,K50,K53,K56,K59,K62,K65,K68,K71,K74,),"",SUM(K11,K14,K17,K20,K23,K26,K29,K32,K35,K38,K41,K44,K47,K50,K53,K56,K59,K62,K65,K68,K71,K74,)) | ... V3: =IF(V8=SUM(V11,V14,V17,V20,V23,V26,V29,V32,V35,V38,V41,V44,V47,V50,V53,V56,V59,V62,V65,V68,V71,V74,),"",SUM(V11,V14,V17,V20,V23,V26,V29,V32,V35,V38,V41,V44,V47,V50,V53,V56,V59,V62,V65,V68,V71,V74,))
A4: 區域及特殊族群別 Locality & Ethnos | D4: 兒童少年受虐/間題類型 (人數)By Types/Matters (Person)
D5: 總計 Total | G5: 遺棄 Abandon | K5: 身心不當對待Physical Emotional Abuse | S5: 目睹家暴 Witnessing Domestic Violence | U5: 兒少物質濫用
G6: 棄嬰 Abandoned Infants | I6: 棄兒 Abandoned Children | K6: 身體不當對待 Physical Abuse | M6: 精神不當對待 Emotional Abuse | O6: 性不當對待 Sexual Abuse | Q6: 疏忽 Neglect
D7: 合計 SubTotal | E7: 男 Male | F7: 女 Female | G7: 男 Male | H7: 女 Female | I7: 男 Male | J7: 女 Female | K7: 男 Male | L7: 女 Female | M7: 男 Male | N7: 女 Female | O7: 男 Male | P7: 女 Female | Q7: 男 Male | R7: 女 Female | S7: 男 Male | T7: 女 Female | U7: 男 Male | V7: 女 Female
A8: 總計 | B8: 計 | C8: Total | D8: 5039 | E8: 2315 | F8: 2724 | G8: 2 | H8: 1 | I8: 5 | J8: 1 | K8: 1536 | L8: 1084 | M8: 110 | N8: 94 | O8: 307 | P8: 1291 | Q8: 327 | R8: 233 | S8: 28 | T8: 20 | U8: 0 | V8: 0
A9: Total | B9: 一般 | C9: General | D9: 4540 | E9: 2086 | F9: 2454 | G9: 2 | H9: 1 | I9: 4 | J9: 1 | K9: 1396 | L9: 988 | M9: 100 | N9: 86 | O9: 269 | P9: 1151 | Q9: 290 | R9: 207 | S9: 25 | T9: 20 | U9: 0 | V9: 0
B10: 原住民 | C10: Indigenous | D10: 499 | E10: 229 | F10: 270 | G10: 0 | H10: 0 | I10: 1 | J10: 0 | K10: 140 | L10: 96 | M10: 10 | N10: 8 | O10: 38 | P10: 140 | Q10: 37 | R10: 26 | S10: 3 | T10: 0 | U10: 0 | V10: 0
A11: 新北市 | B11: 計 | C11: Total | D11: 1014 | E11: 463 | F11: 551 | G11: 0 | H11: 0 | I11: 0 | J11: 0 | K11: 325 | L11: 210 | M11: 36 | N11: 21 | O11: 60 | P11: 289 | Q11: 35 | R11: 23 | S11: 7 | T11: 8 | U11: 0 | V11: 0
A12: New Taipei City | B12: 一般 | C12: General | D12: 960 | E12: 444 | F12: 516 | G12: 0 | H12: 0 | I12: 0 | J12: 0 | K12: 309 | L12: 195 | M12: 35 | N12: 20 | O12: 59 | P12: 270 | Q12: 34 | R12: 23 | S12: 7 | T12: 8 | U12: 0 | V12: 0
B13: 原住民 | C13: Indigenous | D13: 54 | E13: 19 | F13: 35 | G13: 0 | H13: 0 | I13: 0 | J13: 0 | K13: 16 | L13: 15 | M13: 1 | N13: 1 | O13: 1 | P13: 19 | Q13: 1 | R13: 0 | S13: 0 | T13: 0 | U13: 0 | V13: 0
A14: 臺北市 | B14: 計 | C14: Total | D14: 506 | E14: 246 | F14: 260 | G14: 0 | H14: 0 | I14: 0 | J14: 0 | K14: 156 | L14: 108 | M14: 4 | N14: 6 | O14: 36 | P14: 107 | Q14: 49 | R14: 38 | S14: 1 | T14: 1 | U14: 0 | V14: 0
A15: Taipei City | B15: 一般 | C15: General | D15: 500 | E15: 243 | F15: 257 | G15: 0 | H15: 0 | I15: 0 | J15: 0 | K15: 153 | L15: 105 | M15: 4 | N15: 6 | O15: 36 | P15: 107 | Q15: 49 | R15: 38 | S15: 1 | T15: 1 | U15: 0 | V15: 0
B16: 原住民 | C16: Indigenous | D16: 6 | E16: 3 | F16: 3 | G16: 0 | H16: 0 | I16: 0 | J16: 0 | K16: 3 | L16: 3 | M16: 0 | N16: 0 | O16: 0 | P16: 0 | Q16: 0 | R16: 0 | S16: 0 | T16: 0 | U16: 0 | V16: 0
A17: 桃園市 | B17: 計 | C17: Total | D17: 545 | E17: 259 | F17: 286 | G17: 0 | H17: 0 | I17: 0 | J17: 0 | K17: 213 | L17: 132 | M17: 1 | N17: 0 | O17: 28 | P17: 149 | Q17: 17 | R17: 4 | S17: 0 | T17: 1 | U17: 0 | V17: 0
A18: Taoyuan City | B18: 一般 | C18: General | D18: 447 | E18: 205 | F18: 242 | G18: 0 | H18: 0 | I18: 0 | J18: 0 | K18: 171 | L18: 115 | M18: 0 | N18: 0 | O18: 22 | P18: 124 | Q18: 12 | R18: 2 | S18: 0 | T18: 1 | U18: 0 | V18: 0
B19: 原住民 | C19: Indigenous | D19: 98 | E19: 54 | F19: 44 | G19: 0 | H19: 0 | I19: 0 | J19: 0 | K19: 42 | L19: 17 | M19: 1 | N19: 0 | O19: 6 | P19: 25 | Q19: 5 | R19: 2 | S19: 0 | T19: 0 | U19: 0 | V19: 0
A20: 臺中市 | B20: 計 | C20: Total | D20: 622 | E20: 315 | F20: 307 | G20: 0 | H20: 0 | I20: 0 | J20: 0 | K20: 216 | L20: 142 | M20: 10 | N20: 10 | O20: 50 | P20: 130 | Q20: 30 | R20: 21 | S20: 9 | T20: 4 | U20: 0 | V20: 0
A21: Taichung City | B21: 一般 | C21: General | D21: 589 | E21: 303 | F21: 286 | G21: 0 | H21: 0 | I21: 0 | J21: 0 | K21: 209 | L21: 132 | M21: 7 | N21: 10 | O21: 48 | P21: 120 | Q21: 30 | R21: 20 | S21: 9 | T21: 4 | U21: 0 | V21: 0
B22: 原住民 | C22: Indigenous | D22: 33 | E22: 12 | F22: 21 | G22: 0 | H22: 0 | I22: 0 | J22: 0 | K22: 7 | L22: 10 | M22: 3 | N22: 0 | O22: 2 | P22: 10 | Q22: 0 | R22: 1 | S22: 0 | T22: 0 | U22: 0 | V22: 0
A23: 臺南市 | B23: 計 | C23: Total | D23: 263 | E23: 128 | F23: 135 | G23: 0 | H23: 0 | I23: 1 | J23: 0 | K23: 78 | L23: 64 | M23: 5 | N23: 4 | O23: 13 | P23: 49 | Q23: 31 | R23: 18 | S23: 0 | T23: 0 | U23: 0 | V23: 0
A24: Tainan City | B24: 一般 | C24: General | D24: 248 | E24: 118 | F24: 130 | G24: 0 | H24: 0 | I24: 1 | J24: 0 | K24: 71 | L24: 61 | M24: 5 | N24: 4 | O24: 12 | P24: 47 | Q24: 29 | R24: 18 | S24: 0 | T24: 0 | U24: 0 | V24: 0
B25: 原住民 | C25: Indigenous | D25: 15 | E25: 10 | F25: 5 | G25: 0 | H25: 0 | I25: 0 | J25: 0 | K25: 7 | L25: 3 | M25: 0 | N25: 0 | O25: 1 | P25: 2 | Q25: 2 | R25: 0 | S25: 0 | T25: 0 | U25: 0 | V25: 0
A26: 高雄市 | B26: 計 | C26: Total | D26: 553 | E26: 259 | F26: 294 | G26: 1 | H26: 0 | I26: 0 | J26: 1 | K26: 184 | L26: 123 | M26: 11 | N26: 13 | O26: 24 | P26: 135 | Q26: 36 | R26: 21 | S26: 3 | T26: 1 | U26: 0 | V26: 0
A27: Kaohsiung City | B27: 一般 | C27: General | D27: 516 | E27: 244 | F27: 272 | G27: 1 | H27: 0 | I27: 0 | J27: 1 | K27: 177 | L27: 116 | M27: 10 | N27: 11 | O27: 21 | P27: 123 | Q27: 34 | R27: 20 | S27: 1 | T27: 1 | U27: 0 | V27: 0
B28: 原住民 | C28: Indigenous | D28: 37 | E28: 15 | F28: 22 | G28: 0 | H28: 0 | I28: 0 | J28: 0 | K28: 7 | L28: 7 | M28: 1 | N28: 2 | O28: 3 | P28: 12 | Q28: 2 | R28: 1 | S28: 2 | T28: 0 | U28: 0 | V28: 0
A29: 宜蘭縣 | B29: 計 | C29: Total | D29: 47 | E29: 21 | F29: 26 | G29: 0 | H29: 0 | I29: 0 | J29: 0 | K29: 13 | L29: 5 | M29: 1 | N29: 2 | O29: 2 | P29: 18 | Q29: 5 | R29: 1 | S29: 0 | T29: 0 | U29: 0 | V29: 0
A30: Yilan County | B30: 一般 | C30: General | D30: 44 | E30: 19 | F30: 25 | G30: 0 | H30: 0 | I30: 0 | J30: 0 | K30: 13 | L30: 5 | M30: 1 | N30: 2 | O30: 0 | P30: 17 | Q30: 5 | R30: 1 | S30: 0 | T30: 0 | U30: 0 | V30: 0
B31: 原住民 | C31: Indigenous | D31: 3 | E31: 2 | F31: 1 | G31: 0 | H31: 0 | I31: 0 | J31: 0 | K31: 0 | L31: 0 | M31: 0 | N31: 0 | O31: 2 | P31: 1 | Q31: 0 | R31: 0 | S31: 0 | T31: 0 | U31: 0 | V31: 0
A32: 新竹縣 | B32: 計 | C32: Total | D32: 212 | E32: 95 | F32: 117 | G32: 0 | H32: 1 | I32: 1 | J32: 0 | K32: 65 | L32: 54 | M32: 5 | N32: 5 | O32: 5 | P32: 45 | Q32: 17 | R32: 12 | S32: 2 | T32: 0 | U32: 0 | V32: 0
A33: Hsinchu County | B33: 一般 | C33: General | D33: 175 | E33: 77 | F33: 98 | G33: 0 | H33: 1 | I33: 0 | J33: 0 | K33: 56 | L33: 47 | M33: 5 | N33: 4 | O33: 4 | P33: 38 | Q33: 10 | R33: 8 | S33: 2 | T33: 0 | U33: 0 | V33: 0
B34: 原住民 | C34: Indigenous | D34: 37 | E34: 18 | F34: 19 | G34: 0 | H34: 0 | I34: 1 | J34: 0 | K34: 9 | L34: 7 | M34: 0 | N34: 1 | O34: 1 | P34: 7 | Q34: 7 | R34: 4 | S34: 0 | T34: 0 | U34: 0 | V34: 0
A35: 苗栗縣 | B35: 計 | C35: Total | D35: 75 | E35: 25 | F35: 50 | G35: 0 | H35: 0 | I35: 0 | J35: 0 | K35: 15 | L35: 16 | M35: 1 | N35: 2 | O35: 3 | P35: 30 | Q35: 6 | R35: 2 | S35: 0 | T35: 0 | U35: 0 | V35: 0
A36: Miaoli County | B36: 一般 | C36: General | D36: 66 | E36: 22 | F36: 44 | G36: 0 | H36: 0 | I36: 0 | J36: 0 | K36: 13 | L36: 13 | M36: 1 | N36: 1 | O36: 2 | P36: 28 | Q36: 6 | R36: 2 | S36: 0 | T36: 0 | U36: 0 | V36: 0
B37: 原住民 | C37: Indigenous | D37: 9 | E37: 3 | F37: 6 | G37: 0 | H37: 0 | I37: 0 | J37: 0 | K37: 2 | L37: 3 | M37: 0 | N37: 1 | O37: 1 | P37: 2 | Q37: 0 | R37: 0 | S37: 0 | T37: 0 | U37: 0 | V37: 0
A38: 彰化縣 | B38: 計 | C38: Total | D38: 260 | E38: 107 | F38: 153 | G38: 0 | H38: 0 | I38: 0 | J38: 0 | K38: 52 | L38: 41 | M38: 17 | N38: 8 | O38: 20 | P38: 83 | Q38: 18 | R38: 20 | S38: 0 | T38: 1 | U38: 0 | V38: 0
A39: Changhua County | B39: 一般 | C39: General | D39: 242 | E39: 103 | F39: 139 | G39: 0 | H39: 0 | I39: 0 | J39: 0 | K39: 50 | L39: 38 | M39: 16 | N39: 8 | O39: 20 | P39: 73 | Q39: 17 | R39: 19 | S39: 0 | T39: 1 | U39: 0 | V39: 0
B40: 原住民 | C40: Indigenous | D40: 18 | E40: 4 | F40: 14 | G40: 0 | H40: 0 | I40: 0 | J40: 0 | K40: 2 | L40: 3 | M40: 1 | N40: 0 | O40: 0 | P40: 10 | Q40: 1 | R40: 1 | S40: 0 | T40: 0 | U40: 0 | V40: 0
...

Sheet  Jan.-June, 2024
A1: 兒童及少年保護-受虐/問題類型Child and Youth Protection Cases - Type/Matter of Abused
A2: 單位：人 Unit : Person
A3: 民國113年1-6月,Jan.-June, 2024 | D3: =IF(D8=SUM(D11,D14,D17,D20,D23,D26,D29,D32,D35,D38,D41,D44,D47,D50,D53,D56,D59,D62,D65,D68,D71,D74,),"",SUM(D11,D14,D17,D20,D23,D26,D29,D32,D35,D38,D41,D44,D47,D50,D53,D56,D59,D62,D65,D68,D71,D74,)) | E3: =IF(E8=SUM(E11,E14,E17,E20,E23,E26,E29,E32,E35,E38,E41,E44,E47,E50,E53,E56,E59,E62,E65,E68,E71,E74,),"",SUM(E11,E14,E17,E20,E23,E26,E29,E32,E35,E38,E41,E44,E47,E50,E53,E56,E59,E62,E65,E68,E71,E74,)) | F3: =IF(F8=SUM(F11,F14,F17,F20,F23,F26,F29,F32,F35,F38,F41,F44,F47,F50,F53,F56,F59,F62,F65,F68,F71,F74,),"",SUM(F11,F14,F17,F20,F23,F26,F29,F32,F35,F38,F41,F44,F47,F50,F53,F56,F59,F62,F65,F68,F71,F74,)) | G3: =IF(G8=SUM(G11,G14,G17,G20,G23,G26,G29,G32,G35,G38,G41,G44,G47,G50,G53,G56,G59,G62,G65,G68,G71,G74,),"",SUM(G11,G14,G17,G20,G23,G26,G29,G32,G35,G38,G41,G44,G47,G50,G53,G56,G59,G62,G65,G68,G71,G74,)) | H3: =IF(H8=SUM(H11,H14,H17,H20,H23,H26,H29,H32,H35,H38,H41,H44,H47,H50,H53,H56,H59,H62,H65,H68,H71,H74,),"",SUM(H11,H14,H17,H20,H23,H26,H29,H32,H35,H38,H41,H44,H47,H50,H53,H56,H59,H62,H65,H68,H71,H74,)) | I3: =IF(I8=SUM(I11,I14,I17,I20,I23,I26,I29,I32,I35,I38,I41,I44,I47,I50,I53,I56,I59,I62,I65,I68,I71,I74,),"",SUM(I11,I14,I17,I20,I23,I26,I29,I32,I35,I38,I41,I44,I47,I50,I53,I56,I59,I62,I65,I68,I71,I74,)) | J3: =IF(J8=SUM(J11,J14,J17,J20,J23,J26,J29,J32,J35,J38,J41,J44,J47,J50,J53,J56,J59,J62,J65,J68,J71,J74,),"",SUM(J11,J14,J17,J20,J23,J26,J29,J32,J35,J38,J41,J44,J47,J50,J53,J56,J59,J62,J65,J68,J71,J74,)) | K3: =IF(K8=SUM(K11,K14,K17,K20,K23,K26,K29,K32,K35,K38,K41,K44,K47,K50,K53,K56,K59,K62,K65,K68,K71,K74,),"",SUM(K11,K14,K17,K20,K23,K26,K29,K32,K35,K38,K41,K44,K47,K50,K53,K56,K59,K62,K65,K68,K71,K74,)) | ... V3: =IF(V8=SUM(V11,V14,V17,V20,V23,V26,V29,V32,V35,V38,V41,V44,V47,V50,V53,V56,V59,V62,V65,V68,V71,V74,),"",SUM(V11,V14,V17,V20,V23,V26,V29,V32,V35,V38,V41,V44,V47,V50,V53,V56,V59,V62,V65,V68,V71,V74,))
A4: 區域及特殊族群別 Locality & Ethnos | D4: 兒童少年受虐/間題類型 (人數)By Types/Matters (Person)
D5: 總計 Total | G5: 遺棄 Abandon | K5: 身心不當對待Physical Emotional Abuse | S5: 目睹家暴 Witnessing Domestic Violence | U5: 兒少物質濫用
G6: 棄嬰 Abandoned Infants | I6: 棄兒 Abandoned Children | K6: 身體不當對待 Physical Abuse | M6: 精神不當對待 Emotional Abuse | O6: 性不當對待 Sexual Abuse | Q6: 疏忽 Neglect
D7: 合計 SubTotal | E7: 男 Male | F7: 女 Female | G7: 男 Male | H7: 女 Female | I7: 男 Male | J7: 女 Female | K7: 男 Male | L7: 女 Female | M7: 男 Male | N7: 女 Female | O7: 男 Male | P7: 女 Female | Q7: 男 Male | R7: 女 Female | S7: 男 Male | T7: 女 Female | U7: 男 Male | V7: 女 Female
A8: 總計 | B8: 計 | C8: Total | D8: 5771 | E8: 2521 | F8: 3250 | G8: 3 | H8: 5 | I8: 5 | J8: 3 | K8: 1804 | L8: 1242 | M8: 144 | N8: 144 | O8: 278 | P8: 1591 | Q8: 273 | R8: 243 | S8: 9 | T8: 11 | U8: 5 | V8: 11
A9: Total | B9: 一般 | C9: General | D9: 5255 | E9: 2289 | F9: 2966 | G9: 3 | H9: 5 | I9: 5 | J9: 3 | K9: 1659 | L9: 1167 | M9: 132 | N9: 126 | O9: 237 | P9: 1430 | Q9: 241 | R9: 222 | S9: 9 | T9: 9 | U9: 3 | V9: 4
B10: 原住民 | C10: Indigenous | D10: 516 | E10: 232 | F10: 284 | G10: 0 | H10: 0 | I10: 0 | J10: 0 | K10: 145 | L10: 75 | M10: 12 | N10: 18 | O10: 41 | P10: 161 | Q10: 32 | R10: 21 | S10: 0 | T10: 2 | U10: 2 | V10: 7
A11: 新北市 | B11: 計 | C11: Total | D11: 1208 | E11: 511 | F11: 697 | G11: 0 | H11: 0 | I11: 0 | J11: 0 | K11: 411 | L11: 275 | M11: 27 | N11: 32 | O11: 43 | P11: 361 | Q11: 27 | R11: 26 | S11: 3 | T11: 3 | U11: 0 | V11: 0
A12: New Taipei City | B12: 一般 | C12: General | D12: 1132 | E12: 473 | F12: 659 | G12: 0 | H12: 0 | I12: 0 | J12: 0 | K12: 379 | L12: 261 | M12: 25 | N12: 27 | O12: 40 | P12: 344 | Q12: 26 | R12: 24 | S12: 3 | T12: 3 | U12: 0 | V12: 0
B13: 原住民 | C13: Indigenous | D13: 76 | E13: 38 | F13: 38 | G13: 0 | H13: 0 | I13: 0 | J13: 0 | K13: 32 | L13: 14 | M13: 2 | N13: 5 | O13: 3 | P13: 17 | Q13: 1 | R13: 2 | S13: 0 | T13: 0 | U13: 0 | V13: 0
A14: 臺北市 | B14: 計 | C14: Total | D14: 571 | E14: 252 | F14: 319 | G14: 0 | H14: 0 | I14: 0 | J14: 0 | K14: 172 | L14: 122 | M14: 8 | N14: 7 | O14: 44 | P14: 155 | Q14: 28 | R14: 34 | S14: 0 | T14: 1 | U14: 0 | V14: 0
A15: Taipei City | B15: 一般 | C15: General | D15: 551 | E15: 240 | F15: 311 | G15: 0 | H15: 0 | I15: 0 | J15: 0 | K15: 164 | L15: 120 | M15: 8 | N15: 7 | O15: 44 | P15: 150 | Q15: 24 | R15: 33 | S15: 0 | T15: 1 | U15: 0 | V15: 0
B16: 原住民 | C16: Indigenous | D16: 20 | E16: 12 | F16: 8 | G16: 0 | H16: 0 | I16: 0 | J16: 0 | K16: 8 | L16: 2 | M16: 0 | N16: 0 | O16: 0 | P16: 5 | Q16: 4 | R16: 1 | S16: 0 | T16: 0 | U16: 0 | V16: 0
A17: 桃園市 | B17: 計 | C17: Total | D17: 505 | E17: 232 | F17: 273 | G17: 0 | H17: 0 | I17: 0 | J17: 0 | K17: 181 | L17: 117 | M17: 11 | N17: 9 | O17: 22 | P17: 139 | Q17: 18 | R17: 8 | S17: 0 | T17: 0 | U17: 0 | V17: 0
A18: Taoyuan City | B18: 一般 | C18: General | D18: 445 | E18: 204 | F18: 241 | G18: 0 | H18: 0 | I18: 0 | J18: 0 | K18: 156 | L18: 108 | M18: 11 | N18: 9 | O18: 19 | P18: 116 | Q18: 18 | R18: 8 | S18: 0 | T18: 0 | U18: 0 | V18: 0
B19: 原住民 | C19: Indigenous | D19: 60 | E19: 28 | F19: 32 | G19: 0 | H19: 0 | I19: 0 | J19: 0 | K19: 25 | L19: 9 | M19: 0 | N19: 0 | O19: 3 | P19: 23 | Q19: 0 | R19: 0 | S19: 0 | T19: 0 | U19: 0 | V19: 0
A20: 臺中市 | B20: 計 | C20: Total | D20: 717 | E20: 339 | F20: 378 | G20: 0 | H20: 0 | I20: 1 | J20: 0 | K20: 273 | L20: 179 | M20: 22 | N20: 25 | O20: 20 | P20: 158 | Q20: 23 | R20: 15 | S20: 0 | T20: 1 | U20: 0 | V20: 0
A21: Taichung City | B21: 一般 | C21: General | D21: 675 | E21: 316 | F21: 359 | G21: 0 | H21: 0 | I21: 1 | J21: 0 | K21: 255 | L21: 173 | M21: 22 | N21: 24 | O21: 18 | P21: 148 | Q21: 20 | R21: 14 | S21: 0 | T21: 0 | U21: 0 | V21: 0
B22: 原住民 | C22: Indigenous | D22: 42 | E22: 23 | F22: 19 | G22: 0 | H22: 0 | I22: 0 | J22: 0 | K22: 18 | L22: 6 | M22: 0 | N22: 1 | O22: 2 | P22: 10 | Q22: 3 | R22: 1 | S22: 0 | T22: 1 | U22: 0 | V22: 0
A23: 臺南市 | B23: 計 | C23: Total | D23: 309 | E23: 143 | F23: 166 | G23: 0 | H23: 0 | I23: 3 | J23: 2 | K23: 100 | L23: 75 | M23: 1 | N23: 3 | O23: 10 | P23: 66 | Q23: 28 | R23: 19 | S23: 1 | T23: 1 | U23: 0 | V23: 0
A24: Tainan City | B24: 一般 | C24: General | D24: 300 | E24: 142 | F24: 158 | G24: 0 | H24: 0 | I24: 3 | J24: 2 | K24: 99 | L24: 74 | M24: 1 | N24: 3 | O24: 10 | P24: 61 | Q24: 28 | R24: 17 | S24: 1 | T24: 1 | U24: 0 | V24: 0
B25: 原住民 | C25: Indigenous | D25: 9 | E25: 1 | F25: 8 | G25: 0 | H25: 0 | I25: 0 | J25: 0 | K25: 1 | L25: 1 | M25: 0 | N25: 0 | O25: 0 | P25: 5 | Q25: 0 | R25: 2 | S25: 0 | T25: 0 | U25: 0 | V25: 0
A26: 高雄市 | B26: 計 | C26: Total | D26: 604 | E26: 283 | F26: 321 | G26: 2 | H26: 5 | I26: 0 | J26: 0 | K26: 217 | L26: 138 | M26: 15 | N26: 17 | O26: 27 | P26: 128 | Q26: 21 | R26: 33 | S26: 1 | T26: 0 | U26: 0 | V26: 0
A27: Kaohsiung City | B27: 一般 | C27: General | D27: 568 | E27: 265 | F27: 303 | G27: 2 | H27: 5 | I27: 0 | J27: 0 | K27: 210 | L27: 130 | M27: 13 | N27: 15 | O27: 22 | P27: 122 | Q27: 17 | R27: 31 | S27: 1 | T27: 0 | U27: 0 | V27: 0
B28: 原住民 | C28: Indigenous | D28: 36 | E28: 18 | F28: 18 | G28: 0 | H28: 0 | I28: 0 | J28: 0 | K28: 7 | L28: 8 | M28: 2 | N28: 2 | O28: 5 | P28: 6 | Q28: 4 | R28: 2 | S28: 0 | T28: 0 | U28: 0 | V28: 0
A29: 宜蘭縣 | B29: 計 | C29: Total | D29: 94 | E29: 31 | F29: 63 | G29: 0 | H29: 0 | I29: 0 | J29: 0 | K29: 23 | L29: 20 | M29: 1 | N29: 4 | O29: 2 | P29: 36 | Q29: 5 | R29: 3 | S29: 0 | T29: 0 | U29: 0 | V29: 0
A30: Yilan County | B30: 一般 | C30: General | D30: 84 | E30: 26 | F30: 58 | G30: 0 | H30: 0 | I30: 0 | J30: 0 | K30: 21 | L30: 20 | M30: 0 | N30: 4 | O30: 0 | P30: 31 | Q30: 5 | R30: 3 | S30: 0 | T30: 0 | U30: 0 | V30: 0
B31: 原住民 | C31: Indigenous | D31: 10 | E31: 5 | F31: 5 | G31: 0 | H31: 0 | I31: 0 | J31: 0 | K31: 2 | L31: 0 | M31: 1 | N31: 0 | O31: 2 | P31: 5 | Q31: 0 | R31: 0 | S31: 0 | T31: 0 | U31: 0 | V31: 0
A32: 新竹縣 | B32: 計 | C32: Total | D32: 204 | E32: 86 | F32: 118 | G32: 0 | H32: 0 | I32: 1 | J32: 0 | K32: 38 | L32: 30 | M32: 7 | N32: 1 | O32: 20 | P32: 73 | Q32: 18 | R32: 14 | S32: 2 | T32: 0 | U32: 0 | V32: 0
A33: Hsinchu County | B33: 一般 | C33: General | D33: 170 | E33: 67 | F33: 103 | G33: 0 | H33: 0 | I33: 1 | J33: 0 | K33: 31 | L33: 29 | M33: 7 | N33: 1 | O33: 13 | P33: 64 | Q33: 13 | R33: 9 | S33: 2 | T33: 0 | U33: 0 | V33: 0
B34: 原住民 | C34: Indigenous | D34: 34 | E34: 19 | F34: 15 | G34: 0 | H34: 0 | I34: 0 | J34: 0 | K34: 7 | L34: 1 | M34: 0 | N34: 0 | O34: 7 | P34: 9 | Q34: 5 | R34: 5 | S34: 0 | T34: 0 | U34: 0 | V34: 0
