Workbook

Sheet 歷年
A1: 兒童及少年保護-受虐人數 Number of Abused Child and Youth
A2: 單位：人 Unit : Persons
A3: 年別 Year | B3: 受虐兒童少年人數按年齡分(人) By Age
B4: 合計 Total | E4: 0-未滿3歲 Under 3 Years | G4: 3-未滿6歲 3-Under 6 Years | I4: 6-未滿9歲 6-Under 9 Years | K4: 9-未滿12歲 9-Under 12 Years | M4: 12-未滿15歲 12-Under 15 Years | O4: 15-未滿18歲 15-Under 18 Years
B5: 計 Total | C5: 男 Male | D5: 女 Female | E5: 男 Male | F5: 女 Female | G5: 男 Male | H5: 女 Female | I5: 男 Male | J5: 女 Female | K5: 男 Male | L5: 女 Female | M5: 男 Male | N5: 女 Female | O5: 男 Male | P5: 女 Female
A7: 108年, 2019 | B7: ='2019'!D8 -> 11113 | C7: ='2019'!E8 -> 4832 | D7: ='2019'!F8 -> 6281 | E7: ='2019'!G8 -> 565 | F7: ='2019'!H8 -> 449 | G7: ='2019'!I8 -> 634 | H7: ='2019'!J8 -> 596 | I7: ='2019'!K8 -> 955 | ... P7: ='2019'!R8 -> 1883
A8: 109年, 2020 | B8: ='2020'!D8 -> 12610 | C8: ='2020'!E8 -> 5475 | D8: ='2020'!F8 -> 7135 | E8: ='2020'!G8 -> 628 | F8: ='2020'!H8 -> 518 | G8: ='2020'!I8 -> 750 | H8: ='2020'!J8 -> 685 | I8: ='2020'!K8 -> 1064 | ... P8: ='2020'!R8 -> 2153
A9: 110年, 2021 | B9: ='2021'!D8 -> 11523 | C9: ='2021'!E8 -> 5108 | D9: ='2021'!F8 -> 6415 | E9: ='2021'!G8 -> 595 | F9: ='2021'!H8 -> 482 | G9: ='2021'!I8 -> 774 | H9: ='2021'!J8 -> 615 | I9: ='2021'!K8 -> 1022 | ... P9: ='2021'!R8 -> 1859
A10: 111年, 2022 | B10: ='2022'!D8 -> 11950 | C10: ='2022'!E8 -> 5281 | D10: ='2022'!F8 -> 6669 | E10: ='2022'!G8 -> 655 | F10: ='2022'!H8 -> 497 | G10: ='2022'!I8 -> 812 | H10: ='2022'!J8 -> 695 | I10: ='2022'!K8 -> 1025 | ... P10: ='2022'!R8 -> 1923
A11: 112年, 2023 | B11: ='2023'!D8 -> 12646 | C11: ='2023'!E8 -> 5649 | D11: ='2023'!F8 -> 6997 | E11: ='2023'!G8 -> 668 | F11: ='2023'!H8 -> 534 | G11: ='2023'!I8 -> 968 | H11: ='2023'!J8 -> 698 | I11: ='2023'!K8 -> 1178 | ... P11: ='2023'!R8 -> 1818
A12: 113年, 2024 | B12: ='2024'!D8 -> 10810 | C12: ='2024'!E8 -> 4836 | D12: ='2024'!F8 -> 5974 | E12: ='2024'!G8 -> 564 | F12: ='2024'!H8 -> 437 | G12: ='2024'!I8 -> 788 | H12: ='2024'!J8 -> 664 | I12: ='2024'!K8 -> 1202 | ... P12: ='2024'!R8 -> 1567
A13: 上半年, Jan.-June | B13: 5771 | C13: 2521 | D13: 3250 | E13: 257 | F13: 212 | G13: 418 | H13: 331 | I13: 636 | J13: 408 | K13: 600 | L13: 453 | M13: 409 | N13: 952 | O13: 201 | P13: 894
A14: 下半年, July-Dec. | B14: 5039 | C14: 2315 | D14: 2724 | E14: 307 | F14: 225 | G14: 370 | H14: 333 | I14: 566 | J14: 330 | K14: 486 | L14: 344 | M14: 403 | N14: 819 | O14: 183 | P14: 673
A15: 114年, 2025 | B15: ='2025'!D8 -> 9898 | C15: ='2025'!E8 -> 4451 | D15: ='2025'!F8 -> 5447 | E15: ='2025'!G8 -> 644 | F15: ='2025'!H8 -> 478 | G15: ='2025'!I8 -> 769 | H15: ='2025'!J8 -> 551 | I15: ='2025'!K8 -> 1016 | ... P15: ='2025'!R8 -> 1364
A16: 上半年, Jan.-June | B16: ='Jan.-June, 2025'!D8 -> 5352 | C16: ='Jan.-June, 2025'!E8 -> 2421 | D16: ='Jan.-June, 2025'!F8 -> 2931 | E16: ='Jan.-June, 2025'!G8 -> 316 | F16: ='Jan.-June, 2025'!H8 -> 237 | G16: ='Jan.-June, 2025'!I8 -> 388 | H16: ='Jan.-June, 2025'!J8 -> 275 | I16: ='Jan.-June, 2025'!K8 -> 571 | ... P16: ='Jan.-June, 2025'!R8 -> 740
A17: 下半年, July-Dec. | B17: ='July-Dec., 2025'!D8 -> 4546 | C17: ='July-Dec., 2025'!E8 -> 2030 | D17: ='July-Dec., 2025'!F8 -> 2516 | E17: ='July-Dec., 2025'!G8 -> 328 | F17: ='July-Dec., 2025'!H8 -> 241 | G17: ='July-Dec., 2025'!I8 -> 381 | H17: ='July-Dec., 2025'!J8 -> 276 | I17: ='July-Dec., 2025'!K8 -> 445 | ... P17: ='July-Dec., 2025'!R8 -> 624
A18: 資料來源：各直轄市、縣市政府；106年及107年歷年由保護服務司另行提供。
A19: Source: County and Government.
A20: 更新日期：2026/03/31
B21: =IF(B15=SUM(B16:B17),"","*") | C21: =IF(C15=SUM(C16:C17),"","*") | D21: =IF(D15=SUM(D16:D17),"","*") | E21: =IF(E15=SUM(E16:E17),"","*") | F21: =IF(F15=SUM(F16:F17),"","*") | G21: =IF(G15=SUM(G16:G17),"","*") | H21: =IF(H15=SUM(H16:H17),"","*") | I21: =IF(I15=SUM(I16:I17),"","*") | ... P21: =IF(P15=SUM(P16:P17),"","*")

Sheet 2025
A1: 兒童及少年保護-受虐人數 Number of Abused Child and Youth
A2: 單位：人 Unit : Persons
A3: 民國114年, 2025 | D3: =IF(D8=SUM(D11,D14,D17,D20,D23,D26,D29,D32,D35,D38,D41,D44,D47,D50,D53,D56,D59,D62,D65,D68,D71,D74,),"","*") | E3: =IF(E8=SUM(E11,E14,E17,E20,E23,E26,E29,E32,E35,E38,E41,E44,E47,E50,E53,E56,E59,E62,E65,E68,E71,E74,),"","*") | F3: =IF(F8=SUM(F11,F14,F17,F20,F23,F26,F29,F32,F35,F38,F41,F44,F47,F50,F53,F56,F59,F62,F65,F68,F71,F74,),"","*") | G3: =IF(G8=SUM(G11,G14,G17,G20,G23,G26,G29,G32,G35,G38,G41,G44,G47,G50,G53,G56,G59,G62,G65,G68,G71,G74,),"","*") | H3: =IF(H8=SUM(H11,H14,H17,H20,H23,H26,H29,H32,H35,H38,H41,H44,H47,H50,H53,H56,H59,H62,H65,H68,H71,H74,),"","*") | I3: =IF(I8=SUM(I11,I14,I17,I20,I23,I26,I29,I32,I35,I38,I41,I44,I47,I50,I53,I56,I59,I62,I65,I68,I71,I74,),"","*") | J3: =IF(J8=SUM(J11,J14,J17,J20,J23,J26,J29,J32,J35,J38,J41,J44,J47,J50,J53,J56,J59,J62,J65,J68,J71,J74,),"","*") | K3: =IF(K8=SUM(K11,K14,K17,K20,K23,K26,K29,K32,K35,K38,K41,K44,K47,K50,K53,K56,K59,K62,K65,K68,K71,K74,),"","*") | ... R3: =IF(R8=SUM(R11,R14,R17,R20,R23,R26,R29,R32,R35,R38,R41,R44,R47,R50,R53,R56,R59,R62,R65,R68,R71,R74,),"","*")
A4: 區域及特殊族群別 Locality & Ethnos | D4: 受虐兒童少年人數按年齡分(人) By Age
D5: 合計 Total | G5: 0-未滿3歲 Under 3 Years | I5: 3-未滿6歲 3-Under 6 Years | K5: 6-未滿9歲 6-Under 9 Years | M5: 9-未滿12歲 9-Under 12 Years | O5: 12-未滿15歲 12-Under 15 Years | Q5: 15-未滿18歲 15-Under 18 Years
D6: 計 Total | E6: 男 Male | F6: 女 Female | G6: 男 Male | H6: 女 Female | I6: 男 Male | J6: 女 Female | K6: 男 Male | L6: 女 Female | M6: 男 Male | N6: 女 Female | O6: 男 Male | P6: 女 Female | Q6: 男 Male | R6: 女 Female
A8: 總計 | B8: 計 | C8: Total | D8: 9898 | E8: 4451 | F8: 5447 | G8: 644 | H8: 478 | I8: 769 | J8: 551 | K8: 1016 | L8: 690 | M8: 961 | N8: 663 | O8: 738 | P8: 1701 | Q8: 323 | R8: 1364
A9: Total | B9: 一般 | C9: General | D9: 8952 | E9: 4080 | F9: 4872 | G9: 598 | H9: 420 | I9: 692 | J9: 493 | K9: 934 | L9: 618 | M9: 877 | N9: 600 | O9: 677 | P9: 1510 | Q9: 302 | R9: 1231
B10: 原住民 | C10: Indigenous | D10: 946 | E10: 371 | F10: 575 | G10: 46 | H10: 58 | I10: 77 | J10: 58 | K10: 82 | L10: 72 | M10: 84 | N10: 63 | O10: 61 | P10: 191 | Q10: 21 | R10: 133
A11: 新北市 | B11: 計 | C11: Total | D11: 2147 | E11: 951 | F11: 1196 | G11: 86 | H11: 50 | I11: 142 | J11: 80 | K11: 240 | L11: 166 | M11: 259 | N11: 176 | O11: 159 | P11: 383 | Q11: 65 | R11: 341
A12: New Taipei City | B12: 一般 | C12: General | D12: 2009 | E12: 902 | F12: 1107 | G12: 83 | H12: 44 | I12: 135 | J12: 71 | K12: 230 | L12: 152 | M12: 242 | N12: 167 | O12: 149 | P12: 349 | Q12: 63 | R12: 324
B13: 原住民 | C13: Indigenous | D13: 138 | E13: 49 | F13: 89 | G13: 3 | H13: 6 | I13: 7 | J13: 9 | K13: 10 | L13: 14 | M13: 17 | N13: 9 | O13: 10 | P13: 34 | Q13: 2 | R13: 17
A14: 臺北市 | B14: 計 | C14: Total | D14: 894 | E14: 424 | F14: 470 | G14: 59 | H14: 52 | I14: 83 | J14: 61 | K14: 95 | L14: 56 | M14: 86 | N14: 46 | O14: 68 | P14: 140 | Q14: 33 | R14: 115
A15: Taipei City | B15: 一般 | C15: General | D15: 874 | E15: 413 | F15: 461 | G15: 58 | H15: 52 | I15: 78 | J15: 60 | K15: 93 | L15: 53 | M15: 84 | N15: 46 | O15: 67 | P15: 138 | Q15: 33 | R15: 112
B16: 原住民 | C16: Indigenous | D16: 20 | E16: 11 | F16: 9 | G16: 1 | H16: 0 | I16: 5 | J16: 1 | K16: 2 | L16: 3 | M16: 2 | N16: 0 | O16: 1 | P16: 2 | Q16: 0 | R16: 3
A17: 桃園市 | B17: 計 | C17: Total | D17: 777 | E17: 353 | F17: 424 | G17: 37 | H17: 30 | I17: 67 | J17: 38 | K17: 95 | L17: 58 | M17: 90 | N17: 57 | O17: 50 | P17: 127 | Q17: 14 | R17: 114
A18: Taoyuan City | B18: 一般 | C18: General | D18: 645 | E18: 296 | F18: 349 | G18: 28 | H18: 21 | I18: 49 | J18: 28 | K18: 79 | L18: 50 | M18: 79 | N18: 50 | O18: 47 | P18: 105 | Q18: 14 | R18: 95
B19: 原住民 | C19: Indigenous | D19: 132 | E19: 57 | F19: 75 | G19: 9 | H19: 9 | I19: 18 | J19: 10 | K19: 16 | L19: 8 | M19: 11 | N19: 7 | O19: 3 | P19: 22 | Q19: 0 | R19: 19
A20: 臺中市 | B20: 計 | C20: Total | D20: 1327 | E20: 663 | F20: 664 | G20: 110 | H20: 72 | I20: 90 | J20: 75 | K20: 155 | L20: 84 | M20: 134 | N20: 78 | O20: 121 | P20: 207 | Q20: 53 | R20: 148
A21: Taichung City | B21: 一般 | C21: General | D21: 1250 | E21: 621 | F21: 629 | G21: 106 | H21: 68 | I21: 86 | J21: 69 | K21: 142 | L21: 77 | M21: 126 | N21: 75 | O21: 115 | P21: 198 | Q21: 46 | R21: 142
B22: 原住民 | C22: Indigenous | D22: 77 | E22: 42 | F22: 35 | G22: 4 | H22: 4 | I22: 4 | J22: 6 | K22: 13 | L22: 7 | M22: 8 | N22: 3 | O22: 6 | P22: 9 | Q22: 7 | R22: 6
A23: 臺南市 | B23: 計 | C23: Total | D23: 532 | E23: 263 | F23: 269 | G23: 46 | H23: 32 | I23: 58 | J23: 31 | K23: 63 | L23: 37 | M23: 52 | N23: 36 | O23: 33 | P23: 90 | Q23: 11 | R23: 43
A24: Tainan City | B24: 一般 | C24: General | D24: 510 | E24: 249 | F24: 261 | G24: 44 | H24: 32 | I24: 54 | J24: 30 | K24: 61 | L24: 37 | M24: 47 | N24: 35 | O24: 32 | P24: 88 | Q24: 11 | R24: 39
B25: 原住民 | C25: Indigenous | D25: 22 | E25: 14 | F25: 8 | G25: 2 | H25: 0 | I25: 4 | J25: 1 | K25: 2 | L25: 0 | M25: 5 | N25: 1 | O25: 1 | P25: 2 | Q25: 0 | R25: 4
A26: 高雄市 | B26: 計 | C26: Total | D26: 1283 | E26: 606 | F26: 677 | G26: 89 | H26: 76 | I26: 126 | J26: 78 | K26: 146 | L26: 85 | M26: 132 | N26: 86 | O26: 80 | P26: 216 | Q26: 33 | R26: 136
A27: Kaohsiung City | B27: 一般 | C27: General | D27: 1191 | E27: 569 | F27: 622 | G27: 85 | H27: 67 | I27: 118 | J27: 73 | K27: 133 | L27: 82 | M27: 123 | N27: 79 | O27: 78 | P27: 198 | Q27: 32 | R27: 123
B28: 原住民 | C28: Indigenous | D28: 92 | E28: 37 | F28: 55 | G28: 4 | H28: 9 | I28: 8 | J28: 5 | K28: 13 | L28: 3 | M28: 9 | N28: 7 | O28: 2 | P28: 18 | Q28: 1 | R28: 13
A29: 宜蘭縣 | B29: 計 | C29: Total | D29: 65 | E29: 10 | F29: 55 | G29: 4 | H29: 10 | I29: 0 | J29: 1 | K29: 3 | L29: 5 | M29: 1 | N29: 2 | O29: 1 | P29: 26 | Q29: 1 | R29: 11
A30: Yilan County | B30: 一般 | C30: General | D30: 61 | E30: 10 | F30: 51 | G30: 4 | H30: 10 | I30: 0 | J30: 1 | K30: 3 | L30: 5 | M30: 1 | N30: 2 | O30: 1 | P30: 24 | Q30: 1 | R30: 9
B31: 原住民 | C31: Indigenous | D31: 4 | E31: 0 | F31: 4 | G31: 0 | H31: 0 | I31: 0 | J31: 0 | K31: 0 | L31: 0 | M31: 0 | N31: 0 | O31: 0 | P31: 2 | Q31: 0 | R31: 2
A32: 新竹縣 | B32: 計 | C32: Total | D32: 362 | E32: 163 | F32: 199 | G32: 34 | H32: 25 | I32: 35 | J32: 30 | K32: 40 | L32: 24 | M32: 22 | N32: 27 | O32: 25 | P32: 58 | Q32: 7 | R32: 35
A33: Hsinchu County | B33: 一般 | C33: General | D33: 303 | E33: 142 | F33: 161 | G33: 30 | H33: 16 | I33: 27 | J33: 27 | K33: 38 | L33: 20 | M33: 18 | N33: 19 | O33: 23 | P33: 49 | Q33: 6 | R33: 30
B34: 原住民 | C34: Indigenous | D34: 59 | E34: 21 | F34: 38 | G34: 4 | H34: 9 | I34: 8 | J34: 3 | K34: 2 | L34: 4 | M34: 4 | N34: 8 | O34: 2 | P34: 9 | Q34: 1 | R34: 5
A35: 苗栗縣 | B35: 計 | C35: Total | D35: 182 | E35: 49 | F35: 133 | G35: 11 | H35: 9 | I35: 10 | J35: 12 | K35: 9 | L35: 10 | M35: 12 | N35: 17 | O35: 4 | P35: 39 | Q35: 3 | R35: 46
A36: Miaoli County | B36: 一般 | C36: General | D36: 163 | E36: 45 | F36: 118 | G36: 11 | H36: 7 | I36: 8 | J36: 12 | K36: 8 | L36: 10 | M36: 11 | N36: 15 | O36: 4 | P36: 35 | Q36: 3 | R36: 39
B37: 原住民 | C37: Indigenous | D37: 19 | E37: 4 | F37: 15 | G37: 0 | H37: 2 | I37: 2 | J37: 0 | K37: 1 | L37: 0 | M37: 1 | N37: 2 | O37: 0 | P37: 4 | Q37: 0 | R37: 7
A38: 彰化縣 | B38: 計 | C38: Total | D38: 373 | E38: 161 | F38: 212 | G38: 34 | H38: 17 | I38: 20 | J38: 27 | K38: 29 | L38: 29 | M38: 29 | N38: 15 | O38: 27 | P38: 65 | Q38: 22 | R38: 59
A39: Changhua County | B39: 一般 | C39: General | D39: 357 | E39: 156 | F39: 201 | G39: 33 | H39: 16 | I39: 20 | J39: 26 | K39: 29 | L39: 29 | M39: 29 | N39: 15 | O39: 27 | P39: 59 | Q39: 18 | R39: 56
B40: 原住民 | C40: Indigenous | D40: 16 | E40: 5 | F40: 11 | G40: 1 | H40: 1 | I40: 0 | J40: 1 | K40: 0 | L40: 0 | M40: 0 | N40: 0 | O40: 0 | P40: 6 | Q40: 4 | R40: 3
A41: 南投縣 | B41: 計 | C41: Total | D41: 195 | E41: 72 | F41: 123 | G41: 10 | H41: 11 | I41: 13 | J41: 9 | K41: 19 | L41: 17 | M41: 11 | N41: 20 | O41: 10 | P41: 31 | Q41: 9 | R41: 35
...

Sheet July-Dec., 2025
A1: 兒童及少年保護-受虐人數 Number of Abused Child and Youth
A2: 單位：人 Unit : Persons
A3: 民國114年7-12月 July-Dec., 2025 | D3: =IF(D8=SUM(D11,D14,D17,D20,D23,D26,D29,D32,D35,D38,D41,D44,D47,D50,D53,D56,D59,D62,D65,D68,D71,D74,),"","*") | E3: =IF(E8=SUM(E11,E14,E17,E20,E23,E26,E29,E32,E35,E38,E41,E44,E47,E50,E53,E56,E59,E62,E65,E68,E71,E74,),"","*") | F3: =IF(F8=SUM(F11,F14,F17,F20,F23,F26,F29,F32,F35,F38,F41,F44,F47,F50,F53,F56,F59,F62,F65,F68,F71,F74,),"","*") | G3: =IF(G8=SUM(G11,G14,G17,G20,G23,G26,G29,G32,G35,G38,G41,G44,G47,G50,G53,G56,G59,G62,G65,G68,G71,G74,),"","*") | H3: =IF(H8=SUM(H11,H14,H17,H20,H23,H26,H29,H32,H35,H38,H41,H44,H47,H50,H53,H56,H59,H62,H65,H68,H71,H74,),"","*") | I3: =IF(I8=SUM(I11,I14,I17,I20,I23,I26,I29,I32,I35,I38,I41,I44,I47,I50,I53,I56,I59,I62,I65,I68,I71,I74,),"","*") | J3: =IF(J8=SUM(J11,J14,J17,J20,J23,J26,J29,J32,J35,J38,J41,J44,J47,J50,J53,J56,J59,J62,J65,J68,J71,J74,),"","*") | K3: =IF(K8=SUM(K11,K14,K17,K20,K23,K26,K29,K32,K35,K38,K41,K44,K47,K50,K53,K56,K59,K62,K65,K68,K71,K74,),"","*") | ... R3: =IF(R8=SUM(R11,R14,R17,R20,R23,R26,R29,R32,R35,R38,R41,R44,R47,R50,R53,R56,R59,R62,R65,R68,R71,R74,),"","*")
A4: 區域及特殊族群別 Locality & Ethnos | D4: 受虐兒童少年人數按年齡分(人) By Age
D5: 合計 Total | G5: 0-未滿3歲 Under 3 Years | I5: 3-未滿6歲 3-Under 6 Years | K5: 6-未滿9歲 6-Under 9 Years | M5: 9-未滿12歲 9-Under 12 Years | O5: 12-未滿15歲 12-Under 15 Years | Q5: 15-未滿18歲 15-Under 18 Years
D6: 計 Total | E6: 男 Male | F6: 女 Female | G6: 男 Male | H6: 女 Female | I6: 男 Male | J6: 女 Female | K6: 男 Male | L6: 女 Female | M6: 男 Male | N6: 女 Female | O6: 男 Male | P6: 女 Female | Q6: 男 Male | R6: 女 Female
A8: 總計 | B8: 計 | C8: Total | D8: 4546 | E8: 2030 | F8: 2516 | G8: 328 | H8: 241 | I8: 381 | J8: 276 | K8: 445 | L8: 307 | M8: 436 | N8: 286 | O8: 311 | P8: 782 | Q8: 129 | R8: 624
A9: Total | B9: 一般 | C9: General | D9: 4085 | E9: 1858 | F9: 2227 | G9: 300 | H9: 200 | I9: 348 | J9: 244 | K9: 412 | L9: 268 | M9: 392 | N9: 256 | O9: 284 | P9: 690 | Q9: 122 | R9: 569
B10: 原住民 | C10: Indigenous | D10: 461 | E10: 172 | F10: 289 | G10: 28 | H10: 41 | I10: 33 | J10: 32 | K10: 33 | L10: 39 | M10: 44 | N10: 30 | O10: 27 | P10: 92 | Q10: 7 | R10: 55
A11: 新北市 | B11: 計 | C11: Total | D11: 996 | E11: 451 | F11: 545 | G11: 42 | H11: 32 | I11: 82 | J11: 43 | K11: 101 | L11: 72 | M11: 121 | N11: 68 | O11: 74 | P11: 169 | Q11: 31 | R11: 161
A12: New Taipei City | B12: 一般 | C12: General | D12: 914 | E12: 422 | F12: 492 | G12: 39 | H12: 27 | I12: 79 | J12: 38 | K12: 95 | L12: 63 | M12: 113 | N12: 63 | O12: 66 | P12: 146 | Q12: 30 | R12: 155
B13: 原住民 | C13: Indigenous | D13: 82 | E13: 29 | F13: 53 | G13: 3 | H13: 5 | I13: 3 | J13: 5 | K13: 6 | L13: 9 | M13: 8 | N13: 5 | O13: 8 | P13: 23 | Q13: 1 | R13: 6
A14: 臺北市 | B14: 計 | C14: Total | D14: 375 | E14: 161 | F14: 214 | G14: 21 | H14: 21 | I14: 31 | J14: 34 | K14: 42 | L14: 19 | M14: 31 | N14: 22 | O14: 21 | P14: 62 | Q14: 15 | R14: 56
A15: Taipei City | B15: 一般 | C15: General | D15: 364 | E15: 155 | F15: 209 | G15: 20 | H15: 21 | I15: 28 | J15: 33 | K15: 42 | L15: 18 | M15: 30 | N15: 22 | O15: 20 | P15: 61 | Q15: 15 | R15: 54
B16: 原住民 | C16: Indigenous | D16: 11 | E16: 6 | F16: 5 | G16: 1 | H16: 0 | I16: 3 | J16: 1 | K16: 0 | L16: 1 | M16: 1 | N16: 0 | O16: 1 | P16: 1 | Q16: 0 | R16: 2
A17: 桃園市 | B17: 計 | C17: Total | D17: 353 | E17: 153 | F17: 200 | G17: 22 | H17: 22 | I17: 32 | J17: 20 | K17: 37 | L17: 25 | M17: 39 | N17: 19 | O17: 20 | P17: 61 | Q17: 3 | R17: 53
A18: Taoyuan City | B18: 一般 | C18: General | D18: 282 | E18: 124 | F18: 158 | G18: 16 | H18: 13 | I18: 22 | J18: 14 | K18: 32 | L18: 20 | M18: 32 | N18: 15 | O18: 19 | P18: 55 | Q18: 3 | R18: 41
B19: 原住民 | C19: Indigenous | D19: 71 | E19: 29 | F19: 42 | G19: 6 | H19: 9 | I19: 10 | J19: 6 | K19: 5 | L19: 5 | M19: 7 | N19: 4 | O19: 1 | P19: 6 | Q19: 0 | R19: 12
A20: 臺中市 | B20: 計 | C20: Total | D20: 618 | E20: 305 | F20: 313 | G20: 53 | H20: 31 | I20: 43 | J20: 43 | K20: 78 | L20: 38 | M20: 58 | N20: 36 | O20: 55 | P20: 97 | Q20: 18 | R20: 68
A21: Taichung City | B21: 一般 | C21: General | D21: 592 | E21: 291 | F21: 301 | G21: 52 | H21: 29 | I21: 42 | J21: 42 | K21: 73 | L21: 36 | M21: 54 | N21: 36 | O21: 54 | P21: 92 | Q21: 16 | R21: 66
B22: 原住民 | C22: Indigenous | D22: 26 | E22: 14 | F22: 12 | G22: 1 | H22: 2 | I22: 1 | J22: 1 | K22: 5 | L22: 2 | M22: 4 | N22: 0 | O22: 1 | P22: 5 | Q22: 2 | R22: 2
A23: 臺南市 | B23: 計 | C23: Total | D23: 213 | E23: 99 | F23: 114 | G23: 17 | H23: 13 | I23: 23 | J23: 12 | K23: 21 | L23: 11 | M23: 16 | N23: 21 | O23: 17 | P23: 38 | Q23: 5 | R23: 19
A24: Tainan City | B24: 一般 | C24: General | D24: 206 | E24: 96 | F24: 110 | G24: 17 | H24: 13 | I24: 22 | J24: 12 | K24: 21 | L24: 11 | M24: 15 | N24: 20 | O24: 16 | P24: 37 | Q24: 5 | R24: 17
B25: 原住民 | C25: Indigenous | D25: 7 | E25: 3 | F25: 4 | G25: 0 | H25: 0 | I25: 1 | J25: 0 | K25: 0 | L25: 0 | M25: 1 | N25: 1 | O25: 1 | P25: 1 | Q25: 0 | R25: 2
A26: 高雄市 | B26: 計 | C26: Total | D26: 601 | E26: 290 | F26: 311 | G26: 57 | H26: 48 | I26: 61 | J26: 34 | K26: 61 | L26: 37 | M26: 72 | N26: 36 | O26: 28 | P26: 100 | Q26: 11 | R26: 56
A27: Kaohsiung City | B27: 一般 | C27: General | D27: 555 | E27: 272 | F27: 283 | G27: 54 | H27: 41 | I27: 59 | J27: 33 | K27: 53 | L27: 35 | M27: 67 | N27: 31 | O27: 28 | P27: 92 | Q27: 11 | R27: 51
B28: 原住民 | C28: Indigenous | D28: 46 | E28: 18 | F28: 28 | G28: 3 | H28: 7 | I28: 2 | J28: 1 | K28: 8 | L28: 2 | M28: 5 | N28: 5 | O28: 0 | P28: 8 | Q28: 0 | R28: 5
A29: 宜蘭縣 | B29: 計 | C29: Total | D29: 30 | E29: 3 | F29: 27 | G29: 2 | H29: 3 | I29: 0 | J29: 1 | K29: 0 | L29: 2 | M29: 0 | N29: 1 | O29: 0 | P29: 17 | Q29: 1 | R29: 3
A30: Yilan County | B30: 一般 | C30: General | D30: 28 | E30: 3 | F30: 25 | G30: 2 | H30: 3 | I30: 0 | J30: 1 | K30: 0 | L30: 2 | M30: 0 | N30: 1 | O30: 0 | P30: 16 | Q30: 1 | R30: 2
B31: 原住民 | C31: Indigenous | D31: 2 | E31: 0 | F31: 2 | G31: 0 | H31: 0 | I31: 0 | J31: 0 | K31: 0 | L31: 0 | M31: 0 | N31: 0 | O31: 0 | P31: 1 | Q31: 0 | R31: 1
A32: 新竹縣 | B32: 計 | C32: Total | D32: 178 | E32: 83 | F32: 95 | G32: 16 | H32: 12 | I32: 21 | J32: 15 | K32: 21 | L32: 11 | M32: 11 | N32: 12 | O32: 10 | P32: 26 | Q32: 4 | R32: 19
A33: Hsinchu County | B33: 一般 | C33: General | D33: 155 | E33: 71 | F33: 84 | G33: 15 | H33: 8 | I33: 17 | J33: 14 | K33: 19 | L33: 11 | M33: 8 | N33: 10 | O33: 8 | P33: 24 | Q33: 4 | R33: 17
B34: 原住民 | C34: Indigenous | D34: 23 | E34: 12 | F34: 11 | G34: 1 | H34: 4 | I34: 4 | J34: 1 | K34: 2 | L34: 0 | M34: 3 | N34: 2 | O34: 2 | P34: 2 | Q34: 0 | R34: 2
A35: 苗栗縣 | B35: 計 | C35: Total | D35: 91 | E35: 26 | F35: 65 | G35: 7 | H35: 6 | I35: 6 | J35: 7 | K35: 5 | L35: 3 | M35: 6 | N35: 10 | O35: 2 | P35: 19 | Q35: 0 | R35: 20
A36: Miaoli County | B36: 一般 | C36: General | D36: 83 | E36: 24 | F36: 59 | G36: 7 | H36: 4 | I36: 5 | J36: 7 | K36: 5 | L36: 3 | M36: 5 | N36: 10 | O36: 2 | P36: 17 | Q36: 0 | R36: 18
B37: 原住民 | C37: Indigenous | D37: 8 | E37: 2 | F37: 6 | G37: 0 | H37: 2 | I37: 1 | J37: 0 | K37: 0 | L37: 0 | M37: 1 | N37: 0 | O37: 0 | P37: 2 | Q37: 0 | R37: 2
A38: 彰化縣 | B38: 計 | C38: Total | D38: 150 | E38: 61 | F38: 89 | G38: 17 | H38: 7 | I38: 11 | J38: 12 | K38: 11 | L38: 11 | M38: 10 | N38: 2 | O38: 4 | P38: 33 | Q38: 8 | R38: 24
A39: Changhua County | B39: 一般 | C39: General | D39: 140 | E39: 57 | F39: 83 | G39: 16 | H39: 7 | I39: 11 | J39: 11 | K39: 11 | L39: 11 | M39: 10 | N39: 2 | O39: 4 | P39: 31 | Q39: 5 | R39: 21
B40: 原住民 | C40: Indigenous | D40: 10 | E40: 4 | F40: 6 | G40: 1 | H40: 0 | I40: 0 | J40: 1 | K40: 0 | L40: 0 | M40: 0 | N40: 0 | O40: 0 | P40: 2 | Q40: 3 | R40: 3
A41: 南投縣 | B41: 計 | C41: Total | D41: 83 | E41: 30 | F41: 53 | G41: 5 | H41: 1 | I41: 6 | J41: 4 | K41: 4 | L41: 8 | M41: 5 | N41: 9 | O41: 5 | P41: 18 | Q41: 5 | R41: 13
...

Sheet Jan.-June, 2025
A1: 兒童及少年保護-受虐人數 Number of Abused Child and Youth
A2: 單位：人 Unit : Persons
A3: 民國114年1-6月 Jan.-June, 2025 | D3: =IF(D8=SUM(D11,D14,D17,D20,D23,D26,D29,D32,D35,D38,D41,D44,D47,D50,D53,D56,D59,D62,D65,D68,D71,D74,),"","*") | E3: =IF(E8=SUM(E11,E14,E17,E20,E23,E26,E29,E32,E35,E38,E41,E44,E47,E50,E53,E56,E59,E62,E65,E68,E71,E74,),"","*") | F3: =IF(F8=SUM(F11,F14,F17,F20,F23,F26,F29,F32,F35,F38,F41,F44,F47,F50,F53,F56,F59,F62,F65,F68,F71,F74,),"","*") | G3: =IF(G8=SUM(G11,G14,G17,G20,G23,G26,G29,G32,G35,G38,G41,G44,G47,G50,G53,G56,G59,G62,G65,G68,G71,G74,),"","*") | H3: =IF(H8=SUM(H11,H14,H17,H20,H23,H26,H29,H32,H35,H38,H41,H44,H47,H50,H53,H56,H59,H62,H65,H68,H71,H74,),"","*") | I3: =IF(I8=SUM(I11,I14,I17,I20,I23,I26,I29,I32,I35,I38,I41,I44,I47,I50,I53,I56,I59,I62,I65,I68,I71,I74,),"","*") | J3: =IF(J8=SUM(J11,J14,J17,J20,J23,J26,J29,J32,J35,J38,J41,J44,J47,J50,J53,J56,J59,J62,J65,J68,J71,J74,),"","*") | K3: =IF(K8=SUM(K11,K14,K17,K20,K23,K26,K29,K32,K35,K38,K41,K44,K47,K50,K53,K56,K59,K62,K65,K68,K71,K74,),"","*") | ... R3: =IF(R8=SUM(R11,R14,R17,R20,R23,R26,R29,R32,R35,R38,R41,R44,R47,R50,R53,R56,R59,R62,R65,R68,R71,R74,),"","*")
A4: 區域及特殊族群別 Locality & Ethnos | D4: 受虐兒童少年人數按年齡分(人) By Age
D5: 合計 Total | G5: 0-未滿3歲 Under 3 Years | I5: 3-未滿6歲 3-Under 6 Years | K5: 6-未滿9歲 6-Under 9 Years | M5: 9-未滿12歲 9-Under 12 Years | O5: 12-未滿15歲 12-Under 15 Years | Q5: 15-未滿18歲 15-Under 18 Years
D6: 計 Total | E6: 男 Male | F6: 女 Female | G6: 男 Male | H6: 女 Female | I6: 男 Male | J6: 女 Female | K6: 男 Male | L6: 女 Female | M6: 男 Male | N6: 女 Female | O6: 男 Male | P6: 女 Female | Q6: 男 Male | R6: 女 Female
A8: 總計 | B8: 計 | C8: Total | D8: 5352 | E8: 2421 | F8: 2931 | G8: 316 | H8: 237 | I8: 388 | J8: 275 | K8: 571 | L8: 383 | M8: 525 | N8: 377 | O8: 427 | P8: 919 | Q8: 194 | R8: 740
A9: Total | B9: 一般 | C9: General | D9: 4867 | E9: 2222 | F9: 2645 | G9: 298 | H9: 220 | I9: 344 | J9: 249 | K9: 522 | L9: 350 | M9: 485 | N9: 344 | O9: 393 | P9: 820 | Q9: 180 | R9: 662
B10: 原住民 | C10: Indigenous | D10: 485 | E10: 199 | F10: 286 | G10: 18 | H10: 17 | I10: 44 | J10: 26 | K10: 49 | L10: 33 | M10: 40 | N10: 33 | O10: 34 | P10: 99 | Q10: 14 | R10: 78
A11: 新北市 | B11: 計 | C11: Total | D11: 1151 | E11: 500 | F11: 651 | G11: 44 | H11: 18 | I11: 60 | J11: 37 | K11: 139 | L11: 94 | M11: 138 | N11: 108 | O11: 85 | P11: 214 | Q11: 34 | R11: 180
A12: New Taipei City | B12: 一般 | C12: General | D12: 1095 | E12: 480 | F12: 615 | G12: 44 | H12: 17 | I12: 56 | J12: 33 | K12: 135 | L12: 89 | M12: 129 | N12: 104 | O12: 83 | P12: 203 | Q12: 33 | R12: 169
B13: 原住民 | C13: Indigenous | D13: 56 | E13: 20 | F13: 36 | G13: 0 | H13: 1 | I13: 4 | J13: 4 | K13: 4 | L13: 5 | M13: 9 | N13: 4 | O13: 2 | P13: 11 | Q13: 1 | R13: 11
A14: 臺北市 | B14: 計 | C14: Total | D14: 519 | E14: 263 | F14: 256 | G14: 38 | H14: 31 | I14: 52 | J14: 27 | K14: 53 | L14: 37 | M14: 55 | N14: 24 | O14: 47 | P14: 78 | Q14: 18 | R14: 59
A15: Taipei City | B15: 一般 | C15: General | D15: 510 | E15: 258 | F15: 252 | G15: 38 | H15: 31 | I15: 50 | J15: 27 | K15: 51 | L15: 35 | M15: 54 | N15: 24 | O15: 47 | P15: 77 | Q15: 18 | R15: 58
B16: 原住民 | C16: Indigenous | D16: 9 | E16: 5 | F16: 4 | G16: 0 | H16: 0 | I16: 2 | J16: 0 | K16: 2 | L16: 2 | M16: 1 | N16: 0 | O16: 0 | P16: 1 | Q16: 0 | R16: 1
A17: 桃園市 | B17: 計 | C17: Total | D17: 424 | E17: 200 | F17: 224 | G17: 15 | H17: 8 | I17: 35 | J17: 18 | K17: 58 | L17: 33 | M17: 51 | N17: 38 | O17: 30 | P17: 66 | Q17: 11 | R17: 61
A18: Taoyuan City | B18: 一般 | C18: General | D18: 363 | E18: 172 | F18: 191 | G18: 12 | H18: 8 | I18: 27 | J18: 14 | K18: 47 | L18: 30 | M18: 47 | N18: 35 | O18: 28 | P18: 50 | Q18: 11 | R18: 54
B19: 原住民 | C19: Indigenous | D19: 61 | E19: 28 | F19: 33 | G19: 3 | H19: 0 | I19: 8 | J19: 4 | K19: 11 | L19: 3 | M19: 4 | N19: 3 | O19: 2 | P19: 16 | Q19: 0 | R19: 7
A20: 臺中市 | B20: 計 | C20: Total | D20: 709 | E20: 358 | F20: 351 | G20: 57 | H20: 41 | I20: 47 | J20: 32 | K20: 77 | L20: 46 | M20: 76 | N20: 42 | O20: 66 | P20: 110 | Q20: 35 | R20: 80
A21: Taichung City | B21: 一般 | C21: General | D21: 658 | E21: 330 | F21: 328 | G21: 54 | H21: 39 | I21: 44 | J21: 27 | K21: 69 | L21: 41 | M21: 72 | N21: 39 | O21: 61 | P21: 106 | Q21: 30 | R21: 76
B22: 原住民 | C22: Indigenous | D22: 51 | E22: 28 | F22: 23 | G22: 3 | H22: 2 | I22: 3 | J22: 5 | K22: 8 | L22: 5 | M22: 4 | N22: 3 | O22: 5 | P22: 4 | Q22: 5 | R22: 4
A23: 臺南市 | B23: 計 | C23: Total | D23: 319 | E23: 164 | F23: 155 | G23: 29 | H23: 19 | I23: 35 | J23: 19 | K23: 42 | L23: 26 | M23: 36 | N23: 15 | O23: 16 | P23: 52 | Q23: 6 | R23: 24
A24: Tainan City | B24: 一般 | C24: General | D24: 304 | E24: 153 | F24: 151 | G24: 27 | H24: 19 | I24: 32 | J24: 18 | K24: 40 | L24: 26 | M24: 32 | N24: 15 | O24: 16 | P24: 51 | Q24: 6 | R24: 22
B25: 原住民 | C25: Indigenous | D25: 15 | E25: 11 | F25: 4 | G25: 2 | H25: 0 | I25: 3 | J25: 1 | K25: 2 | L25: 0 | M25: 4 | N25: 0 | O25: 0 | P25: 1 | Q25: 0 | R25: 2
A26: 高雄市 | B26: 計 | C26: Total | D26: 682 | E26: 316 | F26: 366 | G26: 32 | H26: 28 | I26: 65 | J26: 44 | K26: 85 | L26: 48 | M26: 60 | N26: 50 | O26: 52 | P26: 116 | Q26: 22 | R26: 80
A27: Kaohsiung City | B27: 一般 | C27: General | D27: 636 | E27: 297 | F27: 339 | G27: 31 | H27: 26 | I27: 59 | J27: 40 | K27: 80 | L27: 47 | M27: 56 | N27: 48 | O27: 50 | P27: 106 | Q27: 21 | R27: 72
B28: 原住民 | C28: Indigenous | D28: 46 | E28: 19 | F28: 27 | G28: 1 | H28: 2 | I28: 6 | J28: 4 | K28: 5 | L28: 1 | M28: 4 | N28: 2 | O28: 2 | P28: 10 | Q28: 1 | R28: 8
A29: 宜蘭縣 | B29: 計 | C29: Total | D29: 35 | E29: 7 | F29: 28 | G29: 2 | H29: 7 | I29: 0 | J29: 0 | K29: 3 | L29: 3 | M29: 1 | N29: 1 | O29: 1 | P29: 9 | Q29: 0 | R29: 8
A30: Yilan County | B30: 一般 | C30: General | D30: 33 | E30: 7 | F30: 26 | G30: 2 | H30: 7 | I30: 0 | J30: 0 | K30: 3 | L30: 3 | M30: 1 | N30: 1 | O30: 1 | P30: 8 | Q30: 0 | R30: 7
B31: 原住民 | C31: Indigenous | D31: 2 | E31: 0 | F31: 2 | G31: 0 | H31: 0 | I31: 0 | J31: 0 | K31: 0 | L31: 0 | M31: 0 | N31: 0 | O31: 0 | P31: 1 | Q31: 0 | R31: 1
A32: 新竹縣 | B32: 計 | C32: Total | D32: 184 | E32: 80 | F32: 104 | G32: 18 | H32: 13 | I32: 14 | J32: 15 | K32: 19 | L32: 13 | M32: 11 | N32: 15 | O32: 15 | P32: 32 | Q32: 3 | R32: 16
A33: Hsinchu County | B33: 一般 | C33: General | D33: 148 | E33: 71 | F33: 77 | G33: 15 | H33: 8 | I33: 10 | J33: 13 | K33: 19 | L33: 9 | M33: 10 | N33: 9 | O33: 15 | P33: 25 | Q33: 2 | R33: 13
B34: 原住民 | C34: Indigenous | D34: 36 | E34: 9 | F34: 27 | G34: 3 | H34: 5 | I34: 4 | J34: 2 | K34: 0 | L34: 4 | M34: 1 | N34: 6 | O34: 0 | P34: 7 | Q34: 1 | R34: 3
A35: 苗栗縣 | B35: 計 | C35: Total | D35: 91 | E35: 23 | F35: 68 | G35: 4 | H35: 3 | I35: 4 | J35: 5 | K35: 4 | L35: 7 | M35: 6 | N35: 7 | O35: 2 | P35: 20 | Q35: 3 | R35: 26
A36: Miaoli County | B36: 一般 | C36: General | D36: 80 | E36: 21 | F36: 59 | G36: 4 | H36: 3 | I36: 3 | J36: 5 | K36: 3 | L36: 7 | M36: 6 | N36: 5 | O36: 2 | P36: 18 | Q36: 3 | R36: 21
B37: 原住民 | C37: Indigenous | D37: 11 | E37: 2 | F37: 9 | G37: 0 | H37: 0 | I37: 1 | J37: 0 | K37: 1 | L37: 0 | M37: 0 | N37: 2 | O37: 0 | P37: 2 | Q37: 0 | R37: 5
A38: 彰化縣 | B38: 計 | C38: Total | D38: 223 | E38: 100 | F38: 123 | G38: 17 | H38: 10 | I38: 9 | J38: 15 | K38: 18 | L38: 18 | M38: 19 | N38: 13 | O38: 23 | P38: 32 | Q38: 14 | R38: 35
A39: Changhua County | B39: 一般 | C39: General | D39: 217 | E39: 99 | F39: 118 | G39: 17 | H39: 9 | I39: 9 | J39: 15 | K39: 18 | L39: 18 | M39: 19 | N39: 13 | O39: 23 | P39: 28 | Q39: 13 | R39: 35
B40: 原住民 | C40: Indigenous | D40: 6 | E40: 1 | F40: 5 | G40: 0 | H40: 1 | I40: 0 | J40: 0 | K40: 0 | L40: 0 | M40: 0 | N40: 0 | O40: 0 | P40: 4 | Q40: 1 | R40: 0
A41: 南投縣 | B41: 計 | C41: Total | D41: 112 | E41: 42 | F41: 70 | G41: 5 | H41: 10 | I41: 7 | J41: 5 | K41: 15 | L41: 9 | M41: 6 | N41: 11 | O41: 5 | P41: 13 | Q41: 4 | R41: 22
...

Sheet 2024
A1: 兒童及少年保護-受虐人數 Number of Abused Child and Youth
A2: 單位：人 Unit : Persons
A3: 民國113年, 2024 | D3: =IF(D8=SUM(D11,D14,D17,D20,D23,D26,D29,D32,D35,D38,D41,D44,D47,D50,D53,D56,D59,D62,D65,D68,D71,D74,),"","*") | E3: =IF(E8=SUM(E11,E14,E17,E20,E23,E26,E29,E32,E35,E38,E41,E44,E47,E50,E53,E56,E59,E62,E65,E68,E71,E74,),"","*") | F3: =IF(F8=SUM(F11,F14,F17,F20,F23,F26,F29,F32,F35,F38,F41,F44,F47,F50,F53,F56,F59,F62,F65,F68,F71,F74,),"","*") | G3: =IF(G8=SUM(G11,G14,G17,G20,G23,G26,G29,G32,G35,G38,G41,G44,G47,G50,G53,G56,G59,G62,G65,G68,G71,G74,),"","*") | H3: =IF(H8=SUM(H11,H14,H17,H20,H23,H26,H29,H32,H35,H38,H41,H44,H47,H50,H53,H56,H59,H62,H65,H68,H71,H74,),"","*") | I3: =IF(I8=SUM(I11,I14,I17,I20,I23,I26,I29,I32,I35,I38,I41,I44,I47,I50,I53,I56,I59,I62,I65,I68,I71,I74,),"","*") | J3: =IF(J8=SUM(J11,J14,J17,J20,J23,J26,J29,J32,J35,J38,J41,J44,J47,J50,J53,J56,J59,J62,J65,J68,J71,J74,),"","*") | K3: =IF(K8=SUM(K11,K14,K17,K20,K23,K26,K29,K32,K35,K38,K41,K44,K47,K50,K53,K56,K59,K62,K65,K68,K71,K74,),"","*") | ... R3: =IF(R8=SUM(R11,R14,R17,R20,R23,R26,R29,R32,R35,R38,R41,R44,R47,R50,R53,R56,R59,R62,R65,R68,R71,R74,),"","*")
A4: 區域及特殊族群別 Locality & Ethnos | D4: 受虐兒童少年人數按年齡分(人) By Age
D5: 合計 Total | G5: 0-未滿3歲 Under 3 Years | I5: 3-未滿6歲 3-Under 6 Years | K5: 6-未滿9歲 6-Under 9 Years | M5: 9-未滿12歲 9-Under 12 Years | O5: 12-未滿15歲 12-Under 15 Years | Q5: 15-未滿18歲 15-Under 18 Years
D6: 計 Total | E6: 男 Male | F6: 女 Female | G6: 男 Male | H6: 女 Female | I6: 男 Male | J6: 女 Female | K6: 男 Male | L6: 女 Female | M6: 男 Male | N6: 女 Female | O6: 男 Male | P6: 女 Female | Q6: 男 Male | R6: 女 Female
A8: 總計 | B8: 計 | C8: Total | D8: 10810 | E8: 4836 | F8: 5974 | G8: 564 | H8: 437 | I8: 788 | J8: 664 | K8: 1202 | L8: 738 | M8: 1086 | N8: 797 | O8: 812 | P8: 1771 | Q8: 384 | R8: 1567
A9: Total | B9: 一般 | C9: General | D9: 9795 | E9: 4375 | F9: 5420 | G9: 509 | H9: 405 | I9: 701 | J9: 616 | K9: 1070 | L9: 675 | M9: 1003 | N9: 710 | O9: 747 | P9: 1585 | Q9: 345 | R9: 1429
B10: 原住民 | C10: Indigenous | D10: 1015 | E10: 461 | F10: 554 | G10: 55 | H10: 32 | I10: 87 | J10: 48 | K10: 132 | L10: 63 | M10: 83 | N10: 87 | O10: 65 | P10: 186 | Q10: 39 | R10: 138
A11: 新北市 | B11: 計 | C11: Total | D11: 2222 | E11: 974 | F11: 1248 | G11: 71 | H11: 47 | I11: 102 | J11: 96 | K11: 254 | L11: 160 | M11: 284 | N11: 189 | O11: 187 | P11: 380 | Q11: 76 | R11: 376
A12: New Taipei City | B12: 一般 | C12: General | D12: 2092 | E12: 917 | F12: 1175 | G12: 70 | H12: 45 | I12: 97 | J12: 90 | K12: 230 | L12: 150 | M12: 267 | N12: 180 | O12: 181 | P12: 348 | Q12: 72 | R12: 362
B13: 原住民 | C13: Indigenous | D13: 130 | E13: 57 | F13: 73 | G13: 1 | H13: 2 | I13: 5 | J13: 6 | K13: 24 | L13: 10 | M13: 17 | N13: 9 | O13: 6 | P13: 32 | Q13: 4 | R13: 14
A14: 臺北市 | B14: 計 | C14: Total | D14: 1077 | E14: 498 | F14: 579 | G14: 56 | H14: 46 | I14: 86 | J14: 110 | K14: 97 | L14: 67 | M14: 111 | N14: 61 | O14: 102 | P14: 159 | Q14: 46 | R14: 136
A15: Taipei City | B15: 一般 | C15: General | D15: 1051 | E15: 483 | F15: 568 | G15: 54 | H15: 44 | I15: 82 | J15: 107 | K15: 91 | L15: 66 | M15: 109 | N15: 60 | O15: 101 | P15: 158 | Q15: 46 | R15: 133
B16: 原住民 | C16: Indigenous | D16: 26 | E16: 15 | F16: 11 | G16: 2 | H16: 2 | I16: 4 | J16: 3 | K16: 6 | L16: 1 | M16: 2 | N16: 1 | O16: 1 | P16: 1 | Q16: 0 | R16: 3
A17: 桃園市 | B17: 計 | C17: Total | D17: 1050 | E17: 491 | F17: 559 | G17: 61 | H17: 56 | I17: 91 | J17: 38 | K17: 143 | L17: 58 | M17: 103 | N17: 84 | O17: 63 | P17: 182 | Q17: 30 | R17: 141
A18: Taoyuan City | B18: 一般 | C18: General | D18: 892 | E18: 409 | F18: 483 | G18: 51 | H18: 53 | I18: 76 | J18: 36 | K18: 116 | L18: 52 | M18: 87 | N18: 67 | O18: 56 | P18: 153 | Q18: 23 | R18: 122
B19: 原住民 | C19: Indigenous | D19: 158 | E19: 82 | F19: 76 | G19: 10 | H19: 3 | I19: 15 | J19: 2 | K19: 27 | L19: 6 | M19: 16 | N19: 17 | O19: 7 | P19: 29 | Q19: 7 | R19: 19
A20: 臺中市 | B20: 計 | C20: Total | D20: 1339 | E20: 654 | F20: 685 | G20: 78 | H20: 53 | I20: 102 | J20: 92 | K20: 163 | L20: 93 | M20: 164 | N20: 87 | O20: 93 | P20: 177 | Q20: 54 | R20: 183
A21: Taichung City | B21: 一般 | C21: General | D21: 1264 | E21: 619 | F21: 645 | G21: 75 | H21: 51 | I21: 96 | J21: 87 | K21: 157 | L21: 87 | M21: 155 | N21: 81 | O21: 86 | P21: 166 | Q21: 50 | R21: 173
B22: 原住民 | C22: Indigenous | D22: 75 | E22: 35 | F22: 40 | G22: 3 | H22: 2 | I22: 6 | J22: 5 | K22: 6 | L22: 6 | M22: 9 | N22: 6 | O22: 7 | P22: 11 | Q22: 4 | R22: 10
A23: 臺南市 | B23: 計 | C23: Total | D23: 572 | E23: 271 | F23: 301 | G23: 46 | H23: 27 | I23: 56 | J23: 42 | K23: 68 | L23: 43 | M23: 38 | N23: 40 | O23: 54 | P23: 75 | Q23: 9 | R23: 74
A24: Tainan City | B24: 一般 | C24: General | D24: 548 | E24: 260 | F24: 288 | G24: 43 | H24: 27 | I24: 55 | J24: 40 | K24: 62 | L24: 42 | M24: 38 | N24: 38 | O24: 53 | P24: 71 | Q24: 9 | R24: 70
B25: 原住民 | C25: Indigenous | D25: 24 | E25: 11 | F25: 13 | G25: 3 | H25: 0 | I25: 1 | J25: 2 | K25: 6 | L25: 1 | M25: 0 | N25: 2 | O25: 1 | P25: 4 | Q25: 0 | R25: 4
A26: 高雄市 | B26: 計 | C26: Total | D26: 1157 | E26: 542 | F26: 615 | G26: 66 | H26: 65 | I26: 68 | J26: 59 | K26: 157 | L26: 90 | M26: 119 | N26: 94 | O26: 94 | P26: 168 | Q26: 38 | R26: 139
A27: Kaohsiung City | B27: 一般 | C27: General | D27: 1084 | E27: 509 | F27: 575 | G27: 62 | H27: 63 | I27: 62 | J27: 54 | K27: 145 | L27: 83 | M27: 114 | N27: 86 | O27: 91 | P27: 159 | Q27: 35 | R27: 130
B28: 原住民 | C28: Indigenous | D28: 73 | E28: 33 | F28: 40 | G28: 4 | H28: 2 | I28: 6 | J28: 5 | K28: 12 | L28: 7 | M28: 5 | N28: 8 | O28: 3 | P28: 9 | Q28: 3 | R28: 9
A29: 宜蘭縣 | B29: 計 | C29: Total | D29: 141 | E29: 52 | F29: 89 | G29: 3 | H29: 8 | I29: 6 | J29: 9 | K29: 15 | L29: 9 | M29: 14 | N29: 8 | O29: 9 | P29: 25 | Q29: 5 | R29: 30
A30: Yilan County | B30: 一般 | C30: General | D30: 128 | E30: 45 | F30: 83 | G30: 3 | H30: 8 | I30: 6 | J30: 9 | K30: 14 | L30: 9 | M30: 13 | N30: 7 | O30: 6 | P30: 22 | Q30: 3 | R30: 28
B31: 原住民 | C31: Indigenous | D31: 13 | E31: 7 | F31: 6 | G31: 0 | H31: 0 | I31: 0 | J31: 0 | K31: 1 | L31: 0 | M31: 1 | N31: 1 | O31: 3 | P31: 3 | Q31: 2 | R31: 2
A32: 新竹縣 | B32: 計 | C32: Total | D32: 416 | E32: 181 | F32: 235 | G32: 31 | H32: 17 | I32: 31 | J32: 30 | K32: 40 | L32: 27 | M32: 32 | N32: 29 | O32: 39 | P32: 89 | Q32: 8 | R32: 43
A33: Hsinchu County | B33: 一般 | C33: General | D33: 345 | E33: 144 | F33: 201 | G33: 28 | H33: 11 | I33: 20 | J33: 24 | K33: 32 | L33: 25 | M33: 26 | N33: 23 | O33: 31 | P33: 80 | Q33: 7 | R33: 38
B34: 原住民 | C34: Indigenous | D34: 71 | E34: 37 | F34: 34 | G34: 3 | H34: 6 | I34: 11 | J34: 6 | K34: 8 | L34: 2 | M34: 6 | N34: 6 | O34: 8 | P34: 9 | Q34: 1 | R34: 5
A35: 苗栗縣 | B35: 計 | C35: Total | D35: 148 | E35: 46 | F35: 102 | G35: 5 | H35: 2 | I35: 4 | J35: 8 | K35: 11 | L35: 21 | M35: 12 | N35: 14 | O35: 8 | P35: 31 | Q35: 6 | R35: 26
A36: Miaoli County | B36: 一般 | C36: General | D36: 131 | E36: 41 | F36: 90 | G36: 5 | H36: 2 | I36: 3 | J36: 8 | K36: 10 | L36: 20 | M36: 11 | N36: 10 | O36: 6 | P36: 27 | Q36: 6 | R36: 23
B37: 原住民 | C37: Indigenous | D37: 17 | E37: 5 | F37: 12 | G37: 0 | H37: 0 | I37: 1 | J37: 0 | K37: 1 | L37: 1 | M37: 1 | N37: 4 | O37: 2 | P37: 4 | Q37: 0 | R37: 3
A38: 彰化縣 | B38: 計 | C38: Total | D38: 544 | E38: 226 | F38: 318 | G38: 31 | H38: 30 | I38: 57 | J38: 27 | K38: 58 | L38: 30 | M38: 39 | N38: 33 | O38: 26 | P38: 98 | Q38: 15 | R38: 100
A39: Changhua County | B39: 一般 | C39: General | D39: 517 | E39: 216 | F39: 301 | G39: 27 | H39: 28 | I39: 56 | J39: 26 | K39: 55 | L39: 30 | M39: 37 | N39: 30 | O39: 26 | P39: 95 | Q39: 15 | R39: 92
B40: 原住民 | C40: Indigenous | D40: 27 | E40: 10 | F40: 17 | G40: 4 | H40: 2 | I40: 1 | J40: 1 | K40: 3 | L40: 0 | M40: 2 | N40: 3 | O40: 0 | P40: 3 | Q40: 0 | R40: 8
A41: 南投縣 | B41: 計 | C41: Total | D41: 221 | E41: 101 | F41: 120 | G41: 9 | H41: 8 | I41: 17 | J41: 19 | K41: 23 | L41: 11 | M41: 26 | N41: 19 | O41: 17 | P41: 38 | Q41: 9 | R41: 25
...

Sheet July-Dec., 2024
A1: 兒童及少年保護-受虐人數 Number of Abused Child and Youth
A2: 單位：人 Unit : Persons
A3: 民國113年7-12月, July-Dec., 2024 | D3: =IF(D8=SUM(D11,D14,D17,D20,D23,D26,D29,D32,D35,D38,D41,D44,D47,D50,D53,D56,D59,D62,D65,D68,D71,D74,),"","*") | E3: =IF(E8=SUM(E11,E14,E17,E20,E23,E26,E29,E32,E35,E38,E41,E44,E47,E50,E53,E56,E59,E62,E65,E68,E71,E74,),"","*") | F3: =IF(F8=SUM(F11,F14,F17,F20,F23,F26,F29,F32,F35,F38,F41,F44,F47,F50,F53,F56,F59,F62,F65,F68,F71,F74,),"","*") | G3: =IF(G8=SUM(G11,G14,G17,G20,G23,G26,G29,G32,G35,G38,G41,G44,G47,G50,G53,G56,G59,G62,G65,G68,G71,G74,),"","*") | H3: =IF(H8=SUM(H11,H14,H17,H20,H23,H26,H29,H32,H35,H38,H41,H44,H47,H50,H53,H56,H59,H62,H65,H68,H71,H74,),"","*") | I3: =IF(I8=SUM(I11,I14,I17,I20,I23,I26,I29,I32,I35,I38,I41,I44,I47,I50,I53,I56,I59,I62,I65,I68,I71,I74,),"","*") | J3: =IF(J8=SUM(J11,J14,J17,J20,J23,J26,J29,J32,J35,J38,J41,J44,J47,J50,J53,J56,J59,J62,J65,J68,J71,J74,),"","*") | K3: =IF(K8=SUM(K11,K14,K17,K20,K23,K26,K29,K32,K35,K38,K41,K44,K47,K50,K53,K56,K59,K62,K65,K68,K71,K74,),"","*") | ... R3: =IF(R8=SUM(R11,R14,R17,R20,R23,R26,R29,R32,R35,R38,R41,R44,R47,R50,R53,R56,R59,R62,R65,R68,R71,R74,),"","*")
A4: 區域及特殊族群別 Locality & Ethnos | D4: 受虐兒童少年人數按年齡分(人) By Age
D5: 合計 Total | G5: 0-未滿3歲 Under 3 Years | I5: 3-未滿6歲 3-Under 6 Years | K5: 6-未滿9歲 6-Under 9 Years | M5: 9-未滿12歲 9-Under 12 Years | O5: 12-未滿15歲 12-Under 15 Years | Q5: 15-未滿18歲 15-Under 18 Years
D6: 計 Total | E6: 男 Male | F6: 女 Female | G6: 男 Male | H6: 女 Female | I6: 男 Male | J6: 女 Female | K6: 男 Male | L6: 女 Female | M6: 男 Male | N6: 女 Female | O6: 男 Male | P6: 女 Female | Q6: 男 Male | R6: 女 Female
A8: 總計 | B8: 計 | C8: Total | D8: 5039 | E8: 2315 | F8: 2724 | G8: 307 | H8: 225 | I8: 370 | J8: 333 | K8: 566 | L8: 330 | M8: 486 | N8: 344 | O8: 403 | P8: 819 | Q8: 183 | R8: 673
A9: Total | B9: 一般 | C9: General | D9: 4540 | E9: 2086 | F9: 2454 | G9: 271 | H9: 211 | I9: 325 | J9: 306 | K9: 502 | L9: 293 | M9: 458 | N9: 298 | O9: 369 | P9: 742 | Q9: 161 | R9: 604
B10: 原住民 | C10: Indigenous | D10: 499 | E10: 229 | F10: 270 | G10: 36 | H10: 14 | I10: 45 | J10: 27 | K10: 64 | L10: 37 | M10: 28 | N10: 46 | O10: 34 | P10: 77 | Q10: 22 | R10: 69
A11: 新北市 | B11: 計 | C11: Total | D11: 1014 | E11: 463 | F11: 551 | G11: 33 | H11: 20 | I11: 45 | J11: 48 | K11: 113 | L11: 72 | M11: 145 | N11: 82 | O11: 87 | P11: 176 | Q11: 40 | R11: 153
A12: New Taipei City | B12: 一般 | C12: General | D12: 960 | E12: 444 | F12: 516 | G12: 33 | H12: 19 | I12: 41 | J12: 44 | K12: 105 | L12: 67 | M12: 141 | N12: 78 | O12: 86 | P12: 161 | Q12: 38 | R12: 147
B13: 原住民 | C13: Indigenous | D13: 54 | E13: 19 | F13: 35 | G13: 0 | H13: 1 | I13: 4 | J13: 4 | K13: 8 | L13: 5 | M13: 4 | N13: 4 | O13: 1 | P13: 15 | Q13: 2 | R13: 6
A14: 臺北市 | B14: 計 | C14: Total | D14: 506 | E14: 246 | F14: 260 | G14: 38 | H14: 25 | I14: 49 | J14: 61 | K14: 45 | L14: 36 | M14: 41 | N14: 19 | O14: 52 | P14: 71 | Q14: 21 | R14: 48
A15: Taipei City | B15: 一般 | C15: General | D15: 500 | E15: 243 | F15: 257 | G15: 38 | H15: 24 | I15: 48 | J15: 61 | K15: 43 | L15: 35 | M15: 41 | N15: 19 | O15: 52 | P15: 70 | Q15: 21 | R15: 48
B16: 原住民 | C16: Indigenous | D16: 6 | E16: 3 | F16: 3 | G16: 0 | H16: 1 | I16: 1 | J16: 0 | K16: 2 | L16: 1 | M16: 0 | N16: 0 | O16: 0 | P16: 1 | Q16: 0 | R16: 0
A17: 桃園市 | B17: 計 | C17: Total | D17: 545 | E17: 259 | F17: 286 | G17: 36 | H17: 35 | I17: 45 | J17: 16 | K17: 71 | L17: 23 | M17: 54 | N17: 39 | O17: 36 | P17: 97 | Q17: 17 | R17: 76
A18: Taoyuan City | B18: 一般 | C18: General | D18: 447 | E18: 205 | F18: 242 | G18: 27 | H18: 34 | I18: 37 | J18: 15 | K18: 52 | L18: 20 | M18: 44 | N18: 27 | O18: 32 | P18: 83 | Q18: 13 | R18: 63
B19: 原住民 | C19: Indigenous | D19: 98 | E19: 54 | F19: 44 | G19: 9 | H19: 1 | I19: 8 | J19: 1 | K19: 19 | L19: 3 | M19: 10 | N19: 12 | O19: 4 | P19: 14 | Q19: 4 | R19: 13
A20: 臺中市 | B20: 計 | C20: Total | D20: 622 | E20: 315 | F20: 307 | G20: 44 | H20: 18 | I20: 46 | J20: 53 | K20: 85 | L20: 39 | M20: 74 | N20: 42 | O20: 44 | P20: 89 | Q20: 22 | R20: 66
A21: Taichung City | B21: 一般 | C21: General | D21: 589 | E21: 303 | F21: 286 | G21: 43 | H21: 17 | I21: 44 | J21: 49 | K21: 84 | L21: 34 | M21: 72 | N21: 41 | O21: 40 | P21: 82 | Q21: 20 | R21: 63
B22: 原住民 | C22: Indigenous | D22: 33 | E22: 12 | F22: 21 | G22: 1 | H22: 1 | I22: 2 | J22: 4 | K22: 1 | L22: 5 | M22: 2 | N22: 1 | O22: 4 | P22: 7 | Q22: 2 | R22: 3
A23: 臺南市 | B23: 計 | C23: Total | D23: 263 | E23: 128 | F23: 135 | G23: 26 | H23: 10 | I23: 22 | J23: 21 | K23: 40 | L23: 17 | M23: 12 | N23: 18 | O23: 25 | P23: 34 | Q23: 3 | R23: 35
A24: Tainan City | B24: 一般 | C24: General | D24: 248 | E24: 118 | F24: 130 | G24: 24 | H24: 10 | I24: 21 | J24: 21 | K24: 34 | L24: 16 | M24: 12 | N24: 18 | O24: 24 | P24: 32 | Q24: 3 | R24: 33
B25: 原住民 | C25: Indigenous | D25: 15 | E25: 10 | F25: 5 | G25: 2 | H25: 0 | I25: 1 | J25: 0 | K25: 6 | L25: 1 | M25: 0 | N25: 0 | O25: 1 | P25: 2 | Q25: 0 | R25: 2
A26: 高雄市 | B26: 計 | C26: Total | D26: 553 | E26: 259 | F26: 294 | G26: 38 | H26: 39 | I26: 27 | J26: 27 | K26: 73 | L26: 42 | M26: 54 | N26: 42 | O26: 50 | P26: 77 | Q26: 17 | R26: 67
A27: Kaohsiung City | B27: 一般 | C27: General | D27: 516 | E27: 244 | F27: 272 | G27: 36 | H27: 39 | I27: 25 | J27: 24 | K27: 69 | L27: 38 | M27: 52 | N27: 37 | O27: 47 | P27: 71 | Q27: 15 | R27: 63
B28: 原住民 | C28: Indigenous | D28: 37 | E28: 15 | F28: 22 | G28: 2 | H28: 0 | I28: 2 | J28: 3 | K28: 4 | L28: 4 | M28: 2 | N28: 5 | O28: 3 | P28: 6 | Q28: 2 | R28: 4
A29: 宜蘭縣 | B29: 計 | C29: Total | D29: 47 | E29: 21 | F29: 26 | G29: 2 | H29: 4 | I29: 3 | J29: 0 | K29: 6 | L29: 4 | M29: 4 | N29: 0 | O29: 5 | P29: 9 | Q29: 1 | R29: 9
A30: Yilan County | B30: 一般 | C30: General | D30: 44 | E30: 19 | F30: 25 | G30: 2 | H30: 4 | I30: 3 | J30: 0 | K30: 6 | L30: 4 | M30: 4 | N30: 0 | O30: 3 | P30: 9 | Q30: 1 | R30: 8
B31: 原住民 | C31: Indigenous | D31: 3 | E31: 2 | F31: 1 | G31: 0 | H31: 0 | I31: 0 | J31: 0 | K31: 0 | L31: 0 | M31: 0 | N31: 0 | O31: 2 | P31: 0 | Q31: 0 | R31: 1
A32: 新竹縣 | B32: 計 | C32: Total | D32: 212 | E32: 95 | F32: 117 | G32: 17 | H32: 9 | I32: 17 | J32: 16 | K32: 26 | L32: 15 | M32: 11 | N32: 14 | O32: 21 | P32: 41 | Q32: 3 | R32: 22
A33: Hsinchu County | B33: 一般 | C33: General | D33: 175 | E33: 77 | F33: 98 | G33: 15 | H33: 6 | I33: 8 | J33: 14 | K33: 22 | L33: 13 | M33: 10 | N33: 11 | O33: 19 | P33: 36 | Q33: 3 | R33: 18
B34: 原住民 | C34: Indigenous | D34: 37 | E34: 18 | F34: 19 | G34: 2 | H34: 3 | I34: 9 | J34: 2 | K34: 4 | L34: 2 | M34: 1 | N34: 3 | O34: 2 | P34: 5 | Q34: 0 | R34: 4
A35: 苗栗縣 | B35: 計 | C35: Total | D35: 75 | E35: 25 | F35: 50 | G35: 3 | H35: 0 | I35: 2 | J35: 3 | K35: 5 | L35: 6 | M35: 8 | N35: 9 | O35: 3 | P35: 19 | Q35: 4 | R35: 13
A36: Miaoli County | B36: 一般 | C36: General | D36: 66 | E36: 22 | F36: 44 | G36: 3 | H36: 0 | I36: 2 | J36: 3 | K36: 4 | L36: 6 | M36: 7 | N36: 5 | O36: 2 | P36: 17 | Q36: 4 | R36: 13
B37: 原住民 | C37: Indigenous | D37: 9 | E37: 3 | F37: 6 | G37: 0 | H37: 0 | I37: 0 | J37: 0 | K37: 1 | L37: 0 | M37: 1 | N37: 4 | O37: 1 | P37: 2 | Q37: 0 | R37: 0
A38: 彰化縣 | B38: 計 | C38: Total | D38: 260 | E38: 107 | F38: 153 | G38: 17 | H38: 18 | I38: 27 | J38: 12 | K38: 23 | L38: 11 | M38: 20 | N38: 14 | O38: 10 | P38: 55 | Q38: 10 | R38: 43
A39: Changhua County | B39: 一般 | C39: General | D39: 242 | E39: 103 | F39: 139 | G39: 15 | H39: 16 | I39: 26 | J39: 11 | K39: 22 | L39: 11 | M39: 20 | N39: 11 | O39: 10 | P39: 53 | Q39: 10 | R39: 37
B40: 原住民 | C40: Indigenous | D40: 18 | E40: 4 | F40: 14 | G40: 2 | H40: 2 | I40: 1 | J40: 1 | K40: 1 | L40: 0 | M40: 0 | N40: 3 | O40: 0 | P40: 2 | Q40: 0 | R40: 6
A41: 南投縣 | B41: 計 | C41: Total | D41: 107 | E41: 50 | F41: 57 | G41: 5 | H41: 5 | I41: 12 | J41: 13 | K41: 13 | L41: 8 | M41: 7 | N41: 5 | O41: 6 | P41: 18 | Q41: 7 | R41: 8
...

Sheet Jan.-June, 2024
A1: 兒童及少年保護-受虐人數 Number of Abused Child and Youth
A2: 單位：人 Unit : Persons
A3: 民國113年1-6月,Jan.-June, 2024 | D3: =IF(D8=SUM(D11,D14,D17,D20,D23,D26,D29,D32,D35,D38,D41,D44,D47,D50,D53,D56,D59,D62,D65,D68,D71,D74,),"","*") | E3: =IF(E8=SUM(E11,E14,E17,E20,E23,E26,E29,E32,E35,E38,E41,E44,E47,E50,E53,E56,E59,E62,E65,E68,E71,E74,),"","*") | F3: =IF(F8=SUM(F11,F14,F17,F20,F23,F26,F29,F32,F35,F38,F41,F44,F47,F50,F53,F56,F59,F62,F65,F68,F71,F74,),"","*") | G3: =IF(G8=SUM(G11,G14,G17,G20,G23,G26,G29,G32,G35,G38,G41,G44,G47,G50,G53,G56,G59,G62,G65,G68,G71,G74,),"","*") | H3: =IF(H8=SUM(H11,H14,H17,H20,H23,H26,H29,H32,H35,H38,H41,H44,H47,H50,H53,H56,H59,H62,H65,H68,H71,H74,),"","*") | I3: =IF(I8=SUM(I11,I14,I17,I20,I23,I26,I29,I32,I35,I38,I41,I44,I47,I50,I53,I56,I59,I62,I65,I68,I71,I74,),"","*") | J3: =IF(J8=SUM(J11,J14,J17,J20,J23,J26,J29,J32,J35,J38,J41,J44,J47,J50,J53,J56,J59,J62,J65,J68,J71,J74,),"","*") | K3: =IF(K8=SUM(K11,K14,K17,K20,K23,K26,K29,K32,K35,K38,K41,K44,K47,K50,K53,K56,K59,K62,K65,K68,K71,K74,),"","*") | ... R3: =IF(R8=SUM(R11,R14,R17,R20,R23,R26,R29,R32,R35,R38,R41,R44,R47,R50,R53,R56,R59,R62,R65,R68,R71,R74,),"","*")
A4: 區域及特殊族群別 Locality & Ethnos | D4: 受虐兒童少年人數按年齡分(人) By Age
D5: 合計 Total | G5: 0-未滿3歲 Under 3 Years | I5: 3-未滿6歲 3-Under 6 Years | K5: 6-未滿9歲 6-Under 9 Years | M5: 9-未滿12歲 9-Under 12 Years | O5: 12-未滿15歲 12-Under 15 Years | Q5: 15-未滿18歲 15-Under 18 Years
D6: 計 Total | E6: 男 Male | F6: 女 Female | G6: 男 Male | H6: 女 Female | I6: 男 Male | J6: 女 Female | K6: 男 Male | L6: 女 Female | M6: 男 Male | N6: 女 Female | O6: 男 Male | P6: 女 Female | Q6: 男 Male | R6: 女 Female
A8: 總計 | B8: 計 | C8: Total | D8: 5771 | E8: 2521 | F8: 3250 | G8: 257 | H8: 212 | I8: 418 | J8: 331 | K8: 636 | L8: 408 | M8: 600 | N8: 453 | O8: 409 | P8: 952 | Q8: 201 | R8: 894
A9: Total | B9: 一般 | C9: General | D9: 5255 | E9: 2289 | F9: 2966 | G9: 238 | H9: 194 | I9: 376 | J9: 310 | K9: 568 | L9: 382 | M9: 545 | N9: 412 | O9: 378 | P9: 843 | Q9: 184 | R9: 825
B10: 原住民 | C10: Indigenous | D10: 516 | E10: 232 | F10: 284 | G10: 19 | H10: 18 | I10: 42 | J10: 21 | K10: 68 | L10: 26 | M10: 55 | N10: 41 | O10: 31 | P10: 109 | Q10: 17 | R10: 69
A11: 新北市 | B11: 計 | C11: Total | D11: 1208 | E11: 511 | F11: 697 | G11: 38 | H11: 27 | I11: 57 | J11: 48 | K11: 141 | L11: 88 | M11: 139 | N11: 107 | O11: 100 | P11: 204 | Q11: 36 | R11: 223
A12: New Taipei City | B12: 一般 | C12: General | D12: 1132 | E12: 473 | F12: 659 | G12: 37 | H12: 26 | I12: 56 | J12: 46 | K12: 125 | L12: 83 | M12: 126 | N12: 102 | O12: 95 | P12: 187 | Q12: 34 | R12: 215
B13: 原住民 | C13: Indigenous | D13: 76 | E13: 38 | F13: 38 | G13: 1 | H13: 1 | I13: 1 | J13: 2 | K13: 16 | L13: 5 | M13: 13 | N13: 5 | O13: 5 | P13: 17 | Q13: 2 | R13: 8
A14: 臺北市 | B14: 計 | C14: Total | D14: 571 | E14: 252 | F14: 319 | G14: 18 | H14: 21 | I14: 37 | J14: 49 | K14: 52 | L14: 31 | M14: 70 | N14: 42 | O14: 50 | P14: 88 | Q14: 25 | R14: 88
A15: Taipei City | B15: 一般 | C15: General | D15: 551 | E15: 240 | F15: 311 | G15: 16 | H15: 20 | I15: 34 | J15: 46 | K15: 48 | L15: 31 | M15: 68 | N15: 41 | O15: 49 | P15: 88 | Q15: 25 | R15: 85
B16: 原住民 | C16: Indigenous | D16: 20 | E16: 12 | F16: 8 | G16: 2 | H16: 1 | I16: 3 | J16: 3 | K16: 4 | L16: 0 | M16: 2 | N16: 1 | O16: 1 | P16: 0 | Q16: 0 | R16: 3
A17: 桃園市 | B17: 計 | C17: Total | D17: 505 | E17: 232 | F17: 273 | G17: 25 | H17: 21 | I17: 46 | J17: 22 | K17: 72 | L17: 35 | M17: 49 | N17: 45 | O17: 27 | P17: 85 | Q17: 13 | R17: 65
A18: Taoyuan City | B18: 一般 | C18: General | D18: 445 | E18: 204 | F18: 241 | G18: 24 | H18: 19 | I18: 39 | J18: 21 | K18: 64 | L18: 32 | M18: 43 | N18: 40 | O18: 24 | P18: 70 | Q18: 10 | R18: 59
B19: 原住民 | C19: Indigenous | D19: 60 | E19: 28 | F19: 32 | G19: 1 | H19: 2 | I19: 7 | J19: 1 | K19: 8 | L19: 3 | M19: 6 | N19: 5 | O19: 3 | P19: 15 | Q19: 3 | R19: 6
A20: 臺中市 | B20: 計 | C20: Total | D20: 717 | E20: 339 | F20: 378 | G20: 34 | H20: 35 | I20: 56 | J20: 39 | K20: 78 | L20: 54 | M20: 90 | N20: 45 | O20: 49 | P20: 88 | Q20: 32 | R20: 117
A21: Taichung City | B21: 一般 | C21: General | D21: 675 | E21: 316 | F21: 359 | G21: 32 | H21: 34 | I21: 52 | J21: 38 | K21: 73 | L21: 53 | M21: 83 | N21: 40 | O21: 46 | P21: 84 | Q21: 30 | R21: 110
B22: 原住民 | C22: Indigenous | D22: 42 | E22: 23 | F22: 19 | G22: 2 | H22: 1 | I22: 4 | J22: 1 | K22: 5 | L22: 1 | M22: 7 | N22: 5 | O22: 3 | P22: 4 | Q22: 2 | R22: 7
A23: 臺南市 | B23: 計 | C23: Total | D23: 309 | E23: 143 | F23: 166 | G23: 20 | H23: 17 | I23: 34 | J23: 21 | K23: 28 | L23: 26 | M23: 26 | N23: 22 | O23: 29 | P23: 41 | Q23: 6 | R23: 39
A24: Tainan City | B24: 一般 | C24: General | D24: 300 | E24: 142 | F24: 158 | G24: 19 | H24: 17 | I24: 34 | J24: 19 | K24: 28 | L24: 26 | M24: 26 | N24: 20 | O24: 29 | P24: 39 | Q24: 6 | R24: 37
B25: 原住民 | C25: Indigenous | D25: 9 | E25: 1 | F25: 8 | G25: 1 | H25: 0 | I25: 0 | J25: 2 | K25: 0 | L25: 0 | M25: 0 | N25: 2 | O25: 0 | P25: 2 | Q25: 0 | R25: 2
A26: 高雄市 | B26: 計 | C26: Total | D26: 604 | E26: 283 | F26: 321 | G26: 28 | H26: 26 | I26: 41 | J26: 32 | K26: 84 | L26: 48 | M26: 65 | N26: 52 | O26: 44 | P26: 91 | Q26: 21 | R26: 72
A27: Kaohsiung City | B27: 一般 | C27: General | D27: 568 | E27: 265 | F27: 303 | G27: 26 | H27: 24 | I27: 37 | J27: 30 | K27: 76 | L27: 45 | M27: 62 | N27: 49 | O27: 44 | P27: 88 | Q27: 20 | R27: 67
B28: 原住民 | C28: Indigenous | D28: 36 | E28: 18 | F28: 18 | G28: 2 | H28: 2 | I28: 4 | J28: 2 | K28: 8 | L28: 3 | M28: 3 | N28: 3 | O28: 0 | P28: 3 | Q28: 1 | R28: 5
A29: 宜蘭縣 | B29: 計 | C29: Total | D29: 94 | E29: 31 | F29: 63 | G29: 1 | H29: 4 | I29: 3 | J29: 9 | K29: 9 | L29: 5 | M29: 10 | N29: 8 | O29: 4 | P29: 16 | Q29: 4 | R29: 21
A30: Yilan County | B30: 一般 | C30: General | D30: 84 | E30: 26 | F30: 58 | G30: 1 | H30: 4 | I30: 3 | J30: 9 | K30: 8 | L30: 5 | M30: 9 | N30: 7 | O30: 3 | P30: 13 | Q30: 2 | R30: 20
B31: 原住民 | C31: Indigenous | D31: 10 | E31: 5 | F31: 5 | G31: 0 | H31: 0 | I31: 0 | J31: 0 | K31: 1 | L31: 0 | M31: 1 | N31: 1 | O31: 1 | P31: 3 | Q31: 2 | R31: 1
A32: 新竹縣 | B32: 計 | C32: Total | D32: 204 | E32: 86 | F32: 118 | G32: 14 | H32: 8 | I32: 14 | J32: 14 | K32: 14 | L32: 12 | M32: 21 | N32: 15 | O32: 18 | P32: 48 | Q32: 5 | R32: 21
A33: Hsinchu County | B33: 一般 | C33: General | D33: 170 | E33: 67 | F33: 103 | G33: 13 | H33: 5 | I33: 12 | J33: 10 | K33: 10 | L33: 12 | M33: 16 | N33: 12 | O33: 12 | P33: 44 | Q33: 4 | R33: 20
B34: 原住民 | C34: Indigenous | D34: 34 | E34: 19 | F34: 15 | G34: 1 | H34: 3 | I34: 2 | J34: 4 | K34: 4 | L34: 0 | M34: 5 | N34: 3 | O34: 6 | P34: 4 | Q34: 1 | R34: 1
A35: 苗栗縣 | B35: 計 | C35: Total | D35: 73 | E35: 21 | F35: 52 | G35: 2 | H35: 2 | I35: 2 | J35: 5 | K35: 6 | L35: 15 | M35: 4 | N35: 5 | O35: 5 | P35: 12 | Q35: 2 | R35: 13
A36: Miaoli County | B36: 一般 | C36: General | D36: 65 | E36: 19 | F36: 46 | G36: 2 | H36: 2 | I36: 1 | J36: 5 | K36: 6 | L36: 14 | M36: 4 | N36: 5 | O36: 4 | P36: 10 | Q36: 2 | R36: 10
B37: 原住民 | C37: Indigenous | D37: 8 | E37: 2 | F37: 6 | G37: 0 | H37: 0 | I37: 1 | J37: 0 | K37: 0 | L37: 1 | M37: 0 | N37: 0 | O37: 1 | P37: 2 | Q37: 0 | R37: 3
A38: 彰化縣 | B38: 計 | C38: Total | D38: 284 | E38: 119 | F38: 165 | G38: 14 | H38: 12 | I38: 30 | J38: 15 | K38: 35 | L38: 19 | M38: 19 | N38: 19 | O38: 16 | P38: 43 | Q38: 5 | R38: 57
A39: Changhua County | B39: 一般 | C39: General | D39: 275 | E39: 113 | F39: 162 | G39: 12 | H39: 12 | I39: 30 | J39: 15 | K39: 33 | L39: 19 | M39: 17 | N39: 19 | O39: 16 | P39: 42 | Q39: 5 | R39: 55
B40: 原住民 | C40: Indigenous | D40: 9 | E40: 6 | F40: 3 | G40: 2 | H40: 0 | I40: 0 | J40: 0 | K40: 2 | L40: 0 | M40: 2 | N40: 0 | O40: 0 | P40: 1 | Q40: 0 | R40: 2
A41: 南投縣 | B41: 計 | C41: Total | D41: 114 | E41: 51 | F41: 63 | G41: 4 | H41: 3 | I41: 5 | J41: 6 | K41: 10 | L41: 3 | M41: 19 | N41: 14 | O41: 11 | P41: 20 | Q41: 2 | R41: 17
...

Sheet 2023
A1: 兒童及少年保護-受虐人數 Number of Abused Child and Youth
A2: 單位：人 Unit : Persons
A3: 民國112年, 2023 | D3: =IF(D8=SUM(D11,D14,D17,D20,D23,D26,D29,D32,D35,D38,D41,D44,D47,D50,D53,D56,D59,D62,D65,D68,D71,D74,),"","*") | E3: =IF(E8=SUM(E11,E14,E17,E20,E23,E26,E29,E32,E35,E38,E41,E44,E47,E50,E53,E56,E59,E62,E65,E68,E71,E74,),"","*") | F3: =IF(F8=SUM(F11,F14,F17,F20,F23,F26,F29,F32,F35,F38,F41,F44,F47,F50,F53,F56,F59,F62,F65,F68,F71,F74,),"","*") | G3: =IF(G8=SUM(G11,G14,G17,G20,G23,G26,G29,G32,G35,G38,G41,G44,G47,G50,G53,G56,G59,G62,G65,G68,G71,G74,),"","*") | H3: =IF(H8=SUM(H11,H14,H17,H20,H23,H26,H29,H32,H35,H38,H41,H44,H47,H50,H53,H56,H59,H62,H65,H68,H71,H74,),"","*") | I3: =IF(I8=SUM(I11,I14,I17,I20,I23,I26,I29,I32,I35,I38,I41,I44,I47,I50,I53,I56,I59,I62,I65,I68,I71,I74,),"","*") | J3: =IF(J8=SUM(J11,J14,J17,J20,J23,J26,J29,J32,J35,J38,J41,J44,J47,J50,J53,J56,J59,J62,J65,J68,J71,J74,),"","*") | K3: =IF(K8=SUM(K11,K14,K17,K20,K23,K26,K29,K32,K35,K38,K41,K44,K47,K50,K53,K56,K59,K62,K65,K68,K71,K74,),"","*") | ... R3: =IF(R8=SUM(R11,R14,R17,R20,R23,R26,R29,R32,R35,R38,R41,R44,R47,R50,R53,R56,R59,R62,R65,R68,R71,R74,),"","*")
A4: 區域及特殊族群別 Locality & Ethnos | D4: 受虐兒童少年人數按年齡分(人) By Age
D5: 合計 Total | G5: 0-未滿3歲 Under 3 Years | I5: 3-未滿6歲 3-Under 6 Years | K5: 6-未滿9歲 6-Under 9 Years | M5: 9-未滿12歲 9-Under 12 Years | O5: 12-未滿15歲 12-Under 15 Years | Q5: 15-未滿18歲 15-Under 18 Years
D6: 計 Total | E6: 男 Male | F6: 女 Female | G6: 男 Male | H6: 女 Female | I6: 男 Male | J6: 女 Female | K6: 男 Male | L6: 女 Female | M6: 男 Male | N6: 女 Female | O6: 男 Male | P6: 女 Female | Q6: 男 Male | R6: 女 Female
A8: 總計 | B8: 計 | C8: Total | D8: 12646 | E8: 5649 | F8: 6997 | G8: 668 | H8: 534 | I8: 968 | J8: 698 | K8: 1178 | L8: 825 | M8: 1196 | N8: 944 | O8: 987 | P8: 2178 | Q8: 652 | R8: 1818
A9: Total | B9: 一般 | C9: General | D9: 11345 | E9: 5102 | F9: 6243 | G9: 591 | H9: 491 | I9: 866 | J9: 627 | K9: 1052 | L9: 734 | M9: 1087 | N9: 826 | O9: 901 | P9: 1906 | Q9: 605 | R9: 1659
B10: 原住民 | C10: Indigenous | D10: 1301 | E10: 547 | F10: 754 | G10: 77 | H10: 43 | I10: 102 | J10: 71 | K10: 126 | L10: 91 | M10: 109 | N10: 118 | O10: 86 | P10: 272 | Q10: 47 | R10: 159
A11: 新北市 | B11: 計 | C11: Total | D11: 1936 | E11: 821 | F11: 1115 | G11: 42 | H11: 37 | I11: 120 | J11: 92 | K11: 198 | L11: 110 | M11: 196 | N11: 179 | O11: 174 | P11: 364 | Q11: 91 | R11: 333
A12: New Taipei City | B12: 一般 | C12: General | D12: 1836 | E12: 784 | F12: 1052 | G12: 41 | H12: 37 | I12: 113 | J12: 89 | K12: 183 | L12: 107 | M12: 190 | N12: 169 | O12: 170 | P12: 330 | Q12: 87 | R12: 320
B13: 原住民 | C13: Indigenous | D13: 100 | E13: 37 | F13: 63 | G13: 1 | H13: 0 | I13: 7 | J13: 3 | K13: 15 | L13: 3 | M13: 6 | N13: 10 | O13: 4 | P13: 34 | Q13: 4 | R13: 13
A14: 臺北市 | B14: 計 | C14: Total | D14: 1068 | E14: 473 | F14: 595 | G14: 47 | H14: 47 | I14: 85 | J14: 75 | K14: 75 | L14: 51 | M14: 107 | N14: 63 | O14: 93 | P14: 198 | Q14: 66 | R14: 161
A15: Taipei City | B15: 一般 | C15: General | D15: 1032 | E15: 460 | F15: 572 | G15: 47 | H15: 46 | I15: 76 | J15: 74 | K15: 73 | L15: 50 | M15: 106 | N15: 63 | O15: 93 | P15: 184 | Q15: 65 | R15: 155
B16: 原住民 | C16: Indigenous | D16: 36 | E16: 13 | F16: 23 | G16: 0 | H16: 1 | I16: 9 | J16: 1 | K16: 2 | L16: 1 | M16: 1 | N16: 0 | O16: 0 | P16: 14 | Q16: 1 | R16: 6
A17: 桃園市 | B17: 計 | C17: Total | D17: 1521 | E17: 721 | F17: 800 | G17: 95 | H17: 53 | I17: 140 | J17: 84 | K17: 188 | L17: 131 | M17: 152 | N17: 97 | O17: 96 | P17: 256 | Q17: 50 | R17: 179
A18: Taoyuan City | B18: 一般 | C18: General | D18: 1265 | E18: 604 | F18: 661 | G18: 76 | H18: 47 | I18: 115 | J18: 67 | K18: 157 | L18: 99 | M18: 135 | N18: 75 | O18: 81 | P18: 219 | Q18: 40 | R18: 154
B19: 原住民 | C19: Indigenous | D19: 256 | E19: 117 | F19: 139 | G19: 19 | H19: 6 | I19: 25 | J19: 17 | K19: 31 | L19: 32 | M19: 17 | N19: 22 | O19: 15 | P19: 37 | Q19: 10 | R19: 25
A20: 臺中市 | B20: 計 | C20: Total | D20: 2074 | E20: 996 | F20: 1078 | G20: 132 | H20: 124 | I20: 203 | J20: 134 | K20: 197 | L20: 138 | M20: 208 | N20: 150 | O20: 146 | P20: 274 | Q20: 110 | R20: 258
A21: Taichung City | B21: 一般 | C21: General | D21: 1957 | E21: 940 | F21: 1017 | G21: 121 | H21: 118 | I21: 194 | J21: 127 | K21: 188 | L21: 136 | M21: 193 | N21: 140 | O21: 141 | P21: 248 | Q21: 103 | R21: 248
B22: 原住民 | C22: Indigenous | D22: 117 | E22: 56 | F22: 61 | G22: 11 | H22: 6 | I22: 9 | J22: 7 | K22: 9 | L22: 2 | M22: 15 | N22: 10 | O22: 5 | P22: 26 | Q22: 7 | R22: 10
A23: 臺南市 | B23: 計 | C23: Total | D23: 804 | E23: 351 | F23: 453 | G23: 53 | H23: 52 | I23: 61 | J23: 42 | K23: 58 | L23: 67 | M23: 81 | N23: 68 | O23: 66 | P23: 114 | Q23: 32 | R23: 110
A24: Tainan City | B24: 一般 | C24: General | D24: 777 | E24: 340 | F24: 437 | G24: 52 | H24: 51 | I24: 60 | J24: 40 | K24: 57 | L24: 66 | M24: 76 | N24: 65 | O24: 65 | P24: 107 | Q24: 30 | R24: 108
B25: 原住民 | C25: Indigenous | D25: 27 | E25: 11 | F25: 16 | G25: 1 | H25: 1 | I25: 1 | J25: 2 | K25: 1 | L25: 1 | M25: 5 | N25: 3 | O25: 1 | P25: 7 | Q25: 2 | R25: 2
A26: 高雄市 | B26: 計 | C26: Total | D26: 1489 | E26: 717 | F26: 772 | G26: 90 | H26: 66 | I26: 113 | J26: 73 | K26: 146 | L26: 90 | M26: 162 | N26: 106 | O26: 116 | P26: 246 | Q26: 90 | R26: 191
A27: Kaohsiung City | B27: 一般 | C27: General | D27: 1397 | E27: 678 | F27: 719 | G27: 89 | H27: 62 | I27: 106 | J27: 68 | K27: 138 | L27: 87 | M27: 147 | N27: 100 | O27: 111 | P27: 224 | Q27: 87 | R27: 178
B28: 原住民 | C28: Indigenous | D28: 92 | E28: 39 | F28: 53 | G28: 1 | H28: 4 | I28: 7 | J28: 5 | K28: 8 | L28: 3 | M28: 15 | N28: 6 | O28: 5 | P28: 22 | Q28: 3 | R28: 13
A29: 宜蘭縣 | B29: 計 | C29: Total | D29: 170 | E29: 63 | F29: 107 | G29: 7 | H29: 5 | I29: 10 | J29: 4 | K29: 9 | L29: 13 | M29: 14 | N29: 16 | O29: 10 | P29: 43 | Q29: 13 | R29: 26
A30: Yilan County | B30: 一般 | C30: General | D30: 158 | E30: 57 | F30: 101 | G30: 7 | H30: 5 | I30: 9 | J30: 4 | K30: 7 | L30: 11 | M30: 13 | N30: 15 | O30: 8 | P30: 42 | Q30: 13 | R30: 24
B31: 原住民 | C31: Indigenous | D31: 12 | E31: 6 | F31: 6 | G31: 0 | H31: 0 | I31: 1 | J31: 0 | K31: 2 | L31: 2 | M31: 1 | N31: 1 | O31: 2 | P31: 1 | Q31: 0 | R31: 2
A32: 新竹縣 | B32: 計 | C32: Total | D32: 307 | E32: 133 | F32: 174 | G32: 15 | H32: 20 | I32: 16 | J32: 15 | K32: 26 | L32: 25 | M32: 32 | N32: 28 | O32: 32 | P32: 48 | Q32: 12 | R32: 38
A33: Hsinchu County | B33: 一般 | C33: General | D33: 255 | E33: 117 | F33: 138 | G33: 14 | H33: 16 | I33: 15 | J33: 13 | K33: 24 | L33: 18 | M33: 27 | N33: 22 | O33: 25 | P33: 38 | Q33: 12 | R33: 31
B34: 原住民 | C34: Indigenous | D34: 52 | E34: 16 | F34: 36 | G34: 1 | H34: 4 | I34: 1 | J34: 2 | K34: 2 | L34: 7 | M34: 5 | N34: 6 | O34: 7 | P34: 10 | Q34: 0 | R34: 7
A35: 苗栗縣 | B35: 計 | C35: Total | D35: 160 | E35: 53 | F35: 107 | G35: 7 | H35: 6 | I35: 10 | J35: 1 | K35: 17 | L35: 9 | M35: 4 | N35: 13 | O35: 10 | P35: 43 | Q35: 5 | R35: 35
A36: Miaoli County | B36: 一般 | C36: General | D36: 142 | E36: 41 | F36: 101 | G36: 6 | H36: 6 | I36: 4 | J36: 1 | K36: 12 | L36: 9 | M36: 4 | N36: 12 | O36: 10 | P36: 39 | Q36: 5 | R36: 34
B37: 原住民 | C37: Indigenous | D37: 18 | E37: 12 | F37: 6 | G37: 1 | H37: 0 | I37: 6 | J37: 0 | K37: 5 | L37: 0 | M37: 0 | N37: 1 | O37: 0 | P37: 4 | Q37: 0 | R37: 1
A38: 彰化縣 | B38: 計 | C38: Total | D38: 577 | E38: 247 | F38: 330 | G38: 39 | H38: 20 | I38: 40 | J38: 28 | K38: 53 | L38: 43 | M38: 37 | N38: 29 | O38: 48 | P38: 110 | Q38: 30 | R38: 100
A39: Changhua County | B39: 一般 | C39: General | D39: 559 | E39: 239 | F39: 320 | G39: 39 | H39: 20 | I39: 40 | J39: 26 | K39: 53 | L39: 43 | M39: 37 | N39: 28 | O39: 41 | P39: 105 | Q39: 29 | R39: 98
B40: 原住民 | C40: Indigenous | D40: 18 | E40: 8 | F40: 10 | G40: 0 | H40: 0 | I40: 0 | J40: 2 | K40: 0 | L40: 0 | M40: 0 | N40: 1 | O40: 7 | P40: 5 | Q40: 1 | R40: 2
A41: 南投縣 | B41: 計 | C41: Total | D41: 299 | E41: 112 | F41: 187 | G41: 13 | H41: 18 | I41: 22 | J41: 27 | K41: 24 | L41: 19 | M41: 23 | N41: 25 | O41: 15 | P41: 53 | Q41: 15 | R41: 45
...

Sheet 2022
A1: 兒童及少年保護-受虐人數 Number of Abused Child and Youth
A2: 單位：人 Unit : Persons
A3: 民國111年, 2022 | D3: =IF(D8=SUM(D11,D14,D17,D20,D23,D26,D29,D32,D35,D38,D41,D44,D47,D50,D53,D56,D59,D62,D65,D68,D71,D74,),"","*") | E3: =IF(E8=SUM(E11,E14,E17,E20,E23,E26,E29,E32,E35,E38,E41,E44,E47,E50,E53,E56,E59,E62,E65,E68,E71,E74,),"","*") | F3: =IF(F8=SUM(F11,F14,F17,F20,F23,F26,F29,F32,F35,F38,F41,F44,F47,F50,F53,F56,F59,F62,F65,F68,F71,F74,),"","*") | G3: =IF(G8=SUM(G11,G14,G17,G20,G23,G26,G29,G32,G35,G38,G41,G44,G47,G50,G53,G56,G59,G62,G65,G68,G71,G74,),"","*") | H3: =IF(H8=SUM(H11,H14,H17,H20,H23,H26,H29,H32,H35,H38,H41,H44,H47,H50,H53,H56,H59,H62,H65,H68,H71,H74,),"","*") | I3: =IF(I8=SUM(I11,I14,I17,I20,I23,I26,I29,I32,I35,I38,I41,I44,I47,I50,I53,I56,I59,I62,I65,I68,I71,I74,),"","*") | J3: =IF(J8=SUM(J11,J14,J17,J20,J23,J26,J29,J32,J35,J38,J41,J44,J47,J50,J53,J56,J59,J62,J65,J68,J71,J74,),"","*") | K3: =IF(K8=SUM(K11,K14,K17,K20,K23,K26,K29,K32,K35,K38,K41,K44,K47,K50,K53,K56,K59,K62,K65,K68,K71,K74,),"","*") | ... R3: =IF(R8=SUM(R11,R14,R17,R20,R23,R26,R29,R32,R35,R38,R41,R44,R47,R50,R53,R56,R59,R62,R65,R68,R71,R74,),"","*")
A4: 區域及特殊族群別 Locality & Ethnos | D4: 受虐兒童少年人數按年齡分(人) By Age
D5: 合計 Total | G5: 0-未滿3歲 Under 3 Years | I5: 3-未滿6歲 3-Under 6 Years | K5: 6-未滿9歲 6-Under 9 Years | M5: 9-未滿12歲 9-Under 12 Years | O5: 12-未滿15歲 12-Under 15 Years | Q5: 15-未滿18歲 15-Under 18 Years
D6: 計 Total | E6: 男 Male | F6: 女 Female | G6: 男 Male | H6: 女 Female | I6: 男 Male | J6: 女 Female | K6: 男 Male | L6: 女 Female | M6: 男 Male | N6: 女 Female | O6: 男 Male | P6: 女 Female | Q6: 男 Male | R6: 女 Female
