Workbook

Sheet 歷年
A1: 兒童及少年保護-施虐者身分別分Number of Persons Who Abuse Child and Youth by Identity
A2: 單位：人 Unit : Persons
A3: 年別 Year | B3: 總計 Total | F3: (養)父母 Parents (Foster Parents) | H3: 手足 Siblings | K3: (外)祖父母 Grandparents | N3: 其他親屬 Other Relatives | Q3: 同居人 Cohabitants | T3: 教師 Teacher | W3: 同學 Schoolmate | Z3: 保母 Babysitter | AC3: 其他 Others | AF3: 不詳 Unknown
B4: 合計 SubTotal | C4: 男 Male | D4: 女 Female | E4: 不詳 Unknown | F4: 男 Male | G4: 女 Female | H4: 男 Male | I4: 女 Female | J4: 不詳 Unknown | K4: 男 Male | L4: 女 Female | M4: 不詳 Unknown | N4: 男 Male | O4: 女 Female | P4: 不詳 Unknown | Q4: 男 Male | R4: 女 Female | S4: 不詳 Unknown | T4: 男 Male | U4: 女 Female | V4: 不詳 Unknown | W4: 男 Male | X4: 女 Female | Y4: 不詳 Unknown | Z4: 男 Male | AA4: 女 Female | AB4: 不詳 Unknown | AC4: 男 Male | AD4: 女 Female | AE4: 不詳 Unknown | AF4: 男 Male | AG4: 女 Female | AH4: 不詳 Unknown
A6: 108年, 2019 | B6: ='2019'!D7 -> 10192 | C6: ='2019'!E7 -> 6900 | D6: ='2019'!F7 -> 3095 | E6: ='2019'!G7 -> 197 | F6: ='2019'!H7 -> 2862 | G6: ='2019'!I7 -> 2081 | H6: ='2019'!J7 -> 183 | I6: ='2019'!K7 -> 24 | ... AH6: ='2019'!AJ7 -> 133
A7: 109年, 2020 | B7: ='2020'!D7 -> 11746 | C7: ='2020'!E7 -> 7944 | D7: ='2020'!F7 -> 3614 | E7: ='2020'!G7 -> 188 | F7: ='2020'!H7 -> 3206 | G7: ='2020'!I7 -> 2325 | H7: ='2020'!J7 -> 172 | I7: ='2020'!K7 -> 34 | ... AH7: ='2020'!AJ7 -> 149
A8: 110年, 2021 | B8: ='2021'!D7 -> 10809 | C8: ='2021'!E7 -> 7156 | D8: ='2021'!F7 -> 3553 | E8: ='2021'!G7 -> 100 | F8: ='2021'!H7 -> 3220 | G8: ='2021'!I7 -> 2571 | H8: ='2021'!J7 -> 237 | I8: ='2021'!K7 -> 42 | ... AH8: ='2021'!AJ7 -> 97
A9: 111年, 2022 | B9: ='2022'!D7 -> 11350 | C9: ='2022'!E7 -> 7490 | D9: ='2022'!F7 -> 3768 | E9: ='2022'!G7 -> 92 | F9: ='2022'!H7 -> 3346 | G9: ='2022'!I7 -> 2602 | H9: ='2022'!J7 -> 234 | I9: ='2022'!K7 -> 53 | ... AH9: ='2022'!AJ7 -> 89
A10: 112年, 2023 | B10: ='2023'!D7 -> 12129 | C10: ='2023'!E7 -> 7988 | D10: ='2023'!F7 -> 4039 | E10: ='2023'!G7 -> 102 | F10: ='2023'!H7 -> 3760 | G10: ='2023'!I7 -> 2899 | H10: ='2023'!J7 -> 264 | I10: ='2023'!K7 -> 70 | ... AH10: ='2023'!AJ7 -> 100
A11: 113年, 2024 | B11: ='2024'!D7 -> 10794 | C11: ='2024'!E7 -> 7117 | D11: ='2024'!F7 -> 3606 | E11: ='2024'!G7 -> 71 | F11: ='2024'!H7 -> 3473 | G11: ='2024'!I7 -> 2748 | H11: ='2024'!J7 -> 235 | I11: ='2024'!K7 -> 59 | ... AH11: ='2024'!AJ7 -> 65
A12: 上半年, Jan.-June | B12: 5731 | C12: 3896 | D12: 1804 | E12: 31 | F12: 1868 | G12: 1365 | H12: 125 | I12: 32 | J12: 0 | K12: 81 | L12: 99 | M12: 0 | N12: 173 | O12: 49 | P12: 0 | Q12: 177 | R12: 36 | S12: 0 | BD12: 48 | BE12: 4 | BF12: 0 | BG12: 142 | BH12: 32 | BI12: 0 | BJ12: 0 | BK12: 9 | BL12: 0 | BM12: 969 | BN12: 137 | BO12: 3 | BP12: 313 | BQ12: 41 | BR12: 28
A13: 下半年, July-Dec. | B13: 5063 | C13: 3221 | D13: 1802 | E13: 40 | F13: 1605 | G13: 1383 | H13: 110 | I13: 27 | J13: 0 | K13: 64 | L13: 92 | M13: 0 | N13: 135 | O13: 44 | P13: 0 | Q13: 130 | R13: 30 | S13: 1 | BD13: 62 | BE13: 1 | BF13: 0 | BG13: 114 | BH13: 20 | BI13: 0 | BJ13: 1 | BK13: 4 | BL13: 0 | BM13: 727 | BN13: 111 | BO13: 2 | BP13: 273 | BQ13: 90 | BR13: 37
A15: 年別 Year | B15: 總計 Total | F15: (養)父母 Parents (Foster Parents) | H15: 手足 Siblings | K15: (外)祖父母 Grandparents | N15: 其他親屬 Other Relatives | Q15: 父或母之同居人 Cohabitants | T15: (前)親密關係伴侶 Intimate Partner | W15: 托育機構人員 Childcare Institution Staff | Z15: 居家式托育人員 Home-based Childcare Staff | AC15: 補習班或兒童課後 照顧服務中心人員 After-school Care Service Center Staff | AF15: 學校教職員工 School Faculty and Staff | AI15: 安置單位人員 Resettlement Agency Staff | AL15: 職場上司同事 Boss/Colleagues | AO15: 朋友/鄰居 Friends/Neighbors | AR15: 網友 Netizens | AU15: 陌生人 Stranger | AX15: 其他 Others | BA15: 不詳 Unknown
B16: 合計 SubTotal | C16: 男 Male | D16: 女 Female | E16: 不詳 Unknown | F16: 男 Male | G16: 女 Female | H16: 男 Male | I16: 女 Female | J16: 不詳 Unknown | K16: 男 Male | L16: 女 Female | M16: 不詳 Unknown | N16: 男 Male | O16: 女 Female | P16: 不詳 Unknown | Q16: 男 Male | R16: 女 Female | S16: 不詳 Unknown | T16: 男 Male | U16: 女 Female | V16: 不詳 Unknown | W16: 男 Male | X16: 女 Female | Y16: 不詳 Unknown | Z16: 男 Male | AA16: 女 Female | AB16: 不詳 Unknown | AC16: 男 Male | AD16: 女 Female | AE16: 不詳 Unknown | AF16: 男 Male | AG16: 女 Female | AH16: 不詳 Unknown | AI16: 男 Male | AJ16: 女 Female | AK16: 不詳 Unknown | AL16: 男 Male | AM16: 女 Female | AN16: 不詳 Unknown | AO16: 男 Male | AP16: 女 Female | AQ16: 不詳 Unknown | AR16: 男 Male | AS16: 女 Female | AT16: 不詳 Unknown | AU16: 男 Male | AV16: 女 Female | AW16: 不詳 Unknown | AX16: 男 Male | AY16: 女 Female | AZ16: 不詳 Unknown | BA16: 男 Male | BB16: 女 Female | BC16: 不詳 Unknown
A18: 114年, 2025 | B18: ='2025'!D7 -> 9781 | C18: ='2025'!E7 -> 6341 | D18: ='2025'!F7 -> 3308 | E18: ='2025'!G7 -> 132 | F18: ='2025'!H7 -> 3070 | G18: ='2025'!I7 -> 2367 | H18: ='2025'!J7 -> 202 | I18: ='2025'!K7 -> 43 | ... BC18: ='2025'!BE7 -> 131
A19: 上半年, Jan.-June | B19: ='Jan.-June, 2025'!D7 -> 5307 | C19: ='Jan.-June, 2025'!E7 -> 3489 | D19: ='Jan.-June, 2025'!F7 -> 1730 | E19: ='Jan.-June, 2025'!G7 -> 88 | F19: ='Jan.-June, 2025'!H7 -> 1755 | G19: ='Jan.-June, 2025'!I7 -> 1288 | H19: ='Jan.-June, 2025'!J7 -> 125 | I19: ='Jan.-June, 2025'!K7 -> 28 | ... BC19: ='Jan.-June, 2025'!BE7 -> 88
A20: 下半年, July-Dec. | B20: ='July-Dec., 2025'!D7 -> 4474 | C20: ='July-Dec., 2025'!E7 -> 2852 | D20: ='July-Dec., 2025'!F7 -> 1578 | E20: ='July-Dec., 2025'!G7 -> 44 | F20: ='July-Dec., 2025'!H7 -> 1315 | G20: ='July-Dec., 2025'!I7 -> 1079 | H20: ='July-Dec., 2025'!J7 -> 77 | I20: ='July-Dec., 2025'!K7 -> 15 | ... BC20: ='July-Dec., 2025'!BE7 -> 43
A21: 資料來源：各直轄市、縣市政府。
A22: Source: County and Government.
A23: 更新日期：2026/03/31
B24: =IF(B18=SUM(B19:B20),"","*") | C24: =IF(C18=SUM(C19:C20),"","*") | D24: =IF(D18=SUM(D19:D20),"","*") | E24: =IF(E18=SUM(E19:E20),"","*") | F24: =IF(F18=SUM(F19:F20),"","*") | G24: =IF(G18=SUM(G19:G20),"","*") | H24: =IF(H18=SUM(H19:H20),"","*") | I24: =IF(I18=SUM(I19:I20),"","*") | ... BC24: =IF(BC18=SUM(BC19:BC20),"","*")

Sheet 2025
A1: 兒童及少年保護-施虐者身分別分Number of Persons Who Abuse Child and Youth by Identity
A2: 單位：人 Unit : Persons
A3: 民國114年, 2025
A4: 區域及特殊族群別 Locality & Ethnos | D4: 總計 Total | H4: (養)父母 Parents (Foster Parents) | J4: 手足 Siblings | M4: (外)祖父母 Grandparents | P4: 其他親屬 Other Relatives | S4: 父或母之同居人 Cohabitants | V4: (前)親密關係伴侶 Intimate Partner | Y4: 托育機構人員 Childcare Institution Staff | AB4: 居家式托育人員 Home-based Childcare Staff | AE4: 補習班或兒童課後 照顧服務中心人員 After-school Care Service Center Staff | AH4: 學校教職員工 School Faculty and Staff | AK4: 安置單位人員 Resettlement Agency Staff | AN4: 職場上司同事 Boss/Colleagues | AQ4: 朋友/鄰居 Friends/Neighbors | AT4: 網友 Netizens | AW4: 陌生人 Stranger | AZ4: 其他 Others | BC4: 不詳 Unknown
D5: 合計 SubTotal | E5: 男 Male | F5: 女 Female | G5: 不詳 Unknown | H5: 男 Male | I5: 女 Female | J5: 男 Male | K5: 女 Female | L5: 不詳 Unknown | M5: 男 Male | N5: 女 Female | O5: 不詳 Unknown | P5: 男 Male | Q5: 女 Female | R5: 不詳 Unknown | S5: 男 Male | T5: 女 Female | U5: 不詳 Unknown | V5: 男 Male | W5: 女 Female | X5: 不詳 Unknown | Y5: 男 Male | Z5: 女 Female | AA5: 不詳 Unknown | AB5: 男 Male | AC5: 女 Female | AD5: 不詳 Unknown | AE5: 男 Male | AF5: 女 Female | AG5: 不詳 Unknown | AH5: 男 Male | AI5: 女 Female | AJ5: 不詳 Unknown | AK5: 男 Male | AL5: 女 Female | AM5: 不詳 Unknown | AN5: 男 Male | AO5: 女 Female | AP5: 不詳 Unknown | AQ5: 男 Male | AR5: 女 Female | AS5: 不詳 Unknown | AT5: 男 Male | AU5: 女 Female | AV5: 不詳 Unknown | AW5: 男 Male | AX5: 女 Female | AY5: 不詳 Unknown | AZ5: 男 Male | BA5: 女 Female | BB5: 不詳 Unknown | BC5: 男 Male | BD5: 女 Female | BE5: 不詳 Unknown
A7: 總計 | B7: 計 | C7: Total | D7: 9781 | E7: 6341 | F7: 3308 | G7: 132 | H7: 3070 | I7: 2367 | J7: 202 | K7: 43 | L7: 0 | M7: 140 | N7: 179 | O7: 0 | P7: 266 | Q7: 71 | R7: 0 | S7: 261 | T7: 79 | U7: 1 | V7: 102 | W7: 6 | X7: 0 | Y7: 1 | Z7: 5 | AA7: 0 | AB7: 5 | AC7: 9 | AD7: 0 | AE7: 17 | AF7: 1 | AG7: 0 | AH7: 52 | AI7: 9 | AJ7: 0 | AK7: 27 | AL7: 5 | AM7: 0 | AN7: 3 | AO7: 0 | AP7: 0 | AQ7: 454 | AR7: 40 | AS7: 0 | AT7: 28 | AU7: 0 | AV7: 0 | AW7: 101 | AX7: 5 | AY7: 0 | AZ7: 922 | BA7: 130 | BB7: 0 | BC7: 690 | BD7: 359 | BE7: 131
A8: Total | B8: 一般 | C8: General | D8: 9136 | E8: 5947 | F8: 3057 | G8: 132 | H8: 2884 | I8: 2169 | J8: 182 | K8: 36 | L8: 0 | M8: 135 | N8: 175 | O8: 0 | P8: 236 | Q8: 64 | R8: 0 | S8: 225 | T8: 78 | U8: 1 | V8: 97 | W8: 6 | X8: 0 | Y8: 1 | Z8: 4 | AA8: 0 | AB8: 5 | AC8: 9 | AD8: 0 | AE8: 17 | AF8: 1 | AG8: 0 | AH8: 51 | AI8: 9 | AJ8: 0 | AK8: 26 | AL8: 5 | AM8: 0 | AN8: 3 | AO8: 0 | AP8: 0 | AQ8: 434 | AR8: 39 | AS8: 0 | AT8: 28 | AU8: 0 | AV8: 0 | AW8: 96 | AX8: 5 | AY8: 0 | AZ8: 875 | BA8: 115 | BB8: 0 | BC8: 652 | BD8: 342 | BE8: 131
B9: 原住民 | C9: Indigenous | D9: 645 | E9: 394 | F9: 251 | G9: 0 | H9: 186 | I9: 198 | J9: 20 | K9: 7 | L9: 0 | M9: 5 | N9: 4 | O9: 0 | P9: 30 | Q9: 7 | R9: 0 | S9: 36 | T9: 1 | U9: 0 | V9: 5 | W9: 0 | X9: 0 | Y9: 0 | Z9: 1 | AA9: 0 | AB9: 0 | AC9: 0 | AD9: 0 | AE9: 0 | AF9: 0 | AG9: 0 | AH9: 1 | AI9: 0 | AJ9: 0 | AK9: 1 | AL9: 0 | AM9: 0 | AN9: 0 | AO9: 0 | AP9: 0 | AQ9: 20 | AR9: 1 | AS9: 0 | AT9: 0 | AU9: 0 | AV9: 0 | AW9: 5 | AX9: 0 | AY9: 0 | AZ9: 47 | BA9: 15 | BB9: 0 | BC9: 38 | BD9: 17 | BE9: 0
A10: 新北市 | B10: 計 | C10: Total | D10: 2119 | E10: 1438 | F10: 651 | G10: 30 | H10: 635 | I10: 459 | J10: 43 | K10: 10 | L10: 0 | M10: 34 | N10: 33 | O10: 0 | P10: 55 | Q10: 10 | R10: 0 | S10: 41 | T10: 11 | U10: 0 | V10: 0 | W10: 0 | X10: 0 | Y10: 0 | Z10: 2 | AA10: 0 | AB10: 0 | AC10: 4 | AD10: 0 | AE10: 1 | AF10: 0 | AG10: 0 | AH10: 17 | AI10: 0 | AJ10: 0 | AK10: 4 | AL10: 0 | AM10: 0 | AN10: 0 | AO10: 0 | AP10: 0 | AQ10: 210 | AR10: 8 | AS10: 0 | AT10: 0 | AU10: 0 | AV10: 0 | AW10: 32 | AX10: 2 | AY10: 0 | AZ10: 168 | BA10: 16 | BB10: 0 | BC10: 198 | BD10: 96 | BE10: 30
A11: New Taipei City | B11: 一般 | C11: General | D11: 2024 | E11: 1387 | F11: 607 | G11: 30 | H11: 614 | I11: 428 | J11: 40 | K11: 8 | L11: 0 | M11: 32 | N11: 32 | O11: 0 | P11: 49 | Q11: 9 | R11: 0 | S11: 34 | T11: 11 | U11: 0 | V11: 0 | W11: 0 | X11: 0 | Y11: 0 | Z11: 1 | AA11: 0 | AB11: 0 | AC11: 4 | AD11: 0 | AE11: 1 | AF11: 0 | AG11: 0 | AH11: 17 | AI11: 0 | AJ11: 0 | AK11: 4 | AL11: 0 | AM11: 0 | AN11: 0 | AO11: 0 | AP11: 0 | AQ11: 208 | AR11: 8 | AS11: 0 | AT11: 0 | AU11: 0 | AV11: 0 | AW11: 31 | AX11: 2 | AY11: 0 | AZ11: 164 | BA11: 13 | BB11: 0 | BC11: 193 | BD11: 91 | BE11: 30
B12: 原住民 | C12: Indigenous | D12: 95 | E12: 51 | F12: 44 | G12: 0 | H12: 21 | I12: 31 | J12: 3 | K12: 2 | L12: 0 | M12: 2 | N12: 1 | O12: 0 | P12: 6 | Q12: 1 | R12: 0 | S12: 7 | T12: 0 | U12: 0 | V12: 0 | W12: 0 | X12: 0 | Y12: 0 | Z12: 1 | AA12: 0 | AB12: 0 | AC12: 0 | AD12: 0 | AE12: 0 | AF12: 0 | AG12: 0 | AH12: 0 | AI12: 0 | AJ12: 0 | AK12: 0 | AL12: 0 | AM12: 0 | AN12: 0 | AO12: 0 | AP12: 0 | AQ12: 2 | AR12: 0 | AS12: 0 | AT12: 0 | AU12: 0 | AV12: 0 | AW12: 1 | AX12: 0 | AY12: 0 | AZ12: 4 | BA12: 3 | BB12: 0 | BC12: 5 | BD12: 5 | BE12: 0
A13: 臺北市 | B13: 計 | C13: Total | D13: 907 | E13: 546 | F13: 324 | G13: 37 | H13: 274 | I13: 227 | J13: 14 | K13: 4 | L13: 0 | M13: 8 | N13: 14 | O13: 0 | P13: 10 | Q13: 5 | R13: 0 | S13: 25 | T13: 4 | U13: 0 | V13: 0 | W13: 0 | X13: 0 | Y13: 1 | Z13: 0 | AA13: 0 | AB13: 0 | AC13: 0 | AD13: 0 | AE13: 4 | AF13: 0 | AG13: 0 | AH13: 3 | AI13: 0 | AJ13: 0 | AK13: 1 | AL13: 0 | AM13: 0 | AN13: 0 | AO13: 0 | AP13: 0 | AQ13: 32 | AR13: 4 | AS13: 0 | AT13: 0 | AU13: 0 | AV13: 0 | AW13: 11 | AX13: 0 | AY13: 0 | AZ13: 116 | BA13: 20 | BB13: 0 | BC13: 47 | BD13: 46 | BE13: 37
A14: Taipei City | B14: 一般 | C14: General | D14: 895 | E14: 543 | F14: 315 | G14: 37 | H14: 272 | I14: 219 | J14: 14 | K14: 4 | L14: 0 | M14: 8 | N14: 14 | O14: 0 | P14: 10 | Q14: 5 | R14: 0 | S14: 25 | T14: 4 | U14: 0 | V14: 0 | W14: 0 | X14: 0 | Y14: 1 | Z14: 0 | AA14: 0 | AB14: 0 | AC14: 0 | AD14: 0 | AE14: 4 | AF14: 0 | AG14: 0 | AH14: 3 | AI14: 0 | AJ14: 0 | AK14: 1 | AL14: 0 | AM14: 0 | AN14: 0 | AO14: 0 | AP14: 0 | AQ14: 31 | AR14: 4 | AS14: 0 | AT14: 0 | AU14: 0 | AV14: 0 | AW14: 11 | AX14: 0 | AY14: 0 | AZ14: 116 | BA14: 20 | BB14: 0 | BC14: 47 | BD14: 45 | BE14: 37
B15: 原住民 | C15: Indigenous | D15: 12 | E15: 3 | F15: 9 | G15: 0 | H15: 2 | I15: 8 | J15: 0 | K15: 0 | L15: 0 | M15: 0 | N15: 0 | O15: 0 | P15: 0 | Q15: 0 | R15: 0 | S15: 0 | T15: 0 | U15: 0 | V15: 0 | W15: 0 | X15: 0 | Y15: 0 | Z15: 0 | AA15: 0 | AB15: 0 | AC15: 0 | AD15: 0 | AE15: 0 | AF15: 0 | AG15: 0 | AH15: 0 | AI15: 0 | AJ15: 0 | AK15: 0 | AL15: 0 | AM15: 0 | AN15: 0 | AO15: 0 | AP15: 0 | AQ15: 1 | AR15: 0 | AS15: 0 | AT15: 0 | AU15: 0 | AV15: 0 | AW15: 0 | AX15: 0 | AY15: 0 | AZ15: 0 | BA15: 0 | BB15: 0 | BC15: 0 | BD15: 1 | BE15: 0
A16: 桃園市 | B16: 計 | C16: Total | D16: 790 | E16: 563 | F16: 216 | G16: 11 | H16: 270 | I16: 169 | J16: 8 | K16: 3 | L16: 0 | M16: 12 | N16: 11 | O16: 0 | P16: 23 | Q16: 5 | R16: 0 | S16: 15 | T16: 5 | U16: 0 | V16: 3 | W16: 0 | X16: 0 | Y16: 0 | Z16: 0 | AA16: 0 | AB16: 0 | AC16: 3 | AD16: 0 | AE16: 2 | AF16: 0 | AG16: 0 | AH16: 11 | AI16: 1 | AJ16: 0 | AK16: 2 | AL16: 0 | AM16: 0 | AN16: 0 | AO16: 0 | AP16: 0 | AQ16: 29 | AR16: 5 | AS16: 0 | AT16: 2 | AU16: 0 | AV16: 0 | AW16: 8 | AX16: 1 | AY16: 0 | AZ16: 134 | BA16: 11 | BB16: 0 | BC16: 44 | BD16: 2 | BE16: 11
A17: Taoyuan City | B17: 一般 | C17: General | D17: 709 | E17: 518 | F17: 180 | G17: 11 | H17: 244 | I17: 138 | J17: 7 | K17: 2 | L17: 0 | M17: 11 | N17: 11 | O17: 0 | P17: 23 | Q17: 4 | R17: 0 | S17: 11 | T17: 5 | U17: 0 | V17: 0 | W17: 0 | X17: 0 | Y17: 0 | Z17: 0 | AA17: 0 | AB17: 0 | AC17: 3 | AD17: 0 | AE17: 2 | AF17: 0 | AG17: 0 | AH17: 11 | AI17: 1 | AJ17: 0 | AK17: 2 | AL17: 0 | AM17: 0 | AN17: 0 | AO17: 0 | AP17: 0 | AQ17: 26 | AR17: 4 | AS17: 0 | AT17: 2 | AU17: 0 | AV17: 0 | AW17: 7 | AX17: 1 | AY17: 0 | AZ17: 129 | BA17: 9 | BB17: 0 | BC17: 43 | BD17: 2 | BE17: 11
B18: 原住民 | C18: Indigenous | D18: 81 | E18: 45 | F18: 36 | G18: 0 | H18: 26 | I18: 31 | J18: 1 | K18: 1 | L18: 0 | M18: 1 | N18: 0 | O18: 0 | P18: 0 | Q18: 1 | R18: 0 | S18: 4 | T18: 0 | U18: 0 | V18: 3 | W18: 0 | X18: 0 | Y18: 0 | Z18: 0 | AA18: 0 | AB18: 0 | AC18: 0 | AD18: 0 | AE18: 0 | AF18: 0 | AG18: 0 | AH18: 0 | AI18: 0 | AJ18: 0 | AK18: 0 | AL18: 0 | AM18: 0 | AN18: 0 | AO18: 0 | AP18: 0 | AQ18: 3 | AR18: 1 | AS18: 0 | AT18: 0 | AU18: 0 | AV18: 0 | AW18: 1 | AX18: 0 | AY18: 0 | AZ18: 5 | BA18: 2 | BB18: 0 | BC18: 1 | BD18: 0 | BE18: 0
A19: 臺中市 | B19: 計 | C19: Total | D19: 1295 | E19: 831 | F19: 443 | G19: 21 | H19: 472 | I19: 283 | J19: 27 | K19: 7 | L19: 0 | M19: 22 | N19: 27 | O19: 0 | P19: 27 | Q19: 11 | R19: 0 | S19: 29 | T19: 13 | U19: 0 | V19: 0 | W19: 0 | X19: 0 | Y19: 0 | Z19: 0 | AA19: 0 | AB19: 0 | AC19: 0 | AD19: 0 | AE19: 1 | AF19: 0 | AG19: 0 | AH19: 4 | AI19: 0 | AJ19: 0 | AK19: 8 | AL19: 0 | AM19: 0 | AN19: 0 | AO19: 0 | AP19: 0 | AQ19: 47 | AR19: 2 | AS19: 0 | AT19: 1 | AU19: 0 | AV19: 0 | AW19: 8 | AX19: 1 | AY19: 0 | AZ19: 133 | BA19: 8 | BB19: 0 | BC19: 52 | BD19: 91 | BE19: 21
A20: Taichung City | B20: 一般 | C20: General | D20: 1240 | E20: 794 | F20: 425 | G20: 21 | H20: 447 | I20: 269 | J20: 24 | K20: 6 | L20: 0 | M20: 21 | N20: 24 | O20: 0 | P20: 26 | Q20: 11 | R20: 0 | S20: 27 | T20: 13 | U20: 0 | V20: 0 | W20: 0 | X20: 0 | Y20: 0 | Z20: 0 | AA20: 0 | AB20: 0 | AC20: 0 | AD20: 0 | AE20: 1 | AF20: 0 | AG20: 0 | AH20: 3 | AI20: 0 | AJ20: 0 | AK20: 8 | AL20: 0 | AM20: 0 | AN20: 0 | AO20: 0 | AP20: 0 | AQ20: 46 | AR20: 2 | AS20: 0 | AT20: 1 | AU20: 0 | AV20: 0 | AW20: 7 | AX20: 1 | AY20: 0 | AZ20: 132 | BA20: 8 | BB20: 0 | BC20: 51 | BD20: 91 | BE20: 21
B21: 原住民 | C21: Indigenous | D21: 55 | E21: 37 | F21: 18 | G21: 0 | H21: 25 | I21: 14 | J21: 3 | K21: 1 | L21: 0 | M21: 1 | N21: 3 | O21: 0 | P21: 1 | Q21: 0 | R21: 0 | S21: 2 | T21: 0 | U21: 0 | V21: 0 | W21: 0 | X21: 0 | Y21: 0 | Z21: 0 | AA21: 0 | AB21: 0 | AC21: 0 | AD21: 0 | AE21: 0 | AF21: 0 | AG21: 0 | AH21: 1 | AI21: 0 | AJ21: 0 | AK21: 0 | AL21: 0 | AM21: 0 | AN21: 0 | AO21: 0 | AP21: 0 | AQ21: 1 | AR21: 0 | AS21: 0 | AT21: 0 | AU21: 0 | AV21: 0 | AW21: 1 | AX21: 0 | AY21: 0 | AZ21: 1 | BA21: 0 | BB21: 0 | BC21: 1 | BD21: 0 | BE21: 0
A22: 臺南市 | B22: 計 | C22: Total | D22: 543 | E22: 340 | F22: 201 | G22: 2 | H22: 174 | I22: 157 | J22: 26 | K22: 2 | L22: 0 | M22: 7 | N22: 9 | O22: 0 | P22: 9 | Q22: 7 | R22: 0 | S22: 24 | T22: 15 | U22: 0 | V22: 0 | W22: 0 | X22: 0 | Y22: 0 | Z22: 0 | AA22: 0 | AB22: 0 | AC22: 0 | AD22: 0 | AE22: 4 | AF22: 0 | AG22: 0 | AH22: 3 | AI22: 0 | AJ22: 0 | AK22: 2 | AL22: 1 | AM22: 0 | AN22: 0 | AO22: 0 | AP22: 0 | AQ22: 14 | AR22: 3 | AS22: 0 | AT22: 0 | AU22: 0 | AV22: 0 | AW22: 9 | AX22: 0 | AY22: 0 | AZ22: 61 | BA22: 4 | BB22: 0 | BC22: 7 | BD22: 3 | BE22: 2
A23: Tainan City | B23: 一般 | C23: General | D23: 529 | E23: 334 | F23: 193 | G23: 2 | H23: 171 | I23: 150 | J23: 24 | K23: 1 | L23: 0 | M23: 7 | N23: 9 | O23: 0 | P23: 9 | Q23: 7 | R23: 0 | S23: 24 | T23: 15 | U23: 0 | V23: 0 | W23: 0 | X23: 0 | Y23: 0 | Z23: 0 | AA23: 0 | AB23: 0 | AC23: 0 | AD23: 0 | AE23: 4 | AF23: 0 | AG23: 0 | AH23: 3 | AI23: 0 | AJ23: 0 | AK23: 2 | AL23: 1 | AM23: 0 | AN23: 0 | AO23: 0 | AP23: 0 | AQ23: 14 | AR23: 3 | AS23: 0 | AT23: 0 | AU23: 0 | AV23: 0 | AW23: 9 | AX23: 0 | AY23: 0 | AZ23: 61 | BA23: 4 | BB23: 0 | BC23: 6 | BD23: 3 | BE23: 2
B24: 原住民 | C24: Indigenous | D24: 14 | E24: 6 | F24: 8 | G24: 0 | H24: 3 | I24: 7 | J24: 2 | K24: 1 | L24: 0 | M24: 0 | N24: 0 | O24: 0 | P24: 0 | Q24: 0 | R24: 0 | S24: 0 | T24: 0 | U24: 0 | V24: 0 | W24: 0 | X24: 0 | Y24: 0 | Z24: 0 | AA24: 0 | AB24: 0 | AC24: 0 | AD24: 0 | AE24: 0 | AF24: 0 | AG24: 0 | AH24: 0 | AI24: 0 | AJ24: 0 | AK24: 0 | AL24: 0 | AM24: 0 | AN24: 0 | AO24: 0 | AP24: 0 | AQ24: 0 | AR24: 0 | AS24: 0 | AT24: 0 | AU24: 0 | AV24: 0 | AW24: 0 | AX24: 0 | AY24: 0 | AZ24: 0 | BA24: 0 | BB24: 0 | BC24: 1 | BD24: 0 | BE24: 0
A25: 高雄市 | B25: 計 | C25: Total | D25: 1297 | E25: 788 | F25: 496 | G25: 13 | H25: 395 | I25: 326 | J25: 20 | K25: 4 | L25: 0 | M25: 17 | N25: 42 | O25: 0 | P25: 20 | Q25: 10 | R25: 0 | S25: 42 | T25: 6 | U25: 1 | V25: 73 | W25: 5 | X25: 0 | Y25: 0 | Z25: 3 | AA25: 0 | AB25: 1 | AC25: 0 | AD25: 0 | AE25: 1 | AF25: 0 | AG25: 0 | AH25: 3 | AI25: 1 | AJ25: 0 | AK25: 1 | AL25: 0 | AM25: 0 | AN25: 2 | AO25: 0 | AP25: 0 | AQ25: 41 | AR25: 4 | AS25: 0 | AT25: 18 | AU25: 0 | AV25: 0 | AW25: 12 | AX25: 0 | AY25: 0 | AZ25: 20 | BA25: 29 | BB25: 0 | BC25: 122 | BD25: 66 | BE25: 12
A26: Kaohsiung City | B26: 一般 | C26: General | D26: 1253 | E26: 768 | F26: 472 | G26: 13 | H26: 383 | I26: 307 | J26: 19 | K26: 4 | L26: 0 | M26: 17 | N26: 42 | O26: 0 | P26: 19 | Q26: 8 | R26: 0 | S26: 42 | T26: 6 | U26: 1 | V26: 71 | W26: 5 | X26: 0 | Y26: 0 | Z26: 3 | AA26: 0 | AB26: 1 | AC26: 0 | AD26: 0 | AE26: 1 | AF26: 0 | AG26: 0 | AH26: 3 | AI26: 1 | AJ26: 0 | AK26: 1 | AL26: 0 | AM26: 0 | AN26: 2 | AO26: 0 | AP26: 0 | AQ26: 40 | AR26: 4 | AS26: 0 | AT26: 18 | AU26: 0 | AV26: 0 | AW26: 12 | AX26: 0 | AY26: 0 | AZ26: 20 | BA26: 28 | BB26: 0 | BC26: 119 | BD26: 64 | BE26: 12
B27: 原住民 | C27: Indigenous | D27: 44 | E27: 20 | F27: 24 | G27: 0 | H27: 12 | I27: 19 | J27: 1 | K27: 0 | L27: 0 | M27: 0 | N27: 0 | O27: 0 | P27: 1 | Q27: 2 | R27: 0 | S27: 0 | T27: 0 | U27: 0 | V27: 2 | W27: 0 | X27: 0 | Y27: 0 | Z27: 0 | AA27: 0 | AB27: 0 | AC27: 0 | AD27: 0 | AE27: 0 | AF27: 0 | AG27: 0 | AH27: 0 | AI27: 0 | AJ27: 0 | AK27: 0 | AL27: 0 | AM27: 0 | AN27: 0 | AO27: 0 | AP27: 0 | AQ27: 1 | AR27: 0 | AS27: 0 | AT27: 0 | AU27: 0 | AV27: 0 | AW27: 0 | AX27: 0 | AY27: 0 | AZ27: 0 | BA27: 1 | BB27: 0 | BC27: 3 | BD27: 2 | BE27: 0
A28: 宜蘭縣 | B28: 計 | C28: Total | D28: 60 | E28: 39 | F28: 21 | G28: 0 | H28: 20 | I28: 15 | J28: 1 | K28: 1 | L28: 0 | M28: 1 | N28: 1 | O28: 0 | P28: 3 | Q28: 1 | R28: 0 | S28: 5 | T28: 2 | U28: 0 | V28: 0 | W28: 0 | X28: 0 | Y28: 0 | Z28: 0 | AA28: 0 | AB28: 0 | AC28: 0 | AD28: 0 | AE28: 0 | AF28: 0 | AG28: 0 | AH28: 1 | AI28: 0 | AJ28: 0 | AK28: 0 | AL28: 0 | AM28: 0 | AN28: 0 | AO28: 0 | AP28: 0 | AQ28: 0 | AR28: 0 | AS28: 0 | AT28: 0 | AU28: 0 | AV28: 0 | AW28: 0 | AX28: 0 | AY28: 0 | AZ28: 8 | BA28: 1 | BB28: 0 | BC28: 0 | BD28: 0 | BE28: 0
A29: Yilan County | B29: 一般 | C29: General | D29: 54 | E29: 34 | F29: 20 | G29: 0 | H29: 20 | I29: 15 | J29: 1 | K29: 1 | L29: 0 | M29: 1 | N29: 1 | O29: 0 | P29: 2 | Q29: 1 | R29: 0 | S29: 4 | T29: 2 | U29: 0 | V29: 0 | W29: 0 | X29: 0 | Y29: 0 | Z29: 0 | AA29: 0 | AB29: 0 | AC29: 0 | AD29: 0 | AE29: 0 | AF29: 0 | AG29: 0 | AH29: 1 | AI29: 0 | AJ29: 0 | AK29: 0 | AL29: 0 | AM29: 0 | AN29: 0 | AO29: 0 | AP29: 0 | AQ29: 0 | AR29: 0 | AS29: 0 | AT29: 0 | AU29: 0 | AV29: 0 | AW29: 0 | AX29: 0 | AY29: 0 | AZ29: 5 | BA29: 0 | BB29: 0 | BC29: 0 | BD29: 0 | BE29: 0
B30: 原住民 | C30: Indigenous | D30: 6 | E30: 5 | F30: 1 | G30: 0 | H30: 0 | I30: 0 | J30: 0 | K30: 0 | L30: 0 | M30: 0 | N30: 0 | O30: 0 | P30: 1 | Q30: 0 | R30: 0 | S30: 1 | T30: 0 | U30: 0 | V30: 0 | W30: 0 | X30: 0 | Y30: 0 | Z30: 0 | AA30: 0 | AB30: 0 | AC30: 0 | AD30: 0 | AE30: 0 | AF30: 0 | AG30: 0 | AH30: 0 | AI30: 0 | AJ30: 0 | AK30: 0 | AL30: 0 | AM30: 0 | AN30: 0 | AO30: 0 | AP30: 0 | AQ30: 0 | AR30: 0 | AS30: 0 | AT30: 0 | AU30: 0 | AV30: 0 | AW30: 0 | AX30: 0 | AY30: 0 | AZ30: 3 | BA30: 1 | BB30: 0 | BC30: 0 | BD30: 0 | BE30: 0
A31: 新竹縣 | B31: 計 | C31: Total | D31: 336 | E31: 206 | F31: 128 | G31: 2 | H31: 118 | I31: 114 | J31: 10 | K31: 0 | L31: 0 | M31: 6 | N31: 2 | O31: 0 | P31: 4 | Q31: 2 | R31: 0 | S31: 16 | T31: 0 | U31: 0 | V31: 0 | W31: 0 | X31: 0 | Y31: 0 | Z31: 0 | AA31: 0 | AB31: 0 | AC31: 0 | AD31: 0 | AE31: 0 | AF31: 0 | AG31: 0 | AH31: 0 | AI31: 0 | AJ31: 0 | AK31: 4 | AL31: 2 | AM31: 0 | AN31: 0 | AO31: 0 | AP31: 0 | AQ31: 2 | AR31: 0 | AS31: 0 | AT31: 0 | AU31: 0 | AV31: 0 | AW31: 6 | AX31: 0 | AY31: 0 | AZ31: 30 | BA31: 8 | BB31: 0 | BC31: 10 | BD31: 0 | BE31: 2
A32: Hsinchu County | B32: 一般 | C32: General | D32: 282 | E32: 178 | F32: 102 | G32: 2 | H32: 108 | I32: 90 | J32: 8 | K32: 0 | L32: 0 | M32: 6 | N32: 2 | O32: 0 | P32: 4 | Q32: 2 | R32: 0 | S32: 6 | T32: 0 | U32: 0 | V32: 0 | W32: 0 | X32: 0 | Y32: 0 | Z32: 0 | AA32: 0 | AB32: 0 | AC32: 0 | AD32: 0 | AE32: 0 | AF32: 0 | AG32: 0 | AH32: 0 | AI32: 0 | AJ32: 0 | AK32: 4 | AL32: 2 | AM32: 0 | AN32: 0 | AO32: 0 | AP32: 0 | AQ32: 2 | AR32: 0 | AS32: 0 | AT32: 0 | AU32: 0 | AV32: 0 | AW32: 6 | AX32: 0 | AY32: 0 | AZ32: 24 | BA32: 6 | BB32: 0 | BC32: 10 | BD32: 0 | BE32: 2
B33: 原住民 | C33: Indigenous | D33: 54 | E33: 28 | F33: 26 | G33: 0 | H33: 10 | I33: 24 | J33: 2 | K33: 0 | L33: 0 | M33: 0 | N33: 0 | O33: 0 | P33: 0 | Q33: 0 | R33: 0 | S33: 10 | T33: 0 | U33: 0 | V33: 0 | W33: 0 | X33: 0 | Y33: 0 | Z33: 0 | AA33: 0 | AB33: 0 | AC33: 0 | AD33: 0 | AE33: 0 | AF33: 0 | AG33: 0 | AH33: 0 | AI33: 0 | AJ33: 0 | AK33: 0 | AL33: 0 | AM33: 0 | AN33: 0 | AO33: 0 | AP33: 0 | AQ33: 0 | AR33: 0 | AS33: 0 | AT33: 0 | AU33: 0 | AV33: 0 | AW33: 0 | AX33: 0 | AY33: 0 | AZ33: 6 | BA33: 2 | BB33: 0 | BC33: 0 | BD33: 0 | BE33: 0
A34: 苗栗縣 | B34: 計 | C34: Total | D34: 201 | E34: 150 | F34: 49 | G34: 2 | H34: 56 | I34: 38 | J34: 1 | K34: 0 | L34: 0 | M34: 1 | N34: 3 | O34: 0 | P34: 13 | Q34: 0 | R34: 0 | S34: 4 | T34: 3 | U34: 0 | V34: 25 | W34: 1 | X34: 0 | Y34: 0 | Z34: 0 | AA34: 0 | AB34: 0 | AC34: 0 | AD34: 0 | AE34: 1 | AF34: 0 | AG34: 0 | AH34: 2 | AI34: 0 | AJ34: 0 | AK34: 0 | AL34: 0 | AM34: 0 | AN34: 1 | AO34: 0 | AP34: 0 | AQ34: 10 | AR34: 1 | AS34: 0 | AT34: 6 | AU34: 0 | AV34: 0 | AW34: 6 | AX34: 0 | AY34: 0 | AZ34: 24 | BA34: 3 | BB34: 0 | BC34: 0 | BD34: 0 | BE34: 2
A35: Miaoli County | B35: 一般 | C35: General | D35: 194 | E35: 144 | F35: 48 | G35: 2 | H35: 51 | I35: 37 | J35: 1 | K35: 0 | L35: 0 | M35: 1 | N35: 3 | O35: 0 | P35: 13 | Q35: 0 | R35: 0 | S35: 4 | T35: 3 | U35: 0 | V35: 25 | W35: 1 | X35: 0 | Y35: 0 | Z35: 0 | AA35: 0 | AB35: 0 | AC35: 0 | AD35: 0 | AE35: 1 | AF35: 0 | AG35: 0 | AH35: 2 | AI35: 0 | AJ35: 0 | AK35: 0 | AL35: 0 | AM35: 0 | AN35: 1 | AO35: 0 | AP35: 0 | AQ35: 10 | AR35: 1 | AS35: 0 | AT35: 6 | AU35: 0 | AV35: 0 | AW35: 6 | AX35: 0 | AY35: 0 | AZ35: 23 | BA35: 3 | BB35: 0 | BC35: 0 | BD35: 0 | BE35: 2
B36: 原住民 | C36: Indigenous | D36: 7 | E36: 6 | F36: 1 | G36: 0 | H36: 5 | I36: 1 | J36: 0 | K36: 0 | L36: 0 | M36: 0 | N36: 0 | O36: 0 | P36: 0 | Q36: 0 | R36: 0 | S36: 0 | T36: 0 | U36: 0 | V36: 0 | W36: 0 | X36: 0 | Y36: 0 | Z36: 0 | AA36: 0 | AB36: 0 | AC36: 0 | AD36: 0 | AE36: 0 | AF36: 0 | AG36: 0 | AH36: 0 | AI36: 0 | AJ36: 0 | AK36: 0 | AL36: 0 | AM36: 0 | AN36: 0 | AO36: 0 | AP36: 0 | AQ36: 0 | AR36: 0 | AS36: 0 | AT36: 0 | AU36: 0 | AV36: 0 | AW36: 0 | AX36: 0 | AY36: 0 | AZ36: 1 | BA36: 0 | BB36: 0 | BC36: 0 | BD36: 0 | BE36: 0
A37: 彰化縣 | B37: 計 | C37: Total | D37: 373 | E37: 194 | F37: 177 | G37: 2 | H37: 131 | I37: 135 | J37: 10 | K37: 4 | L37: 0 | M37: 4 | N37: 10 | O37: 0 | P37: 10 | Q37: 5 | R37: 0 | S37: 4 | T37: 7 | U37: 0 | V37: 0 | W37: 0 | X37: 0 | Y37: 0 | Z37: 0 | AA37: 0 | AB37: 0 | AC37: 0 | AD37: 0 | AE37: 1 | AF37: 1 | AG37: 0 | AH37: 3 | AI37: 6 | AJ37: 0 | AK37: 0 | AL37: 0 | AM37: 0 | AN37: 0 | AO37: 0 | AP37: 0 | AQ37: 0 | AR37: 0 | AS37: 0 | AT37: 0 | AU37: 0 | AV37: 0 | AW37: 0 | AX37: 0 | AY37: 0 | AZ37: 0 | BA37: 0 | BB37: 0 | BC37: 31 | BD37: 9 | BE37: 2
A38: Changhua County | B38: 一般 | C38: General | D38: 360 | E38: 188 | F38: 170 | G38: 2 | H38: 125 | I38: 128 | J38: 10 | K38: 4 | L38: 0 | M38: 4 | N38: 10 | O38: 0 | P38: 10 | Q38: 5 | R38: 0 | S38: 4 | T38: 7 | U38: 0 | V38: 0 | W38: 0 | X38: 0 | Y38: 0 | Z38: 0 | AA38: 0 | AB38: 0 | AC38: 0 | AD38: 0 | AE38: 1 | AF38: 1 | AG38: 0 | AH38: 3 | AI38: 6 | AJ38: 0 | AK38: 0 | AL38: 0 | AM38: 0 | AN38: 0 | AO38: 0 | AP38: 0 | AQ38: 0 | AR38: 0 | AS38: 0 | AT38: 0 | AU38: 0 | AV38: 0 | AW38: 0 | AX38: 0 | AY38: 0 | AZ38: 0 | BA38: 0 | BB38: 0 | BC38: 31 | BD38: 9 | BE38: 2
B39: 原住民 | C39: Indigenous | D39: 13 | E39: 6 | F39: 7 | G39: 0 | H39: 6 | I39: 7 | J39: 0 | K39: 0 | L39: 0 | M39: 0 | N39: 0 | O39: 0 | P39: 0 | Q39: 0 | R39: 0 | S39: 0 | T39: 0 | U39: 0 | V39: 0 | W39: 0 | X39: 0 | Y39: 0 | Z39: 0 | AA39: 0 | AB39: 0 | AC39: 0 | AD39: 0 | AE39: 0 | AF39: 0 | AG39: 0 | AH39: 0 | AI39: 0 | AJ39: 0 | AK39: 0 | AL39: 0 | AM39: 0 | AN39: 0 | AO39: 0 | AP39: 0 | AQ39: 0 | AR39: 0 | AS39: 0 | AT39: 0 | AU39: 0 | AV39: 0 | AW39: 0 | AX39: 0 | AY39: 0 | AZ39: 0 | BA39: 0 | BB39: 0 | BC39: 0 | BD39: 0 | BE39: 0
A40: 南投縣 | B40: 計 | C40: Total | D40: 190 | E40: 138 | F40: 49 | G40: 3 | H40: 51 | I40: 40 | J40: 7 | K40: 1 | L40: 0 | M40: 7 | N40: 2 | O40: 0 | P40: 6 | Q40: 0 | R40: 0 | S40: 2 | T40: 0 | U40: 0 | V40: 0 | W40: 0 | X40: 0 | Y40: 0 | Z40: 0 | AA40: 0 | AB40: 0 | AC40: 0 | AD40: 0 | AE40: 0 | AF40: 0 | AG40: 0 | AH40: 0 | AI40: 0 | AJ40: 0 | AK40: 0 | AL40: 0 | AM40: 0 | AN40: 0 | AO40: 0 | AP40: 0 | AQ40: 2 | AR40: 1 | AS40: 0 | AT40: 1 | AU40: 0 | AV40: 0 | AW40: 0 | AX40: 0 | AY40: 0 | AZ40: 16 | BA40: 0 | BB40: 0 | BC40: 46 | BD40: 5 | BE40: 3
A41: Nantou County | B41: 一般 | C41: General | D41: 150 | E41: 111 | F41: 36 | G41: 3 | H41: 37 | I41: 30 | J41: 5 | K41: 0 | L41: 0 | M41: 7 | N41: 2 | O41: 0 | P41: 3 | Q41: 0 | R41: 0 | S41: 1 | T41: 0 | U41: 0 | V41: 0 | W41: 0 | X41: 0 | Y41: 0 | Z41: 0 | AA41: 0 | AB41: 0 | AC41: 0 | AD41: 0 | AE41: 0 | AF41: 0 | AG41: 0 | AH41: 0 | AI41: 0 | AJ41: 0 | AK41: 0 | AL41: 0 | AM41: 0 | AN41: 0 | AO41: 0 | AP41: 0 | AQ41: 2 | AR41: 1 | AS41: 0 | AT41: 1 | AU41: 0 | AV41: 0 | AW41: 0 | AX41: 0 | AY41: 0 | AZ41: 14 | BA41: 0 | BB41: 0 | BC41: 41 | BD41: 3 | BE41: 3
...

Sheet July-Dec., 2025
A1: 兒童及少年保護-施虐者身分別分Number of Persons Who Abuse Child and Youth by Identity
A2: 單位：人 Unit : Persons
A3: 民國114年7-12月 July-Dec., 2025 | D3: =IF(D8=SUM(D11,D14,D17,D20,D23,D26,D29,D32,D35,D38,D41,D44,D47,D50,D53,D56,D59,D62,D65,D68,D71,D74,),"","*") | E3: =IF(E8=SUM(E11,E14,E17,E20,E23,E26,E29,E32,E35,E38,E41,E44,E47,E50,E53,E56,E59,E62,E65,E68,E71,E74,),"","*") | F3: =IF(F8=SUM(F11,F14,F17,F20,F23,F26,F29,F32,F35,F38,F41,F44,F47,F50,F53,F56,F59,F62,F65,F68,F71,F74,),"","*") | G3: =IF(G8=SUM(G11,G14,G17,G20,G23,G26,G29,G32,G35,G38,G41,G44,G47,G50,G53,G56,G59,G62,G65,G68,G71,G74,),"","*") | H3: =IF(H8=SUM(H11,H14,H17,H20,H23,H26,H29,H32,H35,H38,H41,H44,H47,H50,H53,H56,H59,H62,H65,H68,H71,H74,),"","*") | I3: =IF(I8=SUM(I11,I14,I17,I20,I23,I26,I29,I32,I35,I38,I41,I44,I47,I50,I53,I56,I59,I62,I65,I68,I71,I74,),"","*") | J3: =IF(J8=SUM(J11,J14,J17,J20,J23,J26,J29,J32,J35,J38,J41,J44,J47,J50,J53,J56,J59,J62,J65,J68,J71,J74,),"","*") | K3: =IF(K8=SUM(K11,K14,K17,K20,K23,K26,K29,K32,K35,K38,K41,K44,K47,K50,K53,K56,K59,K62,K65,K68,K71,K74,),"","*") | ... BE3: =IF(BE8=SUM(BE11,BE14,BE17,BE20,BE23,BE26,BE29,BE32,BE35,BE38,BE41,BE44,BE47,BE50,BE53,BE56,BE59,BE62,BE65,BE68,BE71,BE74,),"","*")
A4: 區域及特殊族群別 Locality & Ethnos | D4: 總計 Total | H4: (養)父母 Parents (Foster Parents) | J4: 手足 Siblings | M4: (外)祖父母 Grandparents | P4: 其他親屬 Other Relatives | S4: 父或母之同居人 Cohabitants | V4: (前)親密關係伴侶 Intimate Partner | Y4: 托育機構人員 Childcare Institution Staff | AB4: 居家式托育人員 Home-based Childcare Staff | AE4: 補習班或兒童課後 照顧服務中心人員 After-school Care Service Center Staff | AH4: 學校教職員工 School Faculty and Staff | AK4: 安置單位人員 Resettlement Agency Staff | AN4: 職場上司同事 Boss/Colleagues | AQ4: 朋友/鄰居 Friends/Neighbors | AT4: 網友 Netizens | AW4: 陌生人 Stranger | AZ4: 其他 Others | BC4: 不詳 Unknown
D5: 合計 SubTotal | E5: 男 Male | F5: 女 Female | G5: 不詳 Unknown | H5: 男 Male | I5: 女 Female | J5: 男 Male | K5: 女 Female | L5: 不詳 Unknown | M5: 男 Male | N5: 女 Female | O5: 不詳 Unknown | P5: 男 Male | Q5: 女 Female | R5: 不詳 Unknown | S5: 男 Male | T5: 女 Female | U5: 不詳 Unknown | V5: 男 Male | W5: 女 Female | X5: 不詳 Unknown | Y5: 男 Male | Z5: 女 Female | AA5: 不詳 Unknown | AB5: 男 Male | AC5: 女 Female | AD5: 不詳 Unknown | AE5: 男 Male | AF5: 女 Female | AG5: 不詳 Unknown | AH5: 男 Male | AI5: 女 Female | AJ5: 不詳 Unknown | AK5: 男 Male | AL5: 女 Female | AM5: 不詳 Unknown | AN5: 男 Male | AO5: 女 Female | AP5: 不詳 Unknown | AQ5: 男 Male | AR5: 女 Female | AS5: 不詳 Unknown | AT5: 男 Male | AU5: 女 Female | AV5: 不詳 Unknown | AW5: 男 Male | AX5: 女 Female | AY5: 不詳 Unknown | AZ5: 男 Male | BA5: 女 Female | BB5: 不詳 Unknown | BC5: 男 Male | BD5: 女 Female | BE5: 不詳 Unknown
A7: 總計 | B7: 計 | C7: Total | D7: 4474 | E7: 2852 | F7: 1578 | G7: 44 | H7: 1315 | I7: 1079 | J7: 77 | K7: 15 | L7: 0 | M7: 66 | N7: 98 | O7: 0 | P7: 113 | Q7: 32 | R7: 0 | S7: 125 | T7: 37 | U7: 1 | V7: 11 | W7: 0 | X7: 0 | Y7: 1 | Z7: 3 | AA7: 0 | AB7: 3 | AC7: 4 | AD7: 0 | AE7: 9 | AF7: 0 | AG7: 0 | AH7: 18 | AI7: 1 | AJ7: 0 | AK7: 11 | AL7: 3 | AM7: 0 | AN7: 1 | AO7: 0 | AP7: 0 | AQ7: 320 | AR7: 34 | AS7: 0 | AT7: 3 | AU7: 0 | AV7: 0 | AW7: 47 | AX7: 2 | AY7: 0 | AZ7: 308 | BA7: 58 | BB7: 0 | BC7: 424 | BD7: 212 | BE7: 43
A8: Total | B8: 一般 | C8: General | D8: 4159 | E8: 2661 | F8: 1454 | G8: 44 | H8: 1234 | I8: 981 | J8: 67 | K8: 12 | L8: 0 | M8: 61 | N8: 96 | O8: 0 | P8: 100 | Q8: 27 | R8: 0 | S8: 101 | T8: 37 | U8: 1 | V8: 11 | W8: 0 | X8: 0 | Y8: 1 | Z8: 3 | AA8: 0 | AB8: 3 | AC8: 4 | AD8: 0 | AE8: 9 | AF8: 0 | AG8: 0 | AH8: 18 | AI8: 1 | AJ8: 0 | AK8: 11 | AL8: 3 | AM8: 0 | AN8: 1 | AO8: 0 | AP8: 0 | AQ8: 302 | AR8: 33 | AS8: 0 | AT8: 3 | AU8: 0 | AV8: 0 | AW8: 44 | AX8: 2 | AY8: 0 | AZ8: 297 | BA8: 54 | BB8: 0 | BC8: 398 | BD8: 201 | BE8: 43
B9: 原住民 | C9: Indigenous | D9: 315 | E9: 191 | F9: 124 | G9: 0 | H9: 81 | I9: 98 | J9: 10 | K9: 3 | L9: 0 | M9: 5 | N9: 2 | O9: 0 | P9: 13 | Q9: 5 | R9: 0 | S9: 24 | T9: 0 | U9: 0 | V9: 0 | W9: 0 | X9: 0 | Y9: 0 | Z9: 0 | AA9: 0 | AB9: 0 | AC9: 0 | AD9: 0 | AE9: 0 | AF9: 0 | AG9: 0 | AH9: 0 | AI9: 0 | AJ9: 0 | AK9: 0 | AL9: 0 | AM9: 0 | AN9: 0 | AO9: 0 | AP9: 0 | AQ9: 18 | AR9: 1 | AS9: 0 | AT9: 0 | AU9: 0 | AV9: 0 | AW9: 3 | AX9: 0 | AY9: 0 | AZ9: 11 | BA9: 4 | BB9: 0 | BC9: 26 | BD9: 11 | BE9: 0
A10: 新北市 | B10: 計 | C10: Total | D10: 987 | E10: 666 | F10: 307 | G10: 14 | H10: 261 | I10: 182 | J10: 15 | K10: 2 | L10: 0 | M10: 10 | N10: 19 | O10: 0 | P10: 21 | Q10: 5 | R10: 0 | S10: 25 | T10: 5 | U10: 0 | V10: 0 | W10: 0 | X10: 0 | Y10: 0 | Z10: 0 | AA10: 0 | AB10: 0 | AC10: 1 | AD10: 0 | AE10: 0 | AF10: 0 | AG10: 0 | AH10: 5 | AI10: 0 | AJ10: 0 | AK10: 2 | AL10: 0 | AM10: 0 | AN10: 0 | AO10: 0 | AP10: 0 | AQ10: 104 | AR10: 5 | AS10: 0 | AT10: 0 | AU10: 0 | AV10: 0 | AW10: 14 | AX10: 1 | AY10: 0 | AZ10: 72 | BA10: 9 | BB10: 0 | BC10: 137 | BD10: 78 | BE10: 14
A11: New Taipei City | B11: 一般 | C11: General | D11: 936 | E11: 637 | F11: 285 | G11: 14 | H11: 251 | I11: 169 | J11: 14 | K11: 2 | L11: 0 | M11: 8 | N11: 18 | O11: 0 | P11: 18 | Q11: 5 | R11: 0 | S11: 18 | T11: 5 | U11: 0 | V11: 0 | W11: 0 | X11: 0 | Y11: 0 | Z11: 0 | AA11: 0 | AB11: 0 | AC11: 1 | AD11: 0 | AE11: 0 | AF11: 0 | AG11: 0 | AH11: 5 | AI11: 0 | AJ11: 0 | AK11: 2 | AL11: 0 | AM11: 0 | AN11: 0 | AO11: 0 | AP11: 0 | AQ11: 102 | AR11: 5 | AS11: 0 | AT11: 0 | AU11: 0 | AV11: 0 | AW11: 14 | AX11: 1 | AY11: 0 | AZ11: 72 | BA11: 6 | BB11: 0 | BC11: 133 | BD11: 73 | BE11: 14
B12: 原住民 | C12: Indigenous | D12: 51 | E12: 29 | F12: 22 | G12: 0 | H12: 10 | I12: 13 | J12: 1 | K12: 0 | L12: 0 | M12: 2 | N12: 1 | O12: 0 | P12: 3 | Q12: 0 | R12: 0 | S12: 7 | T12: 0 | U12: 0 | V12: 0 | W12: 0 | X12: 0 | Y12: 0 | Z12: 0 | AA12: 0 | AB12: 0 | AC12: 0 | AD12: 0 | AE12: 0 | AF12: 0 | AG12: 0 | AH12: 0 | AI12: 0 | AJ12: 0 | AK12: 0 | AL12: 0 | AM12: 0 | AN12: 0 | AO12: 0 | AP12: 0 | AQ12: 2 | AR12: 0 | AS12: 0 | AT12: 0 | AU12: 0 | AV12: 0 | AW12: 0 | AX12: 0 | AY12: 0 | AZ12: 0 | BA12: 3 | BB12: 0 | BC12: 4 | BD12: 5 | BE12: 0
A13: 臺北市 | B13: 計 | C13: Total | D13: 374 | E13: 239 | F13: 134 | G13: 1 | H13: 106 | I13: 91 | J13: 4 | K13: 0 | L13: 0 | M13: 3 | N13: 4 | O13: 0 | P13: 4 | Q13: 3 | R13: 0 | S13: 10 | T13: 2 | U13: 0 | V13: 0 | W13: 0 | X13: 0 | Y13: 1 | Z13: 0 | AA13: 0 | AB13: 0 | AC13: 0 | AD13: 0 | AE13: 3 | AF13: 0 | AG13: 0 | AH13: 3 | AI13: 0 | AJ13: 0 | AK13: 0 | AL13: 0 | AM13: 0 | AN13: 0 | AO13: 0 | AP13: 0 | AQ13: 32 | AR13: 4 | AS13: 0 | AT13: 0 | AU13: 0 | AV13: 0 | AW13: 3 | AX13: 0 | AY13: 0 | AZ13: 32 | BA13: 0 | BB13: 0 | BC13: 38 | BD13: 30 | BE13: 1
A14: Taipei City | B14: 一般 | C14: General | D14: 368 | E14: 238 | F14: 129 | G14: 1 | H14: 106 | I14: 87 | J14: 4 | K14: 0 | L14: 0 | M14: 3 | N14: 4 | O14: 0 | P14: 4 | Q14: 3 | R14: 0 | S14: 10 | T14: 2 | U14: 0 | V14: 0 | W14: 0 | X14: 0 | Y14: 1 | Z14: 0 | AA14: 0 | AB14: 0 | AC14: 0 | AD14: 0 | AE14: 3 | AF14: 0 | AG14: 0 | AH14: 3 | AI14: 0 | AJ14: 0 | AK14: 0 | AL14: 0 | AM14: 0 | AN14: 0 | AO14: 0 | AP14: 0 | AQ14: 31 | AR14: 4 | AS14: 0 | AT14: 0 | AU14: 0 | AV14: 0 | AW14: 3 | AX14: 0 | AY14: 0 | AZ14: 32 | BA14: 0 | BB14: 0 | BC14: 38 | BD14: 29 | BE14: 1
B15: 原住民 | C15: Indigenous | D15: 6 | E15: 1 | F15: 5 | G15: 0 | H15: 0 | I15: 4 | J15: 0 | K15: 0 | L15: 0 | M15: 0 | N15: 0 | O15: 0 | P15: 0 | Q15: 0 | R15: 0 | S15: 0 | T15: 0 | U15: 0 | V15: 0 | W15: 0 | X15: 0 | Y15: 0 | Z15: 0 | AA15: 0 | AB15: 0 | AC15: 0 | AD15: 0 | AE15: 0 | AF15: 0 | AG15: 0 | AH15: 0 | AI15: 0 | AJ15: 0 | AK15: 0 | AL15: 0 | AM15: 0 | AN15: 0 | AO15: 0 | AP15: 0 | AQ15: 1 | AR15: 0 | AS15: 0 | AT15: 0 | AU15: 0 | AV15: 0 | AW15: 0 | AX15: 0 | AY15: 0 | AZ15: 0 | BA15: 0 | BB15: 0 | BC15: 0 | BD15: 1 | BE15: 0
A16: 桃園市 | B16: 計 | C16: Total | D16: 352 | E16: 251 | F16: 92 | G16: 9 | H16: 120 | I16: 75 | J16: 4 | K16: 0 | L16: 0 | M16: 7 | N16: 7 | O16: 0 | P16: 14 | Q16: 1 | R16: 0 | S16: 10 | T16: 0 | U16: 0 | V16: 0 | W16: 0 | X16: 0 | Y16: 0 | Z16: 0 | AA16: 0 | AB16: 0 | AC16: 1 | AD16: 0 | AE16: 1 | AF16: 0 | AG16: 0 | AH16: 0 | AI16: 0 | AJ16: 0 | AK16: 0 | AL16: 0 | AM16: 0 | AN16: 0 | AO16: 0 | AP16: 0 | AQ16: 26 | AR16: 5 | AS16: 0 | AT16: 2 | AU16: 0 | AV16: 0 | AW16: 6 | AX16: 0 | AY16: 0 | AZ16: 39 | BA16: 1 | BB16: 0 | BC16: 22 | BD16: 2 | BE16: 9
A17: Taoyuan City | B17: 一般 | C17: General | D17: 311 | E17: 227 | F17: 75 | G17: 9 | H17: 106 | I17: 60 | J17: 3 | K17: 0 | L17: 0 | M17: 6 | N17: 7 | O17: 0 | P17: 14 | Q17: 0 | R17: 0 | S17: 6 | T17: 0 | U17: 0 | V17: 0 | W17: 0 | X17: 0 | Y17: 0 | Z17: 0 | AA17: 0 | AB17: 0 | AC17: 1 | AD17: 0 | AE17: 1 | AF17: 0 | AG17: 0 | AH17: 0 | AI17: 0 | AJ17: 0 | AK17: 0 | AL17: 0 | AM17: 0 | AN17: 0 | AO17: 0 | AP17: 0 | AQ17: 24 | AR17: 4 | AS17: 0 | AT17: 2 | AU17: 0 | AV17: 0 | AW17: 5 | AX17: 0 | AY17: 0 | AZ17: 38 | BA17: 1 | BB17: 0 | BC17: 22 | BD17: 2 | BE17: 9
B18: 原住民 | C18: Indigenous | D18: 41 | E18: 24 | F18: 17 | G18: 0 | H18: 14 | I18: 15 | J18: 1 | K18: 0 | L18: 0 | M18: 1 | N18: 0 | O18: 0 | P18: 0 | Q18: 1 | R18: 0 | S18: 4 | T18: 0 | U18: 0 | V18: 0 | W18: 0 | X18: 0 | Y18: 0 | Z18: 0 | AA18: 0 | AB18: 0 | AC18: 0 | AD18: 0 | AE18: 0 | AF18: 0 | AG18: 0 | AH18: 0 | AI18: 0 | AJ18: 0 | AK18: 0 | AL18: 0 | AM18: 0 | AN18: 0 | AO18: 0 | AP18: 0 | AQ18: 2 | AR18: 1 | AS18: 0 | AT18: 0 | AU18: 0 | AV18: 0 | AW18: 1 | AX18: 0 | AY18: 0 | AZ18: 1 | BA18: 0 | BB18: 0 | BC18: 0 | BD18: 0 | BE18: 0
A19: 臺中市 | B19: 計 | C19: Total | D19: 613 | E19: 398 | F19: 209 | G19: 6 | H19: 230 | I19: 153 | J19: 15 | K19: 5 | L19: 0 | M19: 14 | N19: 16 | O19: 0 | P19: 9 | Q19: 5 | R19: 0 | S19: 12 | T19: 7 | U19: 0 | V19: 0 | W19: 0 | X19: 0 | Y19: 0 | Z19: 0 | AA19: 0 | AB19: 0 | AC19: 0 | AD19: 0 | AE19: 0 | AF19: 0 | AG19: 0 | AH19: 2 | AI19: 0 | AJ19: 0 | AK19: 5 | AL19: 0 | AM19: 0 | AN19: 0 | AO19: 0 | AP19: 0 | AQ19: 46 | AR19: 2 | AS19: 0 | AT19: 0 | AU19: 0 | AV19: 0 | AW19: 2 | AX19: 0 | AY19: 0 | AZ19: 43 | BA19: 2 | BB19: 0 | BC19: 20 | BD19: 19 | BE19: 6
A20: Taichung City | B20: 一般 | C20: General | D20: 590 | E20: 384 | F20: 200 | G20: 6 | H20: 222 | I20: 146 | J20: 12 | K20: 4 | L20: 0 | M20: 13 | N20: 15 | O20: 0 | P20: 9 | Q20: 5 | R20: 0 | S20: 12 | T20: 7 | U20: 0 | V20: 0 | W20: 0 | X20: 0 | Y20: 0 | Z20: 0 | AA20: 0 | AB20: 0 | AC20: 0 | AD20: 0 | AE20: 0 | AF20: 0 | AG20: 0 | AH20: 2 | AI20: 0 | AJ20: 0 | AK20: 5 | AL20: 0 | AM20: 0 | AN20: 0 | AO20: 0 | AP20: 0 | AQ20: 45 | AR20: 2 | AS20: 0 | AT20: 0 | AU20: 0 | AV20: 0 | AW20: 1 | AX20: 0 | AY20: 0 | AZ20: 43 | BA20: 2 | BB20: 0 | BC20: 20 | BD20: 19 | BE20: 6
B21: 原住民 | C21: Indigenous | D21: 23 | E21: 14 | F21: 9 | G21: 0 | H21: 8 | I21: 7 | J21: 3 | K21: 1 | L21: 0 | M21: 1 | N21: 1 | O21: 0 | P21: 0 | Q21: 0 | R21: 0 | S21: 0 | T21: 0 | U21: 0 | V21: 0 | W21: 0 | X21: 0 | Y21: 0 | Z21: 0 | AA21: 0 | AB21: 0 | AC21: 0 | AD21: 0 | AE21: 0 | AF21: 0 | AG21: 0 | AH21: 0 | AI21: 0 | AJ21: 0 | AK21: 0 | AL21: 0 | AM21: 0 | AN21: 0 | AO21: 0 | AP21: 0 | AQ21: 1 | AR21: 0 | AS21: 0 | AT21: 0 | AU21: 0 | AV21: 0 | AW21: 1 | AX21: 0 | AY21: 0 | AZ21: 0 | BA21: 0 | BB21: 0 | BC21: 0 | BD21: 0 | BE21: 0
A22: 臺南市 | B22: 計 | C22: Total | D22: 214 | E22: 135 | F22: 77 | G22: 2 | H22: 55 | I22: 57 | J22: 6 | K22: 1 | L22: 0 | M22: 5 | N22: 6 | O22: 0 | P22: 4 | Q22: 3 | R22: 0 | S22: 9 | T22: 4 | U22: 0 | V22: 0 | W22: 0 | X22: 0 | Y22: 0 | Z22: 0 | AA22: 0 | AB22: 0 | AC22: 0 | AD22: 0 | AE22: 3 | AF22: 0 | AG22: 0 | AH22: 2 | AI22: 0 | AJ22: 0 | AK22: 2 | AL22: 1 | AM22: 0 | AN22: 0 | AO22: 0 | AP22: 0 | AQ22: 14 | AR22: 3 | AS22: 0 | AT22: 0 | AU22: 0 | AV22: 0 | AW22: 7 | AX22: 0 | AY22: 0 | AZ22: 24 | BA22: 1 | BB22: 0 | BC22: 4 | BD22: 1 | BE22: 2
A23: Tainan City | B23: 一般 | C23: General | D23: 210 | E23: 134 | F23: 74 | G23: 2 | H23: 55 | I23: 55 | J23: 5 | K23: 0 | L23: 0 | M23: 5 | N23: 6 | O23: 0 | P23: 4 | Q23: 3 | R23: 0 | S23: 9 | T23: 4 | U23: 0 | V23: 0 | W23: 0 | X23: 0 | Y23: 0 | Z23: 0 | AA23: 0 | AB23: 0 | AC23: 0 | AD23: 0 | AE23: 3 | AF23: 0 | AG23: 0 | AH23: 2 | AI23: 0 | AJ23: 0 | AK23: 2 | AL23: 1 | AM23: 0 | AN23: 0 | AO23: 0 | AP23: 0 | AQ23: 14 | AR23: 3 | AS23: 0 | AT23: 0 | AU23: 0 | AV23: 0 | AW23: 7 | AX23: 0 | AY23: 0 | AZ23: 24 | BA23: 1 | BB23: 0 | BC23: 4 | BD23: 1 | BE23: 2
B24: 原住民 | C24: Indigenous | D24: 4 | E24: 1 | F24: 3 | G24: 0 | H24: 0 | I24: 2 | J24: 1 | K24: 1 | L24: 0 | M24: 0 | N24: 0 | O24: 0 | P24: 0 | Q24: 0 | R24: 0 | S24: 0 | T24: 0 | U24: 0 | V24: 0 | W24: 0 | X24: 0 | Y24: 0 | Z24: 0 | AA24: 0 | AB24: 0 | AC24: 0 | AD24: 0 | AE24: 0 | AF24: 0 | AG24: 0 | AH24: 0 | AI24: 0 | AJ24: 0 | AK24: 0 | AL24: 0 | AM24: 0 | AN24: 0 | AO24: 0 | AP24: 0 | AQ24: 0 | AR24: 0 | AS24: 0 | AT24: 0 | AU24: 0 | AV24: 0 | AW24: 0 | AX24: 0 | AY24: 0 | AZ24: 0 | BA24: 0 | BB24: 0 | BC24: 0 | BD24: 0 | BE24: 0
A25: 高雄市 | B25: 計 | C25: Total | D25: 627 | E25: 349 | F25: 272 | G25: 6 | H25: 166 | I25: 149 | J25: 7 | K25: 2 | L25: 0 | M25: 8 | N25: 23 | O25: 0 | P25: 9 | Q25: 6 | R25: 0 | S25: 20 | T25: 5 | U25: 1 | V25: 0 | W25: 0 | X25: 0 | Y25: 0 | Z25: 3 | AA25: 0 | AB25: 1 | AC25: 0 | AD25: 0 | AE25: 0 | AF25: 0 | AG25: 0 | AH25: 2 | AI25: 0 | AJ25: 0 | AK25: 0 | AL25: 0 | AM25: 0 | AN25: 0 | AO25: 0 | AP25: 0 | AQ25: 28 | AR25: 1 | AS25: 0 | AT25: 0 | AU25: 0 | AV25: 0 | AW25: 3 | AX25: 0 | AY25: 0 | AZ25: 15 | BA25: 27 | BB25: 0 | BC25: 90 | BD25: 56 | BE25: 5
A26: Kaohsiung City | B26: 一般 | C26: General | D26: 607 | E26: 341 | F26: 260 | G26: 6 | H26: 162 | I26: 141 | J26: 7 | K26: 2 | L26: 0 | M26: 8 | N26: 23 | O26: 0 | P26: 9 | Q26: 4 | R26: 0 | S26: 20 | T26: 5 | U26: 1 | V26: 0 | W26: 0 | X26: 0 | Y26: 0 | Z26: 3 | AA26: 0 | AB26: 1 | AC26: 0 | AD26: 0 | AE26: 0 | AF26: 0 | AG26: 0 | AH26: 2 | AI26: 0 | AJ26: 0 | AK26: 0 | AL26: 0 | AM26: 0 | AN26: 0 | AO26: 0 | AP26: 0 | AQ26: 27 | AR26: 1 | AS26: 0 | AT26: 0 | AU26: 0 | AV26: 0 | AW26: 3 | AX26: 0 | AY26: 0 | AZ26: 15 | BA26: 27 | BB26: 0 | BC26: 87 | BD26: 54 | BE26: 5
B27: 原住民 | C27: Indigenous | D27: 20 | E27: 8 | F27: 12 | G27: 0 | H27: 4 | I27: 8 | J27: 0 | K27: 0 | L27: 0 | M27: 0 | N27: 0 | O27: 0 | P27: 0 | Q27: 2 | R27: 0 | S27: 0 | T27: 0 | U27: 0 | V27: 0 | W27: 0 | X27: 0 | Y27: 0 | Z27: 0 | AA27: 0 | AB27: 0 | AC27: 0 | AD27: 0 | AE27: 0 | AF27: 0 | AG27: 0 | AH27: 0 | AI27: 0 | AJ27: 0 | AK27: 0 | AL27: 0 | AM27: 0 | AN27: 0 | AO27: 0 | AP27: 0 | AQ27: 1 | AR27: 0 | AS27: 0 | AT27: 0 | AU27: 0 | AV27: 0 | AW27: 0 | AX27: 0 | AY27: 0 | AZ27: 0 | BA27: 0 | BB27: 0 | BC27: 3 | BD27: 2 | BE27: 0
A28: 宜蘭縣 | B28: 計 | C28: Total | D28: 30 | E28: 17 | F28: 13 | G28: 0 | H28: 10 | I28: 8 | J28: 0 | K28: 1 | L28: 0 | M28: 1 | N28: 1 | O28: 0 | P28: 2 | Q28: 1 | R28: 0 | S28: 4 | T28: 2 | U28: 0 | V28: 0 | W28: 0 | X28: 0 | Y28: 0 | Z28: 0 | AA28: 0 | AB28: 0 | AC28: 0 | AD28: 0 | AE28: 0 | AF28: 0 | AG28: 0 | AH28: 0 | AI28: 0 | AJ28: 0 | AK28: 0 | AL28: 0 | AM28: 0 | AN28: 0 | AO28: 0 | AP28: 0 | AQ28: 0 | AR28: 0 | AS28: 0 | AT28: 0 | AU28: 0 | AV28: 0 | AW28: 0 | AX28: 0 | AY28: 0 | AZ28: 0 | BA28: 0 | BB28: 0 | BC28: 0 | BD28: 0 | BE28: 0
A29: Yilan County | B29: 一般 | C29: General | D29: 28 | E29: 15 | F29: 13 | G29: 0 | H29: 10 | I29: 8 | J29: 0 | K29: 1 | L29: 0 | M29: 1 | N29: 1 | O29: 0 | P29: 1 | Q29: 1 | R29: 0 | S29: 3 | T29: 2 | U29: 0 | V29: 0 | W29: 0 | X29: 0 | Y29: 0 | Z29: 0 | AA29: 0 | AB29: 0 | AC29: 0 | AD29: 0 | AE29: 0 | AF29: 0 | AG29: 0 | AH29: 0 | AI29: 0 | AJ29: 0 | AK29: 0 | AL29: 0 | AM29: 0 | AN29: 0 | AO29: 0 | AP29: 0 | AQ29: 0 | AR29: 0 | AS29: 0 | AT29: 0 | AU29: 0 | AV29: 0 | AW29: 0 | AX29: 0 | AY29: 0 | AZ29: 0 | BA29: 0 | BB29: 0 | BC29: 0 | BD29: 0 | BE29: 0
B30: 原住民 | C30: Indigenous | D30: 2 | E30: 2 | F30: 0 | G30: 0 | H30: 0 | I30: 0 | J30: 0 | K30: 0 | L30: 0 | M30: 0 | N30: 0 | O30: 0 | P30: 1 | Q30: 0 | R30: 0 | S30: 1 | T30: 0 | U30: 0 | V30: 0 | W30: 0 | X30: 0 | Y30: 0 | Z30: 0 | AA30: 0 | AB30: 0 | AC30: 0 | AD30: 0 | AE30: 0 | AF30: 0 | AG30: 0 | AH30: 0 | AI30: 0 | AJ30: 0 | AK30: 0 | AL30: 0 | AM30: 0 | AN30: 0 | AO30: 0 | AP30: 0 | AQ30: 0 | AR30: 0 | AS30: 0 | AT30: 0 | AU30: 0 | AV30: 0 | AW30: 0 | AX30: 0 | AY30: 0 | AZ30: 0 | BA30: 0 | BB30: 0 | BC30: 0 | BD30: 0 | BE30: 0
A31: 新竹縣 | B31: 計 | C31: Total | D31: 168 | E31: 103 | F31: 64 | G31: 1 | H31: 59 | I31: 57 | J31: 5 | K31: 0 | L31: 0 | M31: 3 | N31: 1 | O31: 0 | P31: 2 | Q31: 1 | R31: 0 | S31: 8 | T31: 0 | U31: 0 | V31: 0 | W31: 0 | X31: 0 | Y31: 0 | Z31: 0 | AA31: 0 | AB31: 0 | AC31: 0 | AD31: 0 | AE31: 0 | AF31: 0 | AG31: 0 | AH31: 0 | AI31: 0 | AJ31: 0 | AK31: 2 | AL31: 1 | AM31: 0 | AN31: 0 | AO31: 0 | AP31: 0 | AQ31: 1 | AR31: 0 | AS31: 0 | AT31: 0 | AU31: 0 | AV31: 0 | AW31: 3 | AX31: 0 | AY31: 0 | AZ31: 15 | BA31: 4 | BB31: 0 | BC31: 5 | BD31: 0 | BE31: 1
A32: Hsinchu County | B32: 一般 | C32: General | D32: 141 | E32: 89 | F32: 51 | G32: 1 | H32: 54 | I32: 45 | J32: 4 | K32: 0 | L32: 0 | M32: 3 | N32: 1 | O32: 0 | P32: 2 | Q32: 1 | R32: 0 | S32: 3 | T32: 0 | U32: 0 | V32: 0 | W32: 0 | X32: 0 | Y32: 0 | Z32: 0 | AA32: 0 | AB32: 0 | AC32: 0 | AD32: 0 | AE32: 0 | AF32: 0 | AG32: 0 | AH32: 0 | AI32: 0 | AJ32: 0 | AK32: 2 | AL32: 1 | AM32: 0 | AN32: 0 | AO32: 0 | AP32: 0 | AQ32: 1 | AR32: 0 | AS32: 0 | AT32: 0 | AU32: 0 | AV32: 0 | AW32: 3 | AX32: 0 | AY32: 0 | AZ32: 12 | BA32: 3 | BB32: 0 | BC32: 5 | BD32: 0 | BE32: 1
B33: 原住民 | C33: Indigenous | D33: 27 | E33: 14 | F33: 13 | G33: 0 | H33: 5 | I33: 12 | J33: 1 | K33: 0 | L33: 0 | M33: 0 | N33: 0 | O33: 0 | P33: 0 | Q33: 0 | R33: 0 | S33: 5 | T33: 0 | U33: 0 | V33: 0 | W33: 0 | X33: 0 | Y33: 0 | Z33: 0 | AA33: 0 | AB33: 0 | AC33: 0 | AD33: 0 | AE33: 0 | AF33: 0 | AG33: 0 | AH33: 0 | AI33: 0 | AJ33: 0 | AK33: 0 | AL33: 0 | AM33: 0 | AN33: 0 | AO33: 0 | AP33: 0 | AQ33: 0 | AR33: 0 | AS33: 0 | AT33: 0 | AU33: 0 | AV33: 0 | AW33: 0 | AX33: 0 | AY33: 0 | AZ33: 3 | BA33: 1 | BB33: 0 | BC33: 0 | BD33: 0 | BE33: 0
A34: 苗栗縣 | B34: 計 | C34: Total | D34: 99 | E34: 71 | F34: 26 | G34: 2 | H34: 30 | I34: 19 | J34: 0 | K34: 0 | L34: 0 | M34: 0 | N34: 2 | O34: 0 | P34: 7 | Q34: 0 | R34: 0 | S34: 0 | T34: 2 | U34: 0 | V34: 11 | W34: 0 | X34: 0 | Y34: 0 | Z34: 0 | AA34: 0 | AB34: 0 | AC34: 0 | AD34: 0 | AE34: 1 | AF34: 0 | AG34: 0 | AH34: 1 | AI34: 0 | AJ34: 0 | AK34: 0 | AL34: 0 | AM34: 0 | AN34: 1 | AO34: 0 | AP34: 0 | AQ34: 5 | AR34: 1 | AS34: 0 | AT34: 0 | AU34: 0 | AV34: 0 | AW34: 5 | AX34: 0 | AY34: 0 | AZ34: 10 | BA34: 2 | BB34: 0 | BC34: 0 | BD34: 0 | BE34: 2
A35: Miaoli County | B35: 一般 | C35: General | D35: 94 | E35: 67 | F35: 25 | G35: 2 | H35: 26 | I35: 18 | J35: 0 | K35: 0 | L35: 0 | M35: 0 | N35: 2 | O35: 0 | P35: 7 | Q35: 0 | R35: 0 | S35: 0 | T35: 2 | U35: 0 | V35: 11 | W35: 0 | X35: 0 | Y35: 0 | Z35: 0 | AA35: 0 | AB35: 0 | AC35: 0 | AD35: 0 | AE35: 1 | AF35: 0 | AG35: 0 | AH35: 1 | AI35: 0 | AJ35: 0 | AK35: 0 | AL35: 0 | AM35: 0 | AN35: 1 | AO35: 0 | AP35: 0 | AQ35: 5 | AR35: 1 | AS35: 0 | AT35: 0 | AU35: 0 | AV35: 0 | AW35: 5 | AX35: 0 | AY35: 0 | AZ35: 10 | BA35: 2 | BB35: 0 | BC35: 0 | BD35: 0 | BE35: 2
B36: 原住民 | C36: Indigenous | D36: 5 | E36: 4 | F36: 1 | G36: 0 | H36: 4 | I36: 1 | J36: 0 | K36: 0 | L36: 0 | M36: 0 | N36: 0 | O36: 0 | P36: 0 | Q36: 0 | R36: 0 | S36: 0 | T36: 0 | U36: 0 | V36: 0 | W36: 0 | X36: 0 | Y36: 0 | Z36: 0 | AA36: 0 | AB36: 0 | AC36: 0 | AD36: 0 | AE36: 0 | AF36: 0 | AG36: 0 | AH36: 0 | AI36: 0 | AJ36: 0 | AK36: 0 | AL36: 0 | AM36: 0 | AN36: 0 | AO36: 0 | AP36: 0 | AQ36: 0 | AR36: 0 | AS36: 0 | AT36: 0 | AU36: 0 | AV36: 0 | AW36: 0 | AX36: 0 | AY36: 0 | AZ36: 0 | BA36: 0 | BB36: 0 | BC36: 0 | BD36: 0 | BE36: 0
A37: 彰化縣 | B37: 計 | C37: Total | D37: 150 | E37: 61 | F37: 89 | G37: 0 | H37: 52 | I37: 74 | J37: 3 | K37: 1 | L37: 0 | M37: 0 | N37: 6 | O37: 0 | P37: 2 | Q37: 2 | R37: 0 | S37: 2 | T37: 6 | U37: 0 | V37: 0 | W37: 0 | X37: 0 | Y37: 0 | Z37: 0 | AA37: 0 | AB37: 0 | AC37: 0 | AD37: 0 | AE37: 0 | AF37: 0 | AG37: 0 | AH37: 2 | AI37: 0 | AJ37: 0 | AK37: 0 | AL37: 0 | AM37: 0 | AN37: 0 | AO37: 0 | AP37: 0 | AQ37: 0 | AR37: 0 | AS37: 0 | AT37: 0 | AU37: 0 | AV37: 0 | AW37: 0 | AX37: 0 | AY37: 0 | AZ37: 0 | BA37: 0 | BB37: 0 | BC37: 0 | BD37: 0 | BE37: 0
A38: Changhua County | B38: 一般 | C38: General | D38: 140 | E38: 57 | F38: 83 | G38: 0 | H38: 48 | I38: 68 | J38: 3 | K38: 1 | L38: 0 | M38: 0 | N38: 6 | O38: 0 | P38: 2 | Q38: 2 | R38: 0 | S38: 2 | T38: 6 | U38: 0 | V38: 0 | W38: 0 | X38: 0 | Y38: 0 | Z38: 0 | AA38: 0 | AB38: 0 | AC38: 0 | AD38: 0 | AE38: 0 | AF38: 0 | AG38: 0 | AH38: 2 | AI38: 0 | AJ38: 0 | AK38: 0 | AL38: 0 | AM38: 0 | AN38: 0 | AO38: 0 | AP38: 0 | AQ38: 0 | AR38: 0 | AS38: 0 | AT38: 0 | AU38: 0 | AV38: 0 | AW38: 0 | AX38: 0 | AY38: 0 | AZ38: 0 | BA38: 0 | BB38: 0 | BC38: 0 | BD38: 0 | BE38: 0
B39: 原住民 | C39: Indigenous | D39: 10 | E39: 4 | F39: 6 | G39: 0 | H39: 4 | I39: 6 | J39: 0 | K39: 0 | L39: 0 | M39: 0 | N39: 0 | O39: 0 | P39: 0 | Q39: 0 | R39: 0 | S39: 0 | T39: 0 | U39: 0 | V39: 0 | W39: 0 | X39: 0 | Y39: 0 | Z39: 0 | AA39: 0 | AB39: 0 | AC39: 0 | AD39: 0 | AE39: 0 | AF39: 0 | AG39: 0 | AH39: 0 | AI39: 0 | AJ39: 0 | AK39: 0 | AL39: 0 | AM39: 0 | AN39: 0 | AO39: 0 | AP39: 0 | AQ39: 0 | AR39: 0 | AS39: 0 | AT39: 0 | AU39: 0 | AV39: 0 | AW39: 0 | AX39: 0 | AY39: 0 | AZ39: 0 | BA39: 0 | BB39: 0 | BC39: 0 | BD39: 0 | BE39: 0
A40: 南投縣 | B40: 計 | C40: Total | D40: 76 | E40: 60 | F40: 16 | G40: 0 | H40: 20 | I40: 11 | J40: 2 | K40: 0 | L40: 0 | M40: 1 | N40: 0 | O40: 0 | P40: 0 | Q40: 0 | R40: 0 | S40: 0 | T40: 0 | U40: 0 | V40: 0 | W40: 0 | X40: 0 | Y40: 0 | Z40: 0 | AA40: 0 | AB40: 0 | AC40: 0 | AD40: 0 | AE40: 0 | AF40: 0 | AG40: 0 | AH40: 0 | AI40: 0 | AJ40: 0 | AK40: 0 | AL40: 0 | AM40: 0 | AN40: 0 | AO40: 0 | AP40: 0 | AQ40: 1 | AR40: 1 | AS40: 0 | AT40: 1 | AU40: 0 | AV40: 0 | AW40: 0 | AX40: 0 | AY40: 0 | AZ40: 6 | BA40: 0 | BB40: 0 | BC40: 29 | BD40: 4 | BE40: 0
A41: Nantou County | B41: 一般 | C41: General | D41: 60 | E41: 47 | F41: 13 | G41: 0 | H41: 13 | I41: 9 | J41: 1 | K41: 0 | L41: 0 | M41: 1 | N41: 0 | O41: 0 | P41: 0 | Q41: 0 | R41: 0 | S41: 0 | T41: 0 | U41: 0 | V41: 0 | W41: 0 | X41: 0 | Y41: 0 | Z41: 0 | AA41: 0 | AB41: 0 | AC41: 0 | AD41: 0 | AE41: 0 | AF41: 0 | AG41: 0 | AH41: 0 | AI41: 0 | AJ41: 0 | AK41: 0 | AL41: 0 | AM41: 0 | AN41: 0 | AO41: 0 | AP41: 0 | AQ41: 1 | AR41: 1 | AS41: 0 | AT41: 1 | AU41: 0 | AV41: 0 | AW41: 0 | AX41: 0 | AY41: 0 | AZ41: 5 | BA41: 0 | BB41: 0 | BC41: 25 | BD41: 3 | BE41: 0
...

Sheet Jan.-June, 2025
A1: 兒童及少年保護-施虐者身分別分Number of Persons Who Abuse Child and Youth by Identity
A2: 單位：人 Unit : Persons
A3: 民國114年1-6月 Jan.-June, 2025 | D3: =IF(D8=SUM(D11,D14,D17,D20,D23,D26,D29,D32,D35,D38,D41,D44,D47,D50,D53,D56,D59,D62,D65,D68,D71,D74,),"","*") | E3: =IF(E8=SUM(E11,E14,E17,E20,E23,E26,E29,E32,E35,E38,E41,E44,E47,E50,E53,E56,E59,E62,E65,E68,E71,E74,),"","*") | F3: =IF(F8=SUM(F11,F14,F17,F20,F23,F26,F29,F32,F35,F38,F41,F44,F47,F50,F53,F56,F59,F62,F65,F68,F71,F74,),"","*") | G3: =IF(G8=SUM(G11,G14,G17,G20,G23,G26,G29,G32,G35,G38,G41,G44,G47,G50,G53,G56,G59,G62,G65,G68,G71,G74,),"","*") | H3: =IF(H8=SUM(H11,H14,H17,H20,H23,H26,H29,H32,H35,H38,H41,H44,H47,H50,H53,H56,H59,H62,H65,H68,H71,H74,),"","*") | I3: =IF(I8=SUM(I11,I14,I17,I20,I23,I26,I29,I32,I35,I38,I41,I44,I47,I50,I53,I56,I59,I62,I65,I68,I71,I74,),"","*") | J3: =IF(J8=SUM(J11,J14,J17,J20,J23,J26,J29,J32,J35,J38,J41,J44,J47,J50,J53,J56,J59,J62,J65,J68,J71,J74,),"","*") | K3: =IF(K8=SUM(K11,K14,K17,K20,K23,K26,K29,K32,K35,K38,K41,K44,K47,K50,K53,K56,K59,K62,K65,K68,K71,K74,),"","*") | ... BE3: =IF(BE8=SUM(BE11,BE14,BE17,BE20,BE23,BE26,BE29,BE32,BE35,BE38,BE41,BE44,BE47,BE50,BE53,BE56,BE59,BE62,BE65,BE68,BE71,BE74,),"","*")
A4: 區域及特殊族群別 Locality & Ethnos | D4: 總計 Total | H4: (養)父母 Parents (Foster Parents) | J4: 手足 Siblings | M4: (外)祖父母 Grandparents | P4: 其他親屬 Other Relatives | S4: 父或母之同居人 Cohabitants | V4: (前)親密關係伴侶 Intimate Partner | Y4: 托育機構人員 Childcare Institution Staff | AB4: 居家式托育人員 Home-based Childcare Staff | AE4: 補習班或兒童課後 照顧服務中心人員 After-school Care Service Center Staff | AH4: 學校教職員工 School Faculty and Staff | AK4: 安置單位人員 Resettlement Agency Staff | AN4: 職場上司同事 Boss/Colleagues | AQ4: 朋友/鄰居 Friends/Neighbors | AT4: 網友 Netizens | AW4: 陌生人 Stranger | AZ4: 其他 Others | BC4: 不詳 Unknown
D5: 合計 SubTotal | E5: 男 Male | F5: 女 Female | G5: 不詳 Unknown | H5: 男 Male | I5: 女 Female | J5: 男 Male | K5: 女 Female | L5: 不詳 Unknown | M5: 男 Male | N5: 女 Female | O5: 不詳 Unknown | P5: 男 Male | Q5: 女 Female | R5: 不詳 Unknown | S5: 男 Male | T5: 女 Female | U5: 不詳 Unknown | V5: 男 Male | W5: 女 Female | X5: 不詳 Unknown | Y5: 男 Male | Z5: 女 Female | AA5: 不詳 Unknown | AB5: 男 Male | AC5: 女 Female | AD5: 不詳 Unknown | AE5: 男 Male | AF5: 女 Female | AG5: 不詳 Unknown | AH5: 男 Male | AI5: 女 Female | AJ5: 不詳 Unknown | AK5: 男 Male | AL5: 女 Female | AM5: 不詳 Unknown | AN5: 男 Male | AO5: 女 Female | AP5: 不詳 Unknown | AQ5: 男 Male | AR5: 女 Female | AS5: 不詳 Unknown | AT5: 男 Male | AU5: 女 Female | AV5: 不詳 Unknown | AW5: 男 Male | AX5: 女 Female | AY5: 不詳 Unknown | AZ5: 男 Male | BA5: 女 Female | BB5: 不詳 Unknown | BC5: 男 Male | BD5: 女 Female | BE5: 不詳 Unknown
A7: 總計 | B7: 計 | C7: Total | D7: 5307 | E7: 3489 | F7: 1730 | G7: 88 | H7: 1755 | I7: 1288 | J7: 125 | K7: 28 | L7: 0 | M7: 74 | N7: 81 | O7: 0 | P7: 153 | Q7: 39 | R7: 0 | S7: 136 | T7: 42 | U7: 0 | V7: 91 | W7: 6 | X7: 0 | Y7: 0 | Z7: 2 | AA7: 0 | AB7: 2 | AC7: 5 | AD7: 0 | AE7: 8 | AF7: 1 | AG7: 0 | AH7: 34 | AI7: 8 | AJ7: 0 | AK7: 16 | AL7: 2 | AM7: 0 | AN7: 2 | AO7: 0 | AP7: 0 | AQ7: 134 | AR7: 6 | AS7: 0 | AT7: 25 | AU7: 0 | AV7: 0 | AW7: 54 | AX7: 3 | AY7: 0 | AZ7: 614 | BA7: 72 | BB7: 0 | BC7: 266 | BD7: 147 | BE7: 88
A8: Total | B8: 一般 | C8: General | D8: 4977 | E8: 3286 | F8: 1603 | G8: 88 | H8: 1650 | I8: 1188 | J8: 115 | K8: 24 | L8: 0 | M8: 74 | N8: 79 | O8: 0 | P8: 136 | Q8: 37 | R8: 0 | S8: 124 | T8: 41 | U8: 0 | V8: 86 | W8: 6 | X8: 0 | Y8: 0 | Z8: 1 | AA8: 0 | AB8: 2 | AC8: 5 | AD8: 0 | AE8: 8 | AF8: 1 | AG8: 0 | AH8: 33 | AI8: 8 | AJ8: 0 | AK8: 15 | AL8: 2 | AM8: 0 | AN8: 2 | AO8: 0 | AP8: 0 | AQ8: 132 | AR8: 6 | AS8: 0 | AT8: 25 | AU8: 0 | AV8: 0 | AW8: 52 | AX8: 3 | AY8: 0 | AZ8: 578 | BA8: 61 | BB8: 0 | BC8: 254 | BD8: 141 | BE8: 88
B9: 原住民 | C9: Indigenous | D9: 330 | E9: 203 | F9: 127 | G9: 0 | H9: 105 | I9: 100 | J9: 10 | K9: 4 | L9: 0 | M9: 0 | N9: 2 | O9: 0 | P9: 17 | Q9: 2 | R9: 0 | S9: 12 | T9: 1 | U9: 0 | V9: 5 | W9: 0 | X9: 0 | Y9: 0 | Z9: 1 | AA9: 0 | AB9: 0 | AC9: 0 | AD9: 0 | AE9: 0 | AF9: 0 | AG9: 0 | AH9: 1 | AI9: 0 | AJ9: 0 | AK9: 1 | AL9: 0 | AM9: 0 | AN9: 0 | AO9: 0 | AP9: 0 | AQ9: 2 | AR9: 0 | AS9: 0 | AT9: 0 | AU9: 0 | AV9: 0 | AW9: 2 | AX9: 0 | AY9: 0 | AZ9: 36 | BA9: 11 | BB9: 0 | BC9: 12 | BD9: 6 | BE9: 0
A10: 新北市 | B10: 計 | C10: Total | D10: 1132 | E10: 772 | F10: 344 | G10: 16 | H10: 374 | I10: 277 | J10: 28 | K10: 8 | L10: 0 | M10: 24 | N10: 14 | O10: 0 | P10: 34 | Q10: 5 | R10: 0 | S10: 16 | T10: 6 | U10: 0 | V10: 0 | W10: 0 | X10: 0 | Y10: 0 | Z10: 2 | AA10: 0 | AB10: 0 | AC10: 3 | AD10: 0 | AE10: 1 | AF10: 0 | AG10: 0 | AH10: 12 | AI10: 0 | AJ10: 0 | AK10: 2 | AL10: 0 | AM10: 0 | AN10: 0 | AO10: 0 | AP10: 0 | AQ10: 106 | AR10: 3 | AS10: 0 | AT10: 0 | AU10: 0 | AV10: 0 | AW10: 18 | AX10: 1 | AY10: 0 | AZ10: 96 | BA10: 7 | BB10: 0 | BC10: 61 | BD10: 18 | BE10: 16
A11: New Taipei City | B11: 一般 | C11: General | D11: 1088 | E11: 750 | F11: 322 | G11: 16 | H11: 363 | I11: 259 | J11: 26 | K11: 6 | L11: 0 | M11: 24 | N11: 14 | O11: 0 | P11: 31 | Q11: 4 | R11: 0 | S11: 16 | T11: 6 | U11: 0 | V11: 0 | W11: 0 | X11: 0 | Y11: 0 | Z11: 1 | AA11: 0 | AB11: 0 | AC11: 3 | AD11: 0 | AE11: 1 | AF11: 0 | AG11: 0 | AH11: 12 | AI11: 0 | AJ11: 0 | AK11: 2 | AL11: 0 | AM11: 0 | AN11: 0 | AO11: 0 | AP11: 0 | AQ11: 106 | AR11: 3 | AS11: 0 | AT11: 0 | AU11: 0 | AV11: 0 | AW11: 17 | AX11: 1 | AY11: 0 | AZ11: 92 | BA11: 7 | BB11: 0 | BC11: 60 | BD11: 18 | BE11: 16
B12: 原住民 | C12: Indigenous | D12: 44 | E12: 22 | F12: 22 | G12: 0 | H12: 11 | I12: 18 | J12: 2 | K12: 2 | L12: 0 | M12: 0 | N12: 0 | O12: 0 | P12: 3 | Q12: 1 | R12: 0 | S12: 0 | T12: 0 | U12: 0 | V12: 0 | W12: 0 | X12: 0 | Y12: 0 | Z12: 1 | AA12: 0 | AB12: 0 | AC12: 0 | AD12: 0 | AE12: 0 | AF12: 0 | AG12: 0 | AH12: 0 | AI12: 0 | AJ12: 0 | AK12: 0 | AL12: 0 | AM12: 0 | AN12: 0 | AO12: 0 | AP12: 0 | AQ12: 0 | AR12: 0 | AS12: 0 | AT12: 0 | AU12: 0 | AV12: 0 | AW12: 1 | AX12: 0 | AY12: 0 | AZ12: 4 | BA12: 0 | BB12: 0 | BC12: 1 | BD12: 0 | BE12: 0
A13: 臺北市 | B13: 計 | C13: Total | D13: 533 | E13: 307 | F13: 190 | G13: 36 | H13: 168 | I13: 136 | J13: 10 | K13: 4 | L13: 0 | M13: 5 | N13: 10 | O13: 0 | P13: 6 | Q13: 2 | R13: 0 | S13: 15 | T13: 2 | U13: 0 | V13: 0 | W13: 0 | X13: 0 | Y13: 0 | Z13: 0 | AA13: 0 | AB13: 0 | AC13: 0 | AD13: 0 | AE13: 1 | AF13: 0 | AG13: 0 | AH13: 0 | AI13: 0 | AJ13: 0 | AK13: 1 | AL13: 0 | AM13: 0 | AN13: 0 | AO13: 0 | AP13: 0 | AQ13: 0 | AR13: 0 | AS13: 0 | AT13: 0 | AU13: 0 | AV13: 0 | AW13: 8 | AX13: 0 | AY13: 0 | AZ13: 84 | BA13: 20 | BB13: 0 | BC13: 9 | BD13: 16 | BE13: 36
A14: Taipei City | B14: 一般 | C14: General | D14: 527 | E14: 305 | F14: 186 | G14: 36 | H14: 166 | I14: 132 | J14: 10 | K14: 4 | L14: 0 | M14: 5 | N14: 10 | O14: 0 | P14: 6 | Q14: 2 | R14: 0 | S14: 15 | T14: 2 | U14: 0 | V14: 0 | W14: 0 | X14: 0 | Y14: 0 | Z14: 0 | AA14: 0 | AB14: 0 | AC14: 0 | AD14: 0 | AE14: 1 | AF14: 0 | AG14: 0 | AH14: 0 | AI14: 0 | AJ14: 0 | AK14: 1 | AL14: 0 | AM14: 0 | AN14: 0 | AO14: 0 | AP14: 0 | AQ14: 0 | AR14: 0 | AS14: 0 | AT14: 0 | AU14: 0 | AV14: 0 | AW14: 8 | AX14: 0 | AY14: 0 | AZ14: 84 | BA14: 20 | BB14: 0 | BC14: 9 | BD14: 16 | BE14: 36
B15: 原住民 | C15: Indigenous | D15: 6 | E15: 2 | F15: 4 | G15: 0 | H15: 2 | I15: 4 | J15: 0 | K15: 0 | L15: 0 | M15: 0 | N15: 0 | O15: 0 | P15: 0 | Q15: 0 | R15: 0 | S15: 0 | T15: 0 | U15: 0 | V15: 0 | W15: 0 | X15: 0 | Y15: 0 | Z15: 0 | AA15: 0 | AB15: 0 | AC15: 0 | AD15: 0 | AE15: 0 | AF15: 0 | AG15: 0 | AH15: 0 | AI15: 0 | AJ15: 0 | AK15: 0 | AL15: 0 | AM15: 0 | AN15: 0 | AO15: 0 | AP15: 0 | AQ15: 0 | AR15: 0 | AS15: 0 | AT15: 0 | AU15: 0 | AV15: 0 | AW15: 0 | AX15: 0 | AY15: 0 | AZ15: 0 | BA15: 0 | BB15: 0 | BC15: 0 | BD15: 0 | BE15: 0
A16: 桃園市 | B16: 計 | C16: Total | D16: 438 | E16: 312 | F16: 124 | G16: 2 | H16: 150 | I16: 94 | J16: 4 | K16: 3 | L16: 0 | M16: 5 | N16: 4 | O16: 0 | P16: 9 | Q16: 4 | R16: 0 | S16: 5 | T16: 5 | U16: 0 | V16: 3 | W16: 0 | X16: 0 | Y16: 0 | Z16: 0 | AA16: 0 | AB16: 0 | AC16: 2 | AD16: 0 | AE16: 1 | AF16: 0 | AG16: 0 | AH16: 11 | AI16: 1 | AJ16: 0 | AK16: 2 | AL16: 0 | AM16: 0 | AN16: 0 | AO16: 0 | AP16: 0 | AQ16: 3 | AR16: 0 | AS16: 0 | AT16: 0 | AU16: 0 | AV16: 0 | AW16: 2 | AX16: 1 | AY16: 0 | AZ16: 95 | BA16: 10 | BB16: 0 | BC16: 22 | BD16: 0 | BE16: 2
A17: Taoyuan City | B17: 一般 | C17: General | D17: 398 | E17: 291 | F17: 105 | G17: 2 | H17: 138 | I17: 78 | J17: 4 | K17: 2 | L17: 0 | M17: 5 | N17: 4 | O17: 0 | P17: 9 | Q17: 4 | R17: 0 | S17: 5 | T17: 5 | U17: 0 | V17: 0 | W17: 0 | X17: 0 | Y17: 0 | Z17: 0 | AA17: 0 | AB17: 0 | AC17: 2 | AD17: 0 | AE17: 1 | AF17: 0 | AG17: 0 | AH17: 11 | AI17: 1 | AJ17: 0 | AK17: 2 | AL17: 0 | AM17: 0 | AN17: 0 | AO17: 0 | AP17: 0 | AQ17: 2 | AR17: 0 | AS17: 0 | AT17: 0 | AU17: 0 | AV17: 0 | AW17: 2 | AX17: 1 | AY17: 0 | AZ17: 91 | BA17: 8 | BB17: 0 | BC17: 21 | BD17: 0 | BE17: 2
B18: 原住民 | C18: Indigenous | D18: 40 | E18: 21 | F18: 19 | G18: 0 | H18: 12 | I18: 16 | J18: 0 | K18: 1 | L18: 0 | M18: 0 | N18: 0 | O18: 0 | P18: 0 | Q18: 0 | R18: 0 | S18: 0 | T18: 0 | U18: 0 | V18: 3 | W18: 0 | X18: 0 | Y18: 0 | Z18: 0 | AA18: 0 | AB18: 0 | AC18: 0 | AD18: 0 | AE18: 0 | AF18: 0 | AG18: 0 | AH18: 0 | AI18: 0 | AJ18: 0 | AK18: 0 | AL18: 0 | AM18: 0 | AN18: 0 | AO18: 0 | AP18: 0 | AQ18: 1 | AR18: 0 | AS18: 0 | AT18: 0 | AU18: 0 | AV18: 0 | AW18: 0 | AX18: 0 | AY18: 0 | AZ18: 4 | BA18: 2 | BB18: 0 | BC18: 1 | BD18: 0 | BE18: 0
A19: 臺中市 | B19: 計 | C19: Total | D19: 682 | E19: 433 | F19: 234 | G19: 15 | H19: 242 | I19: 130 | J19: 12 | K19: 2 | L19: 0 | M19: 8 | N19: 11 | O19: 0 | P19: 18 | Q19: 6 | R19: 0 | S19: 17 | T19: 6 | U19: 0 | V19: 0 | W19: 0 | X19: 0 | Y19: 0 | Z19: 0 | AA19: 0 | AB19: 0 | AC19: 0 | AD19: 0 | AE19: 1 | AF19: 0 | AG19: 0 | AH19: 2 | AI19: 0 | AJ19: 0 | AK19: 3 | AL19: 0 | AM19: 0 | AN19: 0 | AO19: 0 | AP19: 0 | AQ19: 1 | AR19: 0 | AS19: 0 | AT19: 1 | AU19: 0 | AV19: 0 | AW19: 6 | AX19: 1 | AY19: 0 | AZ19: 90 | BA19: 6 | BB19: 0 | BC19: 32 | BD19: 72 | BE19: 15
A20: Taichung City | B20: 一般 | C20: General | D20: 650 | E20: 410 | F20: 225 | G20: 15 | H20: 225 | I20: 123 | J20: 12 | K20: 2 | L20: 0 | M20: 8 | N20: 9 | O20: 0 | P20: 17 | Q20: 6 | R20: 0 | S20: 15 | T20: 6 | U20: 0 | V20: 0 | W20: 0 | X20: 0 | Y20: 0 | Z20: 0 | AA20: 0 | AB20: 0 | AC20: 0 | AD20: 0 | AE20: 1 | AF20: 0 | AG20: 0 | AH20: 1 | AI20: 0 | AJ20: 0 | AK20: 3 | AL20: 0 | AM20: 0 | AN20: 0 | AO20: 0 | AP20: 0 | AQ20: 1 | AR20: 0 | AS20: 0 | AT20: 1 | AU20: 0 | AV20: 0 | AW20: 6 | AX20: 1 | AY20: 0 | AZ20: 89 | BA20: 6 | BB20: 0 | BC20: 31 | BD20: 72 | BE20: 15
